2024-08-10T20:33:26 {"cpu": 0.203125, "cpu_total": 4, "cpu_usage": 0.05078125, "memory": 2666.0, "memory_total": 16002.0, "memory_usage": 0.16660417447819023, "pipeline_run_id": 34, "pipeline_schedule_id": 3, "pipeline_uuid": "train_sklearn", "hostname": "2f717878a6d7", "level": "INFO", "message": "Pipeline train_sklearn for run 34 in schedule 3 is alive.", "timestamp": 1723322006.150756, "uuid": "ad3d6d900f1b4fcd948bf6bde50c3d75"}
2024-08-10T20:33:26 {"block_run_id": 133, "block_uuid": "training_set", "pipeline_run_id": 34, "pipeline_schedule_id": 3, "pipeline_uuid": "train_sklearn", "hostname": "2f717878a6d7", "level": "INFO", "message": "Execute PipelineRun 34, BlockRun 133: pipeline train_sklearn block training_set", "timestamp": 1723322006.242292, "uuid": "4fff417951d14f7ab5a87d2761c722c1"}
2024-08-10T20:33:26 {"block_run_id": 134, "block_uuid": "set_models", "pipeline_run_id": 34, "pipeline_schedule_id": 3, "pipeline_uuid": "train_sklearn", "hostname": "2f717878a6d7", "level": "INFO", "message": "Execute PipelineRun 34, BlockRun 134: pipeline train_sklearn block set_models", "timestamp": 1723322006.272554, "uuid": "fc1bfa2801a04dc69eb7d7014345fcf2"}
2024-08-10T20:33:26 {"block_run_id": 135, "block_uuid": "training", "pipeline_run_id": 34, "pipeline_schedule_id": 3, "pipeline_uuid": "train_sklearn", "hostname": "2f717878a6d7", "level": "INFO", "message": "Execute PipelineRun 34, BlockRun 135: pipeline train_sklearn block training", "timestamp": 1723322006.283608, "uuid": "a7c0dd4a0322401e8b6cb2632210aa05"}
2024-08-10T20:33:26 {"block_run_id": 134, "block_uuid": "set_models", "pipeline_run_id": 34, "pipeline_schedule_id": 3, "pipeline_uuid": "train_sklearn", "hostname": "2f717878a6d7", "level": "INFO", "message": "BlockRun 134 (block_uuid: set_models) completes.", "timestamp": 1723322006.306084, "uuid": "228bcc203e14458695d6fcdb3e03fdd7"}
2024-08-10T20:33:26 {"block_run_id": 135, "block_uuid": "training", "pipeline_run_id": 34, "pipeline_schedule_id": 3, "pipeline_uuid": "train_sklearn", "hostname": "2f717878a6d7", "level": "INFO", "message": "BlockRun 135 (block_uuid: training) completes.", "timestamp": 1723322006.349058, "uuid": "8555357c7a694622802f6596490f6c7e"}
2024-08-10T20:33:26 {"block_run_id": 133, "block_uuid": "training_set", "pipeline_run_id": 34, "pipeline_schedule_id": 3, "pipeline_uuid": "train_sklearn", "hostname": "2f717878a6d7", "level": "INFO", "message": "BlockRun 133 (block_uuid: training_set) completes.", "timestamp": 1723322006.350016, "uuid": "a521e07d596a4c8d990a982c55b64b3b"}
2024-08-10T20:33:26 {"cpu": 0.203125, "cpu_total": 4, "cpu_usage": 0.05078125, "memory": 2691.0, "memory_total": 16002.0, "memory_usage": 0.16816647919010125, "pipeline_run_id": 34, "pipeline_schedule_id": 3, "pipeline_uuid": "train_sklearn", "hostname": "2f717878a6d7", "level": "INFO", "message": "Pipeline train_sklearn for run 34 in schedule 3 is alive.", "timestamp": 1723322006.689038, "uuid": "087aa75c74384f37a4c394cd19cfa8c8"}
2024-08-10T20:33:27 {"block_run_id": 137, "block_uuid": "training:LinearSVR", "pipeline_run_id": 34, "pipeline_schedule_id": 3, "pipeline_uuid": "train_sklearn", "hostname": "2f717878a6d7", "level": "INFO", "message": "Execute PipelineRun 34, BlockRun 137: pipeline train_sklearn block training:LinearSVR", "timestamp": 1723322007.349377, "uuid": "34576eb2e8b749cd8fa8c477cab68c34"}
2024-08-10T20:33:27 {"block_run_id": 138, "block_uuid": "training:GradientBoostingRegressor", "pipeline_run_id": 34, "pipeline_schedule_id": 3, "pipeline_uuid": "train_sklearn", "hostname": "2f717878a6d7", "level": "INFO", "message": "Execute PipelineRun 34, BlockRun 138: pipeline train_sklearn block training:GradientBoostingRegressor", "timestamp": 1723322007.387454, "uuid": "e6b492b0a257484d92bc44e1b8e6214a"}
2024-08-10T20:33:27 {"block_run_id": 139, "block_uuid": "training:LinearRegression", "pipeline_run_id": 34, "pipeline_schedule_id": 3, "pipeline_uuid": "train_sklearn", "hostname": "2f717878a6d7", "level": "INFO", "message": "Execute PipelineRun 34, BlockRun 139: pipeline train_sklearn block training:LinearRegression", "timestamp": 1723322007.396064, "uuid": "dd19e0640c3348dcb01ebb5685dc0ab0"}
2024-08-10T20:33:27 {"block_run_id": 140, "block_uuid": "training:Lasso", "pipeline_run_id": 34, "pipeline_schedule_id": 3, "pipeline_uuid": "train_sklearn", "hostname": "2f717878a6d7", "level": "INFO", "message": "Execute PipelineRun 34, BlockRun 140: pipeline train_sklearn block training:Lasso", "timestamp": 1723322007.509069, "uuid": "d6547168bcc447fa93018d7b8512bb20"}
2024-08-10T20:33:27 {"block_run_id": 141, "block_uuid": "training:RandomForestRegressor", "pipeline_run_id": 34, "pipeline_schedule_id": 3, "pipeline_uuid": "train_sklearn", "hostname": "2f717878a6d7", "level": "INFO", "message": "Execute PipelineRun 34, BlockRun 141: pipeline train_sklearn block training:RandomForestRegressor", "timestamp": 1723322007.518831, "uuid": "84f5200ad8804599bed0d06d4d1127f7"}
2024-08-10T20:33:30 {"block_run_id": 140, "block_uuid": "training:Lasso", "pipeline_run_id": 34, "pipeline_schedule_id": 3, "pipeline_uuid": "train_sklearn", "hostname": "2f717878a6d7", "level": "EXCEPTION", "message": "BlockRun 140 (block_uuid: training:Lasso) failed.", "timestamp": 1723322010.052487, "uuid": "a786a41389fc4be7ae83c11c9988a41a", "error": ["Traceback (most recent call last):\n  File \"/usr/local/lib/python3.10/site-packages/mage_ai/data_preparation/executors/block_executor.py\", line 647, in execute\n    result = __execute_with_retry()\n  File \"/usr/local/lib/python3.10/site-packages/mage_ai/shared/retry.py\", line 54, in retry_func\n    raise e\n  File \"/usr/local/lib/python3.10/site-packages/mage_ai/shared/retry.py\", line 38, in retry_func\n    return func(*args, **kwargs)\n  File \"/usr/local/lib/python3.10/site-packages/mage_ai/data_preparation/executors/block_executor.py\", line 621, in __execute_with_retry\n    return self._execute(\n  File \"/usr/local/lib/python3.10/site-packages/mage_ai/data_preparation/executors/block_executor.py\", line 1154, in _execute\n    result = self.block.execute_sync(\n  File \"/usr/local/lib/python3.10/site-packages/mage_ai/data_preparation/models/block/__init__.py\", line 1685, in execute_sync\n    return __execute()\n  File \"/usr/local/lib/python3.10/site-packages/mage_ai/data_preparation/models/block/__init__.py\", line 1662, in __execute\n    raise err\n  File \"/usr/local/lib/python3.10/site-packages/mage_ai/data_preparation/models/block/__init__.py\", line 1564, in __execute\n    output = self.execute_block(\n  File \"/usr/local/lib/python3.10/site-packages/mage_ai/data_preparation/models/block/__init__.py\", line 1904, in execute_block\n    outputs = self._execute_block(\n  File \"/usr/local/lib/python3.10/site-packages/mage_ai/data_preparation/models/block/__init__.py\", line 2067, in _execute_block\n    outputs = self.execute_block_function(\n  File \"/usr/local/lib/python3.10/site-packages/mage_ai/data_preparation/models/block/__init__.py\", line 2163, in execute_block_function\n    output = block_function_updated(*input_vars, **global_vars)\n  File \"<string>\", line 33, in hyperparameter_tuning\n  File \"/home/src/Basketball_results_prediction/utils/sklearn.py\", line 138, in tune_hyperparameters\n    best_hyperparameters = fmin(\n  File \"/usr/local/lib/python3.10/site-packages/hyperopt/fmin.py\", line 540, in fmin\n    return trials.fmin(\n  File \"/usr/local/lib/python3.10/site-packages/hyperopt/base.py\", line 671, in fmin\n    return fmin(\n  File \"/usr/local/lib/python3.10/site-packages/hyperopt/fmin.py\", line 586, in fmin\n    rval.exhaust()\n  File \"/usr/local/lib/python3.10/site-packages/hyperopt/fmin.py\", line 364, in exhaust\n    self.run(self.max_evals - n_done, block_until_done=self.asynchronous)\n  File \"/usr/local/lib/python3.10/site-packages/hyperopt/fmin.py\", line 300, in run\n    self.serial_evaluate()\n  File \"/usr/local/lib/python3.10/site-packages/hyperopt/fmin.py\", line 178, in serial_evaluate\n    result = self.domain.evaluate(spec, ctrl)\n  File \"/usr/local/lib/python3.10/site-packages/hyperopt/base.py\", line 892, in evaluate\n    rval = self.fn(pyll_rval)\n  File \"/home/src/Basketball_results_prediction/utils/sklearn.py\", line 93, in __objective\n    mlflow.set_experiment(\"basketball\")\n  File \"/usr/local/lib/python3.10/site-packages/mlflow/tracking/fluent.py\", line 152, in set_experiment\n    experiment_id = client.create_experiment(experiment_name)\n  File \"/usr/local/lib/python3.10/site-packages/mlflow/tracking/client.py\", line 598, in create_experiment\n    return self._tracking_client.create_experiment(name, artifact_location, tags)\n  File \"/usr/local/lib/python3.10/site-packages/mlflow/tracking/_tracking_service/client.py\", line 254, in create_experiment\n    return self.store.create_experiment(\n  File \"/usr/local/lib/python3.10/site-packages/mlflow/store/tracking/rest_store.py\", line 101, in create_experiment\n    response_proto = self._call_endpoint(CreateExperiment, req_body)\n  File \"/usr/local/lib/python3.10/site-packages/mlflow/store/tracking/rest_store.py\", line 60, in _call_endpoint\n    return call_endpoint(self.get_host_creds(), endpoint, method, json_body, response_proto)\n  File \"/usr/local/lib/python3.10/site-packages/mlflow/utils/rest_utils.py\", line 290, in call_endpoint\n    response = verify_rest_response(response, endpoint)\n  File \"/usr/local/lib/python3.10/site-packages/mlflow/utils/rest_utils.py\", line 173, in verify_rest_response\n    raise RestException(json.loads(response.text))\nmlflow.exceptions.RestException: RESOURCE_ALREADY_EXISTS: Experiment(name=basketball) already exists. Error: (raised as a result of Query-invoked autoflush; consider using a session.no_autoflush block if this flush is occurring prematurely)\n(psycopg2.errors.UniqueViolation) duplicate key value violates unique constraint \"experiments_name_key\"\nDETAIL:  Key (name)=(basketball) already exists.\n\n[SQL: INSERT INTO experiments (name, artifact_location, lifecycle_stage, creation_time, last_update_time) VALUES (%(name)s, %(artifact_location)s, %(lifecycle_stage)s, %(creation_time)s, %(last_update_time)s) RETURNING experiments.experiment_id]\n[parameters: {'name': 'basketball', 'artifact_location': '', 'lifecycle_stage': 'active', 'creation_time': 1723322009832, 'last_update_time': 1723322009832}]\n(Background on this error at: https://sqlalche.me/e/20/gkpj)\n"], "error_stack": [["  File \"/usr/local/bin/mage\", line 8, in <module>\n    sys.exit(app())\n", "  File \"/usr/local/lib/python3.10/site-packages/typer/main.py\", line 311, in __call__\n    return get_command(self)(*args, **kwargs)\n", "  File \"/usr/local/lib/python3.10/site-packages/click/core.py\", line 1130, in __call__\n    return self.main(*args, **kwargs)\n", "  File \"/usr/local/lib/python3.10/site-packages/typer/core.py\", line 778, in main\n    return _main(\n", "  File \"/usr/local/lib/python3.10/site-packages/typer/core.py\", line 216, in _main\n    rv = self.invoke(ctx)\n", "  File \"/usr/local/lib/python3.10/site-packages/click/core.py\", line 1657, in invoke\n    return _process_result(sub_ctx.command.invoke(sub_ctx))\n", "  File \"/usr/local/lib/python3.10/site-packages/click/core.py\", line 1404, in invoke\n    return ctx.invoke(self.callback, **ctx.params)\n", "  File \"/usr/local/lib/python3.10/site-packages/click/core.py\", line 760, in invoke\n    return __callback(*args, **kwargs)\n", "  File \"/usr/local/lib/python3.10/site-packages/typer/main.py\", line 683, in wrapper\n    return callback(**use_params)  # type: ignore\n", "  File \"/usr/local/lib/python3.10/site-packages/mage_ai/cli/main.py\", line 147, in start\n    start_server(\n", "  File \"/usr/local/lib/python3.10/site-packages/mage_ai/server/server.py\", line 792, in start_server\n    scheduler_manager.start_scheduler()\n", "  File \"/usr/local/lib/python3.10/site-packages/mage_ai/server/scheduler_manager.py\", line 106, in start_scheduler\n    proc.start()\n", "  File \"/usr/local/lib/python3.10/multiprocessing/process.py\", line 121, in start\n    self._popen = self._Popen(self)\n", "  File \"/usr/local/lib/python3.10/multiprocessing/context.py\", line 224, in _Popen\n    return _default_context.get_context().Process._Popen(process_obj)\n", "  File \"/usr/local/lib/python3.10/multiprocessing/context.py\", line 281, in _Popen\n    return Popen(process_obj)\n", "  File \"/usr/local/lib/python3.10/multiprocessing/popen_fork.py\", line 19, in __init__\n    self._launch(process_obj)\n", "  File \"/usr/local/lib/python3.10/multiprocessing/popen_fork.py\", line 71, in _launch\n    code = process_obj._bootstrap(parent_sentinel=child_r)\n", "  File \"/usr/local/lib/python3.10/multiprocessing/process.py\", line 314, in _bootstrap\n    self.run()\n", "  File \"/usr/local/lib/python3.10/multiprocessing/process.py\", line 108, in run\n    self._target(*self._args, **self._kwargs)\n", "  File \"/usr/local/lib/python3.10/site-packages/mage_ai/orchestration/db/process.py\", line 15, in start_session_and_run\n    results = target(*args)\n", "  File \"/usr/local/lib/python3.10/site-packages/mage_ai/server/scheduler_manager.py\", line 58, in run_scheduler\n    LoopTimeTrigger().start()\n", "  File \"/usr/local/lib/python3.10/site-packages/mage_ai/orchestration/triggers/loop_time_trigger.py\", line 14, in start\n    self.run()\n", "  File \"/usr/local/lib/python3.10/site-packages/mage_ai/orchestration/triggers/time_trigger.py\", line 11, in run\n    schedule_all()\n", "  File \"/usr/local/lib/python3.10/site-packages/mage_ai/orchestration/pipeline_scheduler_original.py\", line 1703, in schedule_all\n    PipelineScheduler(r).start()\n", "  File \"/usr/local/lib/python3.10/site-packages/mage_ai/orchestration/db/__init__.py\", line 158, in func_with_rollback\n    return func(*args, **kwargs)\n", "  File \"/usr/local/lib/python3.10/site-packages/mage_ai/orchestration/pipeline_scheduler_original.py\", line 198, in start\n    self.schedule()\n", "  File \"/usr/local/lib/python3.10/site-packages/mage_ai/orchestration/db/__init__.py\", line 158, in func_with_rollback\n    return func(*args, **kwargs)\n", "  File \"/usr/local/lib/python3.10/site-packages/mage_ai/orchestration/pipeline_scheduler_original.py\", line 334, in schedule\n    self.__schedule_blocks(block_runs)\n", "  File \"/usr/local/lib/python3.10/site-packages/mage_ai/orchestration/pipeline_scheduler_original.py\", line 641, in __schedule_blocks\n    job_manager.add_job(\n", "  File \"/usr/local/lib/python3.10/site-packages/mage_ai/orchestration/job_manager.py\", line 20, in add_job\n    self.queue.enqueue(job_id, target, *args, **kwargs)\n", "  File \"/usr/local/lib/python3.10/site-packages/mage_ai/orchestration/queue/process_queue.py\", line 121, in enqueue\n    self.start_worker_pool()\n", "  File \"/usr/local/lib/python3.10/site-packages/mage_ai/orchestration/queue/process_queue.py\", line 198, in start_worker_pool\n    self.worker_pool_proc.start()\n", "  File \"/usr/local/lib/python3.10/multiprocessing/process.py\", line 121, in start\n    self._popen = self._Popen(self)\n", "  File \"/usr/local/lib/python3.10/multiprocessing/context.py\", line 224, in _Popen\n    return _default_context.get_context().Process._Popen(process_obj)\n", "  File \"/usr/local/lib/python3.10/multiprocessing/context.py\", line 281, in _Popen\n    return Popen(process_obj)\n", "  File \"/usr/local/lib/python3.10/multiprocessing/popen_fork.py\", line 19, in __init__\n    self._launch(process_obj)\n", "  File \"/usr/local/lib/python3.10/multiprocessing/popen_fork.py\", line 71, in _launch\n    code = process_obj._bootstrap(parent_sentinel=child_r)\n", "  File \"/usr/local/lib/python3.10/multiprocessing/process.py\", line 314, in _bootstrap\n    self.run()\n", "  File \"/usr/local/lib/python3.10/multiprocessing/process.py\", line 108, in run\n    self._target(*self._args, **self._kwargs)\n", "  File \"/usr/local/lib/python3.10/site-packages/mage_ai/orchestration/queue/process_queue.py\", line 351, in poll_job_and_execute\n    worker.start()\n", "  File \"/usr/local/lib/python3.10/multiprocessing/process.py\", line 121, in start\n    self._popen = self._Popen(self)\n", "  File \"/usr/local/lib/python3.10/multiprocessing/context.py\", line 224, in _Popen\n    return _default_context.get_context().Process._Popen(process_obj)\n", "  File \"/usr/local/lib/python3.10/multiprocessing/context.py\", line 281, in _Popen\n    return Popen(process_obj)\n", "  File \"/usr/local/lib/python3.10/multiprocessing/popen_fork.py\", line 19, in __init__\n    self._launch(process_obj)\n", "  File \"/usr/local/lib/python3.10/multiprocessing/popen_fork.py\", line 71, in _launch\n    code = process_obj._bootstrap(parent_sentinel=child_r)\n", "  File \"/usr/local/lib/python3.10/multiprocessing/process.py\", line 314, in _bootstrap\n    self.run()\n", "  File \"/usr/local/lib/python3.10/site-packages/newrelic/api/background_task.py\", line 117, in wrapper\n    return wrapped(*args, **kwargs)\n", "  File \"/usr/local/lib/python3.10/site-packages/mage_ai/orchestration/queue/process_queue.py\", line 315, in run\n    start_session_and_run(args[1], *args[2], **args[3])\n", "  File \"/usr/local/lib/python3.10/site-packages/mage_ai/orchestration/db/process.py\", line 15, in start_session_and_run\n    results = target(*args)\n", "  File \"/usr/local/lib/python3.10/site-packages/mage_ai/orchestration/pipeline_scheduler_original.py\", line 1236, in run_block\n    return ExecutorFactory.get_block_executor(\n", "  File \"/usr/local/lib/python3.10/site-packages/mage_ai/data_preparation/executors/block_executor.py\", line 682, in execute\n    on_failure(\n", "  File \"/usr/local/lib/python3.10/site-packages/mage_ai/orchestration/db/__init__.py\", line 158, in func_with_rollback\n    return func(*args, **kwargs)\n", "  File \"/usr/local/lib/python3.10/site-packages/mage_ai/orchestration/pipeline_scheduler_original.py\", line 465, in on_block_failure\n    self.logger.exception(\n", "  File \"/usr/local/lib/python3.10/site-packages/mage_ai/data_preparation/logging/logger.py\", line 30, in exception\n    self.__send_message('exception', message, **kwargs)\n", "  File \"/usr/local/lib/python3.10/site-packages/mage_ai/data_preparation/logging/logger.py\", line 65, in __send_message\n    data['error_stack'] = traceback.format_stack(),\n"]], "error_stacktrace": ["RESOURCE_ALREADY_EXISTS: Experiment(name=basketball) already exists. Error: (raised as a result of Query-invoked autoflush; consider using a session.no_autoflush block if this flush is occurring prematurely)\n(psycopg2.errors.UniqueViolation) duplicate key value violates unique constraint \"experiments_name_key\"\nDETAIL:  Key (name)=(basketball) already exists.\n\n[SQL: INSERT INTO experiments (name, artifact_location, lifecycle_stage, creation_time, last_update_time) VALUES (%(name)s, %(artifact_location)s, %(lifecycle_stage)s, %(creation_time)s, %(last_update_time)s) RETURNING experiments.experiment_id]\n[parameters: {'name': 'basketball', 'artifact_location': '', 'lifecycle_stage': 'active', 'creation_time': 1723322009832, 'last_update_time': 1723322009832}]\n(Background on this error at: https://sqlalche.me/e/20/gkpj)"]}
Traceback (most recent call last):
  File "/usr/local/lib/python3.10/site-packages/mage_ai/data_preparation/executors/block_executor.py", line 647, in execute
    result = __execute_with_retry()
  File "/usr/local/lib/python3.10/site-packages/mage_ai/shared/retry.py", line 54, in retry_func
    raise e
  File "/usr/local/lib/python3.10/site-packages/mage_ai/shared/retry.py", line 38, in retry_func
    return func(*args, **kwargs)
  File "/usr/local/lib/python3.10/site-packages/mage_ai/data_preparation/executors/block_executor.py", line 621, in __execute_with_retry
    return self._execute(
  File "/usr/local/lib/python3.10/site-packages/mage_ai/data_preparation/executors/block_executor.py", line 1154, in _execute
    result = self.block.execute_sync(
  File "/usr/local/lib/python3.10/site-packages/mage_ai/data_preparation/models/block/__init__.py", line 1685, in execute_sync
    return __execute()
  File "/usr/local/lib/python3.10/site-packages/mage_ai/data_preparation/models/block/__init__.py", line 1662, in __execute
    raise err
  File "/usr/local/lib/python3.10/site-packages/mage_ai/data_preparation/models/block/__init__.py", line 1564, in __execute
    output = self.execute_block(
  File "/usr/local/lib/python3.10/site-packages/mage_ai/data_preparation/models/block/__init__.py", line 1904, in execute_block
    outputs = self._execute_block(
  File "/usr/local/lib/python3.10/site-packages/mage_ai/data_preparation/models/block/__init__.py", line 2067, in _execute_block
    outputs = self.execute_block_function(
  File "/usr/local/lib/python3.10/site-packages/mage_ai/data_preparation/models/block/__init__.py", line 2163, in execute_block_function
    output = block_function_updated(*input_vars, **global_vars)
  File "<string>", line 33, in hyperparameter_tuning
  File "/home/src/Basketball_results_prediction/utils/sklearn.py", line 138, in tune_hyperparameters
    best_hyperparameters = fmin(
  File "/usr/local/lib/python3.10/site-packages/hyperopt/fmin.py", line 540, in fmin
    return trials.fmin(
  File "/usr/local/lib/python3.10/site-packages/hyperopt/base.py", line 671, in fmin
    return fmin(
  File "/usr/local/lib/python3.10/site-packages/hyperopt/fmin.py", line 586, in fmin
    rval.exhaust()
  File "/usr/local/lib/python3.10/site-packages/hyperopt/fmin.py", line 364, in exhaust
    self.run(self.max_evals - n_done, block_until_done=self.asynchronous)
  File "/usr/local/lib/python3.10/site-packages/hyperopt/fmin.py", line 300, in run
    self.serial_evaluate()
  File "/usr/local/lib/python3.10/site-packages/hyperopt/fmin.py", line 178, in serial_evaluate
    result = self.domain.evaluate(spec, ctrl)
  File "/usr/local/lib/python3.10/site-packages/hyperopt/base.py", line 892, in evaluate
    rval = self.fn(pyll_rval)
  File "/home/src/Basketball_results_prediction/utils/sklearn.py", line 93, in __objective
    mlflow.set_experiment("basketball")
  File "/usr/local/lib/python3.10/site-packages/mlflow/tracking/fluent.py", line 152, in set_experiment
    experiment_id = client.create_experiment(experiment_name)
  File "/usr/local/lib/python3.10/site-packages/mlflow/tracking/client.py", line 598, in create_experiment
    return self._tracking_client.create_experiment(name, artifact_location, tags)
  File "/usr/local/lib/python3.10/site-packages/mlflow/tracking/_tracking_service/client.py", line 254, in create_experiment
    return self.store.create_experiment(
  File "/usr/local/lib/python3.10/site-packages/mlflow/store/tracking/rest_store.py", line 101, in create_experiment
    response_proto = self._call_endpoint(CreateExperiment, req_body)
  File "/usr/local/lib/python3.10/site-packages/mlflow/store/tracking/rest_store.py", line 60, in _call_endpoint
    return call_endpoint(self.get_host_creds(), endpoint, method, json_body, response_proto)
  File "/usr/local/lib/python3.10/site-packages/mlflow/utils/rest_utils.py", line 290, in call_endpoint
    response = verify_rest_response(response, endpoint)
  File "/usr/local/lib/python3.10/site-packages/mlflow/utils/rest_utils.py", line 173, in verify_rest_response
    raise RestException(json.loads(response.text))
mlflow.exceptions.RestException: RESOURCE_ALREADY_EXISTS: Experiment(name=basketball) already exists. Error: (raised as a result of Query-invoked autoflush; consider using a session.no_autoflush block if this flush is occurring prematurely)
(psycopg2.errors.UniqueViolation) duplicate key value violates unique constraint "experiments_name_key"
DETAIL:  Key (name)=(basketball) already exists.

[SQL: INSERT INTO experiments (name, artifact_location, lifecycle_stage, creation_time, last_update_time) VALUES (%(name)s, %(artifact_location)s, %(lifecycle_stage)s, %(creation_time)s, %(last_update_time)s) RETURNING experiments.experiment_id]
[parameters: {'name': 'basketball', 'artifact_location': '', 'lifecycle_stage': 'active', 'creation_time': 1723322009832, 'last_update_time': 1723322009832}]
(Background on this error at: https://sqlalche.me/e/20/gkpj)
2024-08-10T20:33:30 {"block_run_id": 137, "block_uuid": "training:LinearSVR", "pipeline_run_id": 34, "pipeline_schedule_id": 3, "pipeline_uuid": "train_sklearn", "hostname": "2f717878a6d7", "level": "EXCEPTION", "message": "BlockRun 137 (block_uuid: training:LinearSVR) failed.", "timestamp": 1723322010.075382, "uuid": "b14d96cfcb9f469db14db1736fc48b67", "error": ["Traceback (most recent call last):\n  File \"/usr/local/lib/python3.10/site-packages/mage_ai/data_preparation/executors/block_executor.py\", line 647, in execute\n    result = __execute_with_retry()\n  File \"/usr/local/lib/python3.10/site-packages/mage_ai/shared/retry.py\", line 54, in retry_func\n    raise e\n  File \"/usr/local/lib/python3.10/site-packages/mage_ai/shared/retry.py\", line 38, in retry_func\n    return func(*args, **kwargs)\n  File \"/usr/local/lib/python3.10/site-packages/mage_ai/data_preparation/executors/block_executor.py\", line 621, in __execute_with_retry\n    return self._execute(\n  File \"/usr/local/lib/python3.10/site-packages/mage_ai/data_preparation/executors/block_executor.py\", line 1154, in _execute\n    result = self.block.execute_sync(\n  File \"/usr/local/lib/python3.10/site-packages/mage_ai/data_preparation/models/block/__init__.py\", line 1685, in execute_sync\n    return __execute()\n  File \"/usr/local/lib/python3.10/site-packages/mage_ai/data_preparation/models/block/__init__.py\", line 1662, in __execute\n    raise err\n  File \"/usr/local/lib/python3.10/site-packages/mage_ai/data_preparation/models/block/__init__.py\", line 1564, in __execute\n    output = self.execute_block(\n  File \"/usr/local/lib/python3.10/site-packages/mage_ai/data_preparation/models/block/__init__.py\", line 1904, in execute_block\n    outputs = self._execute_block(\n  File \"/usr/local/lib/python3.10/site-packages/mage_ai/data_preparation/models/block/__init__.py\", line 2067, in _execute_block\n    outputs = self.execute_block_function(\n  File \"/usr/local/lib/python3.10/site-packages/mage_ai/data_preparation/models/block/__init__.py\", line 2163, in execute_block_function\n    output = block_function_updated(*input_vars, **global_vars)\n  File \"<string>\", line 33, in hyperparameter_tuning\n  File \"/home/src/Basketball_results_prediction/utils/sklearn.py\", line 138, in tune_hyperparameters\n    best_hyperparameters = fmin(\n  File \"/usr/local/lib/python3.10/site-packages/hyperopt/fmin.py\", line 540, in fmin\n    return trials.fmin(\n  File \"/usr/local/lib/python3.10/site-packages/hyperopt/base.py\", line 671, in fmin\n    return fmin(\n  File \"/usr/local/lib/python3.10/site-packages/hyperopt/fmin.py\", line 586, in fmin\n    rval.exhaust()\n  File \"/usr/local/lib/python3.10/site-packages/hyperopt/fmin.py\", line 364, in exhaust\n    self.run(self.max_evals - n_done, block_until_done=self.asynchronous)\n  File \"/usr/local/lib/python3.10/site-packages/hyperopt/fmin.py\", line 300, in run\n    self.serial_evaluate()\n  File \"/usr/local/lib/python3.10/site-packages/hyperopt/fmin.py\", line 178, in serial_evaluate\n    result = self.domain.evaluate(spec, ctrl)\n  File \"/usr/local/lib/python3.10/site-packages/hyperopt/base.py\", line 892, in evaluate\n    rval = self.fn(pyll_rval)\n  File \"/home/src/Basketball_results_prediction/utils/sklearn.py\", line 93, in __objective\n    mlflow.set_experiment(\"basketball\")\n  File \"/usr/local/lib/python3.10/site-packages/mlflow/tracking/fluent.py\", line 152, in set_experiment\n    experiment_id = client.create_experiment(experiment_name)\n  File \"/usr/local/lib/python3.10/site-packages/mlflow/tracking/client.py\", line 598, in create_experiment\n    return self._tracking_client.create_experiment(name, artifact_location, tags)\n  File \"/usr/local/lib/python3.10/site-packages/mlflow/tracking/_tracking_service/client.py\", line 254, in create_experiment\n    return self.store.create_experiment(\n  File \"/usr/local/lib/python3.10/site-packages/mlflow/store/tracking/rest_store.py\", line 101, in create_experiment\n    response_proto = self._call_endpoint(CreateExperiment, req_body)\n  File \"/usr/local/lib/python3.10/site-packages/mlflow/store/tracking/rest_store.py\", line 60, in _call_endpoint\n    return call_endpoint(self.get_host_creds(), endpoint, method, json_body, response_proto)\n  File \"/usr/local/lib/python3.10/site-packages/mlflow/utils/rest_utils.py\", line 290, in call_endpoint\n    response = verify_rest_response(response, endpoint)\n  File \"/usr/local/lib/python3.10/site-packages/mlflow/utils/rest_utils.py\", line 173, in verify_rest_response\n    raise RestException(json.loads(response.text))\nmlflow.exceptions.RestException: RESOURCE_ALREADY_EXISTS: Experiment(name=basketball) already exists. Error: (raised as a result of Query-invoked autoflush; consider using a session.no_autoflush block if this flush is occurring prematurely)\n(psycopg2.errors.UniqueViolation) duplicate key value violates unique constraint \"experiments_name_key\"\nDETAIL:  Key (name)=(basketball) already exists.\n\n[SQL: INSERT INTO experiments (name, artifact_location, lifecycle_stage, creation_time, last_update_time) VALUES (%(name)s, %(artifact_location)s, %(lifecycle_stage)s, %(creation_time)s, %(last_update_time)s) RETURNING experiments.experiment_id]\n[parameters: {'name': 'basketball', 'artifact_location': '', 'lifecycle_stage': 'active', 'creation_time': 1723322009844, 'last_update_time': 1723322009844}]\n(Background on this error at: https://sqlalche.me/e/20/gkpj)\n"], "error_stack": [["  File \"/usr/local/bin/mage\", line 8, in <module>\n    sys.exit(app())\n", "  File \"/usr/local/lib/python3.10/site-packages/typer/main.py\", line 311, in __call__\n    return get_command(self)(*args, **kwargs)\n", "  File \"/usr/local/lib/python3.10/site-packages/click/core.py\", line 1130, in __call__\n    return self.main(*args, **kwargs)\n", "  File \"/usr/local/lib/python3.10/site-packages/typer/core.py\", line 778, in main\n    return _main(\n", "  File \"/usr/local/lib/python3.10/site-packages/typer/core.py\", line 216, in _main\n    rv = self.invoke(ctx)\n", "  File \"/usr/local/lib/python3.10/site-packages/click/core.py\", line 1657, in invoke\n    return _process_result(sub_ctx.command.invoke(sub_ctx))\n", "  File \"/usr/local/lib/python3.10/site-packages/click/core.py\", line 1404, in invoke\n    return ctx.invoke(self.callback, **ctx.params)\n", "  File \"/usr/local/lib/python3.10/site-packages/click/core.py\", line 760, in invoke\n    return __callback(*args, **kwargs)\n", "  File \"/usr/local/lib/python3.10/site-packages/typer/main.py\", line 683, in wrapper\n    return callback(**use_params)  # type: ignore\n", "  File \"/usr/local/lib/python3.10/site-packages/mage_ai/cli/main.py\", line 147, in start\n    start_server(\n", "  File \"/usr/local/lib/python3.10/site-packages/mage_ai/server/server.py\", line 792, in start_server\n    scheduler_manager.start_scheduler()\n", "  File \"/usr/local/lib/python3.10/site-packages/mage_ai/server/scheduler_manager.py\", line 106, in start_scheduler\n    proc.start()\n", "  File \"/usr/local/lib/python3.10/multiprocessing/process.py\", line 121, in start\n    self._popen = self._Popen(self)\n", "  File \"/usr/local/lib/python3.10/multiprocessing/context.py\", line 224, in _Popen\n    return _default_context.get_context().Process._Popen(process_obj)\n", "  File \"/usr/local/lib/python3.10/multiprocessing/context.py\", line 281, in _Popen\n    return Popen(process_obj)\n", "  File \"/usr/local/lib/python3.10/multiprocessing/popen_fork.py\", line 19, in __init__\n    self._launch(process_obj)\n", "  File \"/usr/local/lib/python3.10/multiprocessing/popen_fork.py\", line 71, in _launch\n    code = process_obj._bootstrap(parent_sentinel=child_r)\n", "  File \"/usr/local/lib/python3.10/multiprocessing/process.py\", line 314, in _bootstrap\n    self.run()\n", "  File \"/usr/local/lib/python3.10/multiprocessing/process.py\", line 108, in run\n    self._target(*self._args, **self._kwargs)\n", "  File \"/usr/local/lib/python3.10/site-packages/mage_ai/orchestration/db/process.py\", line 15, in start_session_and_run\n    results = target(*args)\n", "  File \"/usr/local/lib/python3.10/site-packages/mage_ai/server/scheduler_manager.py\", line 58, in run_scheduler\n    LoopTimeTrigger().start()\n", "  File \"/usr/local/lib/python3.10/site-packages/mage_ai/orchestration/triggers/loop_time_trigger.py\", line 14, in start\n    self.run()\n", "  File \"/usr/local/lib/python3.10/site-packages/mage_ai/orchestration/triggers/time_trigger.py\", line 11, in run\n    schedule_all()\n", "  File \"/usr/local/lib/python3.10/site-packages/mage_ai/orchestration/pipeline_scheduler_original.py\", line 1703, in schedule_all\n    PipelineScheduler(r).start()\n", "  File \"/usr/local/lib/python3.10/site-packages/mage_ai/orchestration/db/__init__.py\", line 158, in func_with_rollback\n    return func(*args, **kwargs)\n", "  File \"/usr/local/lib/python3.10/site-packages/mage_ai/orchestration/pipeline_scheduler_original.py\", line 198, in start\n    self.schedule()\n", "  File \"/usr/local/lib/python3.10/site-packages/mage_ai/orchestration/db/__init__.py\", line 158, in func_with_rollback\n    return func(*args, **kwargs)\n", "  File \"/usr/local/lib/python3.10/site-packages/mage_ai/orchestration/pipeline_scheduler_original.py\", line 334, in schedule\n    self.__schedule_blocks(block_runs)\n", "  File \"/usr/local/lib/python3.10/site-packages/mage_ai/orchestration/pipeline_scheduler_original.py\", line 641, in __schedule_blocks\n    job_manager.add_job(\n", "  File \"/usr/local/lib/python3.10/site-packages/mage_ai/orchestration/job_manager.py\", line 20, in add_job\n    self.queue.enqueue(job_id, target, *args, **kwargs)\n", "  File \"/usr/local/lib/python3.10/site-packages/mage_ai/orchestration/queue/process_queue.py\", line 121, in enqueue\n    self.start_worker_pool()\n", "  File \"/usr/local/lib/python3.10/site-packages/mage_ai/orchestration/queue/process_queue.py\", line 198, in start_worker_pool\n    self.worker_pool_proc.start()\n", "  File \"/usr/local/lib/python3.10/multiprocessing/process.py\", line 121, in start\n    self._popen = self._Popen(self)\n", "  File \"/usr/local/lib/python3.10/multiprocessing/context.py\", line 224, in _Popen\n    return _default_context.get_context().Process._Popen(process_obj)\n", "  File \"/usr/local/lib/python3.10/multiprocessing/context.py\", line 281, in _Popen\n    return Popen(process_obj)\n", "  File \"/usr/local/lib/python3.10/multiprocessing/popen_fork.py\", line 19, in __init__\n    self._launch(process_obj)\n", "  File \"/usr/local/lib/python3.10/multiprocessing/popen_fork.py\", line 71, in _launch\n    code = process_obj._bootstrap(parent_sentinel=child_r)\n", "  File \"/usr/local/lib/python3.10/multiprocessing/process.py\", line 314, in _bootstrap\n    self.run()\n", "  File \"/usr/local/lib/python3.10/multiprocessing/process.py\", line 108, in run\n    self._target(*self._args, **self._kwargs)\n", "  File \"/usr/local/lib/python3.10/site-packages/mage_ai/orchestration/queue/process_queue.py\", line 351, in poll_job_and_execute\n    worker.start()\n", "  File \"/usr/local/lib/python3.10/multiprocessing/process.py\", line 121, in start\n    self._popen = self._Popen(self)\n", "  File \"/usr/local/lib/python3.10/multiprocessing/context.py\", line 224, in _Popen\n    return _default_context.get_context().Process._Popen(process_obj)\n", "  File \"/usr/local/lib/python3.10/multiprocessing/context.py\", line 281, in _Popen\n    return Popen(process_obj)\n", "  File \"/usr/local/lib/python3.10/multiprocessing/popen_fork.py\", line 19, in __init__\n    self._launch(process_obj)\n", "  File \"/usr/local/lib/python3.10/multiprocessing/popen_fork.py\", line 71, in _launch\n    code = process_obj._bootstrap(parent_sentinel=child_r)\n", "  File \"/usr/local/lib/python3.10/multiprocessing/process.py\", line 314, in _bootstrap\n    self.run()\n", "  File \"/usr/local/lib/python3.10/site-packages/newrelic/api/background_task.py\", line 117, in wrapper\n    return wrapped(*args, **kwargs)\n", "  File \"/usr/local/lib/python3.10/site-packages/mage_ai/orchestration/queue/process_queue.py\", line 315, in run\n    start_session_and_run(args[1], *args[2], **args[3])\n", "  File \"/usr/local/lib/python3.10/site-packages/mage_ai/orchestration/db/process.py\", line 15, in start_session_and_run\n    results = target(*args)\n", "  File \"/usr/local/lib/python3.10/site-packages/mage_ai/orchestration/pipeline_scheduler_original.py\", line 1236, in run_block\n    return ExecutorFactory.get_block_executor(\n", "  File \"/usr/local/lib/python3.10/site-packages/mage_ai/data_preparation/executors/block_executor.py\", line 682, in execute\n    on_failure(\n", "  File \"/usr/local/lib/python3.10/site-packages/mage_ai/orchestration/db/__init__.py\", line 158, in func_with_rollback\n    return func(*args, **kwargs)\n", "  File \"/usr/local/lib/python3.10/site-packages/mage_ai/orchestration/pipeline_scheduler_original.py\", line 465, in on_block_failure\n    self.logger.exception(\n", "  File \"/usr/local/lib/python3.10/site-packages/mage_ai/data_preparation/logging/logger.py\", line 30, in exception\n    self.__send_message('exception', message, **kwargs)\n", "  File \"/usr/local/lib/python3.10/site-packages/mage_ai/data_preparation/logging/logger.py\", line 65, in __send_message\n    data['error_stack'] = traceback.format_stack(),\n"]], "error_stacktrace": ["RESOURCE_ALREADY_EXISTS: Experiment(name=basketball) already exists. Error: (raised as a result of Query-invoked autoflush; consider using a session.no_autoflush block if this flush is occurring prematurely)\n(psycopg2.errors.UniqueViolation) duplicate key value violates unique constraint \"experiments_name_key\"\nDETAIL:  Key (name)=(basketball) already exists.\n\n[SQL: INSERT INTO experiments (name, artifact_location, lifecycle_stage, creation_time, last_update_time) VALUES (%(name)s, %(artifact_location)s, %(lifecycle_stage)s, %(creation_time)s, %(last_update_time)s) RETURNING experiments.experiment_id]\n[parameters: {'name': 'basketball', 'artifact_location': '', 'lifecycle_stage': 'active', 'creation_time': 1723322009844, 'last_update_time': 1723322009844}]\n(Background on this error at: https://sqlalche.me/e/20/gkpj)"]}
Traceback (most recent call last):
  File "/usr/local/lib/python3.10/site-packages/mage_ai/data_preparation/executors/block_executor.py", line 647, in execute
    result = __execute_with_retry()
  File "/usr/local/lib/python3.10/site-packages/mage_ai/shared/retry.py", line 54, in retry_func
    raise e
  File "/usr/local/lib/python3.10/site-packages/mage_ai/shared/retry.py", line 38, in retry_func
    return func(*args, **kwargs)
  File "/usr/local/lib/python3.10/site-packages/mage_ai/data_preparation/executors/block_executor.py", line 621, in __execute_with_retry
    return self._execute(
  File "/usr/local/lib/python3.10/site-packages/mage_ai/data_preparation/executors/block_executor.py", line 1154, in _execute
    result = self.block.execute_sync(
  File "/usr/local/lib/python3.10/site-packages/mage_ai/data_preparation/models/block/__init__.py", line 1685, in execute_sync
    return __execute()
  File "/usr/local/lib/python3.10/site-packages/mage_ai/data_preparation/models/block/__init__.py", line 1662, in __execute
    raise err
  File "/usr/local/lib/python3.10/site-packages/mage_ai/data_preparation/models/block/__init__.py", line 1564, in __execute
    output = self.execute_block(
  File "/usr/local/lib/python3.10/site-packages/mage_ai/data_preparation/models/block/__init__.py", line 1904, in execute_block
    outputs = self._execute_block(
  File "/usr/local/lib/python3.10/site-packages/mage_ai/data_preparation/models/block/__init__.py", line 2067, in _execute_block
    outputs = self.execute_block_function(
  File "/usr/local/lib/python3.10/site-packages/mage_ai/data_preparation/models/block/__init__.py", line 2163, in execute_block_function
    output = block_function_updated(*input_vars, **global_vars)
  File "<string>", line 33, in hyperparameter_tuning
  File "/home/src/Basketball_results_prediction/utils/sklearn.py", line 138, in tune_hyperparameters
    best_hyperparameters = fmin(
  File "/usr/local/lib/python3.10/site-packages/hyperopt/fmin.py", line 540, in fmin
    return trials.fmin(
  File "/usr/local/lib/python3.10/site-packages/hyperopt/base.py", line 671, in fmin
    return fmin(
  File "/usr/local/lib/python3.10/site-packages/hyperopt/fmin.py", line 586, in fmin
    rval.exhaust()
  File "/usr/local/lib/python3.10/site-packages/hyperopt/fmin.py", line 364, in exhaust
    self.run(self.max_evals - n_done, block_until_done=self.asynchronous)
  File "/usr/local/lib/python3.10/site-packages/hyperopt/fmin.py", line 300, in run
    self.serial_evaluate()
  File "/usr/local/lib/python3.10/site-packages/hyperopt/fmin.py", line 178, in serial_evaluate
    result = self.domain.evaluate(spec, ctrl)
  File "/usr/local/lib/python3.10/site-packages/hyperopt/base.py", line 892, in evaluate
    rval = self.fn(pyll_rval)
  File "/home/src/Basketball_results_prediction/utils/sklearn.py", line 93, in __objective
    mlflow.set_experiment("basketball")
  File "/usr/local/lib/python3.10/site-packages/mlflow/tracking/fluent.py", line 152, in set_experiment
    experiment_id = client.create_experiment(experiment_name)
  File "/usr/local/lib/python3.10/site-packages/mlflow/tracking/client.py", line 598, in create_experiment
    return self._tracking_client.create_experiment(name, artifact_location, tags)
  File "/usr/local/lib/python3.10/site-packages/mlflow/tracking/_tracking_service/client.py", line 254, in create_experiment
    return self.store.create_experiment(
  File "/usr/local/lib/python3.10/site-packages/mlflow/store/tracking/rest_store.py", line 101, in create_experiment
    response_proto = self._call_endpoint(CreateExperiment, req_body)
  File "/usr/local/lib/python3.10/site-packages/mlflow/store/tracking/rest_store.py", line 60, in _call_endpoint
    return call_endpoint(self.get_host_creds(), endpoint, method, json_body, response_proto)
  File "/usr/local/lib/python3.10/site-packages/mlflow/utils/rest_utils.py", line 290, in call_endpoint
    response = verify_rest_response(response, endpoint)
  File "/usr/local/lib/python3.10/site-packages/mlflow/utils/rest_utils.py", line 173, in verify_rest_response
    raise RestException(json.loads(response.text))
mlflow.exceptions.RestException: RESOURCE_ALREADY_EXISTS: Experiment(name=basketball) already exists. Error: (raised as a result of Query-invoked autoflush; consider using a session.no_autoflush block if this flush is occurring prematurely)
(psycopg2.errors.UniqueViolation) duplicate key value violates unique constraint "experiments_name_key"
DETAIL:  Key (name)=(basketball) already exists.

[SQL: INSERT INTO experiments (name, artifact_location, lifecycle_stage, creation_time, last_update_time) VALUES (%(name)s, %(artifact_location)s, %(lifecycle_stage)s, %(creation_time)s, %(last_update_time)s) RETURNING experiments.experiment_id]
[parameters: {'name': 'basketball', 'artifact_location': '', 'lifecycle_stage': 'active', 'creation_time': 1723322009844, 'last_update_time': 1723322009844}]
(Background on this error at: https://sqlalche.me/e/20/gkpj)
2024-08-10T20:33:35 {"block_run_id": 141, "block_uuid": "training:RandomForestRegressor", "pipeline_run_id": 34, "pipeline_schedule_id": 3, "pipeline_uuid": "train_sklearn", "hostname": "2f717878a6d7", "level": "EXCEPTION", "message": "BlockRun 141 (block_uuid: training:RandomForestRegressor) failed.", "timestamp": 1723322015.017323, "uuid": "8d1eab7975c148aba27a33ef39a6e7c3", "error": ["Traceback (most recent call last):\n  File \"/usr/local/lib/python3.10/site-packages/google/cloud/storage/blob.py\", line 2567, in upload_from_file\n    created_json = self._do_upload(\n  File \"/usr/local/lib/python3.10/site-packages/google/cloud/storage/blob.py\", line 2368, in _do_upload\n    response = self._do_multipart_upload(\n  File \"/usr/local/lib/python3.10/site-packages/google/cloud/storage/blob.py\", line 1903, in _do_multipart_upload\n    response = upload.transmit(\n  File \"/usr/local/lib/python3.10/site-packages/google/resumable_media/requests/upload.py\", line 153, in transmit\n    return _request_helpers.wait_and_retry(\n  File \"/usr/local/lib/python3.10/site-packages/google/resumable_media/requests/_request_helpers.py\", line 155, in wait_and_retry\n    response = func()\n  File \"/usr/local/lib/python3.10/site-packages/google/resumable_media/requests/upload.py\", line 149, in retriable_request\n    self._process_response(result)\n  File \"/usr/local/lib/python3.10/site-packages/google/resumable_media/_upload.py\", line 125, in _process_response\n    _helpers.require_status_code(response, (http.client.OK,), self._get_status_code)\n  File \"/usr/local/lib/python3.10/site-packages/google/resumable_media/_helpers.py\", line 108, in require_status_code\n    raise common.InvalidResponse(\ngoogle.resumable_media.common.InvalidResponse: ('Request failed with status code', 404, 'Expected one of', <HTTPStatus.OK: 200>)\n\nDuring handling of the above exception, another exception occurred:\n\nTraceback (most recent call last):\n  File \"/usr/local/lib/python3.10/site-packages/mage_ai/data_preparation/executors/block_executor.py\", line 647, in execute\n    result = __execute_with_retry()\n  File \"/usr/local/lib/python3.10/site-packages/mage_ai/shared/retry.py\", line 54, in retry_func\n    raise e\n  File \"/usr/local/lib/python3.10/site-packages/mage_ai/shared/retry.py\", line 38, in retry_func\n    return func(*args, **kwargs)\n  File \"/usr/local/lib/python3.10/site-packages/mage_ai/data_preparation/executors/block_executor.py\", line 621, in __execute_with_retry\n    return self._execute(\n  File \"/usr/local/lib/python3.10/site-packages/mage_ai/data_preparation/executors/block_executor.py\", line 1154, in _execute\n    result = self.block.execute_sync(\n  File \"/usr/local/lib/python3.10/site-packages/mage_ai/data_preparation/models/block/__init__.py\", line 1685, in execute_sync\n    return __execute()\n  File \"/usr/local/lib/python3.10/site-packages/mage_ai/data_preparation/models/block/__init__.py\", line 1662, in __execute\n    raise err\n  File \"/usr/local/lib/python3.10/site-packages/mage_ai/data_preparation/models/block/__init__.py\", line 1564, in __execute\n    output = self.execute_block(\n  File \"/usr/local/lib/python3.10/site-packages/mage_ai/data_preparation/models/block/__init__.py\", line 1904, in execute_block\n    outputs = self._execute_block(\n  File \"/usr/local/lib/python3.10/site-packages/mage_ai/data_preparation/models/block/__init__.py\", line 2067, in _execute_block\n    outputs = self.execute_block_function(\n  File \"/usr/local/lib/python3.10/site-packages/mage_ai/data_preparation/models/block/__init__.py\", line 2163, in execute_block_function\n    output = block_function_updated(*input_vars, **global_vars)\n  File \"<string>\", line 33, in hyperparameter_tuning\n  File \"/home/src/Basketball_results_prediction/utils/sklearn.py\", line 138, in tune_hyperparameters\n    best_hyperparameters = fmin(\n  File \"/usr/local/lib/python3.10/site-packages/hyperopt/fmin.py\", line 540, in fmin\n    return trials.fmin(\n  File \"/usr/local/lib/python3.10/site-packages/hyperopt/base.py\", line 671, in fmin\n    return fmin(\n  File \"/usr/local/lib/python3.10/site-packages/hyperopt/fmin.py\", line 586, in fmin\n    rval.exhaust()\n  File \"/usr/local/lib/python3.10/site-packages/hyperopt/fmin.py\", line 364, in exhaust\n    self.run(self.max_evals - n_done, block_until_done=self.asynchronous)\n  File \"/usr/local/lib/python3.10/site-packages/hyperopt/fmin.py\", line 300, in run\n    self.serial_evaluate()\n  File \"/usr/local/lib/python3.10/site-packages/hyperopt/fmin.py\", line 178, in serial_evaluate\n    result = self.domain.evaluate(spec, ctrl)\n  File \"/usr/local/lib/python3.10/site-packages/hyperopt/base.py\", line 892, in evaluate\n    rval = self.fn(pyll_rval)\n  File \"/home/src/Basketball_results_prediction/utils/sklearn.py\", line 122, in __objective\n    mlflow.sklearn.log_model(artifact_path=\"\",sk_model=model)\n  File \"/usr/local/lib/python3.10/site-packages/mlflow/sklearn/__init__.py\", line 418, in log_model\n    return Model.log(\n  File \"/usr/local/lib/python3.10/site-packages/mlflow/models/model.py\", line 656, in log\n    mlflow.tracking.fluent.log_artifacts(local_path, mlflow_model.artifact_path, run_id)\n  File \"/usr/local/lib/python3.10/site-packages/mlflow/tracking/fluent.py\", line 1096, in log_artifacts\n    MlflowClient().log_artifacts(run_id, local_dir, artifact_path)\n  File \"/usr/local/lib/python3.10/site-packages/mlflow/tracking/client.py\", line 1242, in log_artifacts\n    self._tracking_client.log_artifacts(run_id, local_dir, artifact_path)\n  File \"/usr/local/lib/python3.10/site-packages/mlflow/tracking/_tracking_service/client.py\", line 570, in log_artifacts\n    self._get_artifact_repo(run_id).log_artifacts(local_dir, artifact_path)\n  File \"/usr/local/lib/python3.10/site-packages/mlflow/store/artifact/gcs_artifact_repo.py\", line 106, in log_artifacts\n    gcs_bucket.blob(path, chunk_size=self._GCS_UPLOAD_CHUNK_SIZE).upload_from_filename(\n  File \"/usr/local/lib/python3.10/site-packages/google/cloud/storage/blob.py\", line 2708, in upload_from_filename\n    self.upload_from_file(\n  File \"/usr/local/lib/python3.10/site-packages/google/cloud/storage/blob.py\", line 2584, in upload_from_file\n    _raise_from_invalid_response(exc)\n  File \"/usr/local/lib/python3.10/site-packages/google/cloud/storage/blob.py\", line 4457, in _raise_from_invalid_response\n    raise exceptions.from_http_status(response.status_code, message, response=response)\ngoogle.api_core.exceptions.NotFound: 404 POST https://storage.googleapis.com/upload/storage/v1/b/test-mlops-philippov/o?uploadType=multipart: {\n  \"error\": {\n    \"code\": 404,\n    \"message\": \"The specified bucket does not exist.\",\n    \"errors\": [\n      {\n        \"message\": \"The specified bucket does not exist.\",\n        \"domain\": \"global\",\n        \"reason\": \"notFound\"\n      }\n    ]\n  }\n}\n: ('Request failed with status code', 404, 'Expected one of', <HTTPStatus.OK: 200>)\n"], "error_stack": [["  File \"/usr/local/bin/mage\", line 8, in <module>\n    sys.exit(app())\n", "  File \"/usr/local/lib/python3.10/site-packages/typer/main.py\", line 311, in __call__\n    return get_command(self)(*args, **kwargs)\n", "  File \"/usr/local/lib/python3.10/site-packages/click/core.py\", line 1130, in __call__\n    return self.main(*args, **kwargs)\n", "  File \"/usr/local/lib/python3.10/site-packages/typer/core.py\", line 778, in main\n    return _main(\n", "  File \"/usr/local/lib/python3.10/site-packages/typer/core.py\", line 216, in _main\n    rv = self.invoke(ctx)\n", "  File \"/usr/local/lib/python3.10/site-packages/click/core.py\", line 1657, in invoke\n    return _process_result(sub_ctx.command.invoke(sub_ctx))\n", "  File \"/usr/local/lib/python3.10/site-packages/click/core.py\", line 1404, in invoke\n    return ctx.invoke(self.callback, **ctx.params)\n", "  File \"/usr/local/lib/python3.10/site-packages/click/core.py\", line 760, in invoke\n    return __callback(*args, **kwargs)\n", "  File \"/usr/local/lib/python3.10/site-packages/typer/main.py\", line 683, in wrapper\n    return callback(**use_params)  # type: ignore\n", "  File \"/usr/local/lib/python3.10/site-packages/mage_ai/cli/main.py\", line 147, in start\n    start_server(\n", "  File \"/usr/local/lib/python3.10/site-packages/mage_ai/server/server.py\", line 792, in start_server\n    scheduler_manager.start_scheduler()\n", "  File \"/usr/local/lib/python3.10/site-packages/mage_ai/server/scheduler_manager.py\", line 106, in start_scheduler\n    proc.start()\n", "  File \"/usr/local/lib/python3.10/multiprocessing/process.py\", line 121, in start\n    self._popen = self._Popen(self)\n", "  File \"/usr/local/lib/python3.10/multiprocessing/context.py\", line 224, in _Popen\n    return _default_context.get_context().Process._Popen(process_obj)\n", "  File \"/usr/local/lib/python3.10/multiprocessing/context.py\", line 281, in _Popen\n    return Popen(process_obj)\n", "  File \"/usr/local/lib/python3.10/multiprocessing/popen_fork.py\", line 19, in __init__\n    self._launch(process_obj)\n", "  File \"/usr/local/lib/python3.10/multiprocessing/popen_fork.py\", line 71, in _launch\n    code = process_obj._bootstrap(parent_sentinel=child_r)\n", "  File \"/usr/local/lib/python3.10/multiprocessing/process.py\", line 314, in _bootstrap\n    self.run()\n", "  File \"/usr/local/lib/python3.10/multiprocessing/process.py\", line 108, in run\n    self._target(*self._args, **self._kwargs)\n", "  File \"/usr/local/lib/python3.10/site-packages/mage_ai/orchestration/db/process.py\", line 15, in start_session_and_run\n    results = target(*args)\n", "  File \"/usr/local/lib/python3.10/site-packages/mage_ai/server/scheduler_manager.py\", line 58, in run_scheduler\n    LoopTimeTrigger().start()\n", "  File \"/usr/local/lib/python3.10/site-packages/mage_ai/orchestration/triggers/loop_time_trigger.py\", line 14, in start\n    self.run()\n", "  File \"/usr/local/lib/python3.10/site-packages/mage_ai/orchestration/triggers/time_trigger.py\", line 11, in run\n    schedule_all()\n", "  File \"/usr/local/lib/python3.10/site-packages/mage_ai/orchestration/pipeline_scheduler_original.py\", line 1703, in schedule_all\n    PipelineScheduler(r).start()\n", "  File \"/usr/local/lib/python3.10/site-packages/mage_ai/orchestration/db/__init__.py\", line 158, in func_with_rollback\n    return func(*args, **kwargs)\n", "  File \"/usr/local/lib/python3.10/site-packages/mage_ai/orchestration/pipeline_scheduler_original.py\", line 198, in start\n    self.schedule()\n", "  File \"/usr/local/lib/python3.10/site-packages/mage_ai/orchestration/db/__init__.py\", line 158, in func_with_rollback\n    return func(*args, **kwargs)\n", "  File \"/usr/local/lib/python3.10/site-packages/mage_ai/orchestration/pipeline_scheduler_original.py\", line 334, in schedule\n    self.__schedule_blocks(block_runs)\n", "  File \"/usr/local/lib/python3.10/site-packages/mage_ai/orchestration/pipeline_scheduler_original.py\", line 641, in __schedule_blocks\n    job_manager.add_job(\n", "  File \"/usr/local/lib/python3.10/site-packages/mage_ai/orchestration/job_manager.py\", line 20, in add_job\n    self.queue.enqueue(job_id, target, *args, **kwargs)\n", "  File \"/usr/local/lib/python3.10/site-packages/mage_ai/orchestration/queue/process_queue.py\", line 121, in enqueue\n    self.start_worker_pool()\n", "  File \"/usr/local/lib/python3.10/site-packages/mage_ai/orchestration/queue/process_queue.py\", line 198, in start_worker_pool\n    self.worker_pool_proc.start()\n", "  File \"/usr/local/lib/python3.10/multiprocessing/process.py\", line 121, in start\n    self._popen = self._Popen(self)\n", "  File \"/usr/local/lib/python3.10/multiprocessing/context.py\", line 224, in _Popen\n    return _default_context.get_context().Process._Popen(process_obj)\n", "  File \"/usr/local/lib/python3.10/multiprocessing/context.py\", line 281, in _Popen\n    return Popen(process_obj)\n", "  File \"/usr/local/lib/python3.10/multiprocessing/popen_fork.py\", line 19, in __init__\n    self._launch(process_obj)\n", "  File \"/usr/local/lib/python3.10/multiprocessing/popen_fork.py\", line 71, in _launch\n    code = process_obj._bootstrap(parent_sentinel=child_r)\n", "  File \"/usr/local/lib/python3.10/multiprocessing/process.py\", line 314, in _bootstrap\n    self.run()\n", "  File \"/usr/local/lib/python3.10/multiprocessing/process.py\", line 108, in run\n    self._target(*self._args, **self._kwargs)\n", "  File \"/usr/local/lib/python3.10/site-packages/mage_ai/orchestration/queue/process_queue.py\", line 351, in poll_job_and_execute\n    worker.start()\n", "  File \"/usr/local/lib/python3.10/multiprocessing/process.py\", line 121, in start\n    self._popen = self._Popen(self)\n", "  File \"/usr/local/lib/python3.10/multiprocessing/context.py\", line 224, in _Popen\n    return _default_context.get_context().Process._Popen(process_obj)\n", "  File \"/usr/local/lib/python3.10/multiprocessing/context.py\", line 281, in _Popen\n    return Popen(process_obj)\n", "  File \"/usr/local/lib/python3.10/multiprocessing/popen_fork.py\", line 19, in __init__\n    self._launch(process_obj)\n", "  File \"/usr/local/lib/python3.10/multiprocessing/popen_fork.py\", line 71, in _launch\n    code = process_obj._bootstrap(parent_sentinel=child_r)\n", "  File \"/usr/local/lib/python3.10/multiprocessing/process.py\", line 314, in _bootstrap\n    self.run()\n", "  File \"/usr/local/lib/python3.10/site-packages/newrelic/api/background_task.py\", line 117, in wrapper\n    return wrapped(*args, **kwargs)\n", "  File \"/usr/local/lib/python3.10/site-packages/mage_ai/orchestration/queue/process_queue.py\", line 315, in run\n    start_session_and_run(args[1], *args[2], **args[3])\n", "  File \"/usr/local/lib/python3.10/site-packages/mage_ai/orchestration/db/process.py\", line 15, in start_session_and_run\n    results = target(*args)\n", "  File \"/usr/local/lib/python3.10/site-packages/mage_ai/orchestration/pipeline_scheduler_original.py\", line 1236, in run_block\n    return ExecutorFactory.get_block_executor(\n", "  File \"/usr/local/lib/python3.10/site-packages/mage_ai/data_preparation/executors/block_executor.py\", line 682, in execute\n    on_failure(\n", "  File \"/usr/local/lib/python3.10/site-packages/mage_ai/orchestration/db/__init__.py\", line 158, in func_with_rollback\n    return func(*args, **kwargs)\n", "  File \"/usr/local/lib/python3.10/site-packages/mage_ai/orchestration/pipeline_scheduler_original.py\", line 465, in on_block_failure\n    self.logger.exception(\n", "  File \"/usr/local/lib/python3.10/site-packages/mage_ai/data_preparation/logging/logger.py\", line 30, in exception\n    self.__send_message('exception', message, **kwargs)\n", "  File \"/usr/local/lib/python3.10/site-packages/mage_ai/data_preparation/logging/logger.py\", line 65, in __send_message\n    data['error_stack'] = traceback.format_stack(),\n"]], "error_stacktrace": ["404 POST https://storage.googleapis.com/upload/storage/v1/b/test-mlops-philippov/o?uploadType=multipart: {\n  \"error\": {\n    \"code\": 404,\n    \"message\": \"The specified bucket does not exist.\",\n    \"errors\": [\n      {\n        \"message\": \"The specified bucket does not exist.\",\n        \"domain\": \"global\",\n        \"reason\": \"notFound\"\n      }\n    ]\n  }\n}\n: ('Request failed with status code', 404, 'Expected one of', <HTTPStatus.OK: 200>)"]}
Traceback (most recent call last):
  File "/usr/local/lib/python3.10/site-packages/google/cloud/storage/blob.py", line 2567, in upload_from_file
    created_json = self._do_upload(
  File "/usr/local/lib/python3.10/site-packages/google/cloud/storage/blob.py", line 2368, in _do_upload
    response = self._do_multipart_upload(
  File "/usr/local/lib/python3.10/site-packages/google/cloud/storage/blob.py", line 1903, in _do_multipart_upload
    response = upload.transmit(
  File "/usr/local/lib/python3.10/site-packages/google/resumable_media/requests/upload.py", line 153, in transmit
    return _request_helpers.wait_and_retry(
  File "/usr/local/lib/python3.10/site-packages/google/resumable_media/requests/_request_helpers.py", line 155, in wait_and_retry
    response = func()
  File "/usr/local/lib/python3.10/site-packages/google/resumable_media/requests/upload.py", line 149, in retriable_request
    self._process_response(result)
  File "/usr/local/lib/python3.10/site-packages/google/resumable_media/_upload.py", line 125, in _process_response
    _helpers.require_status_code(response, (http.client.OK,), self._get_status_code)
  File "/usr/local/lib/python3.10/site-packages/google/resumable_media/_helpers.py", line 108, in require_status_code
    raise common.InvalidResponse(
google.resumable_media.common.InvalidResponse: ('Request failed with status code', 404, 'Expected one of', <HTTPStatus.OK: 200>)

During handling of the above exception, another exception occurred:

Traceback (most recent call last):
  File "/usr/local/lib/python3.10/site-packages/mage_ai/data_preparation/executors/block_executor.py", line 647, in execute
    result = __execute_with_retry()
  File "/usr/local/lib/python3.10/site-packages/mage_ai/shared/retry.py", line 54, in retry_func
    raise e
  File "/usr/local/lib/python3.10/site-packages/mage_ai/shared/retry.py", line 38, in retry_func
    return func(*args, **kwargs)
  File "/usr/local/lib/python3.10/site-packages/mage_ai/data_preparation/executors/block_executor.py", line 621, in __execute_with_retry
    return self._execute(
  File "/usr/local/lib/python3.10/site-packages/mage_ai/data_preparation/executors/block_executor.py", line 1154, in _execute
    result = self.block.execute_sync(
  File "/usr/local/lib/python3.10/site-packages/mage_ai/data_preparation/models/block/__init__.py", line 1685, in execute_sync
    return __execute()
  File "/usr/local/lib/python3.10/site-packages/mage_ai/data_preparation/models/block/__init__.py", line 1662, in __execute
    raise err
  File "/usr/local/lib/python3.10/site-packages/mage_ai/data_preparation/models/block/__init__.py", line 1564, in __execute
    output = self.execute_block(
  File "/usr/local/lib/python3.10/site-packages/mage_ai/data_preparation/models/block/__init__.py", line 1904, in execute_block
    outputs = self._execute_block(
  File "/usr/local/lib/python3.10/site-packages/mage_ai/data_preparation/models/block/__init__.py", line 2067, in _execute_block
    outputs = self.execute_block_function(
  File "/usr/local/lib/python3.10/site-packages/mage_ai/data_preparation/models/block/__init__.py", line 2163, in execute_block_function
    output = block_function_updated(*input_vars, **global_vars)
  File "<string>", line 33, in hyperparameter_tuning
  File "/home/src/Basketball_results_prediction/utils/sklearn.py", line 138, in tune_hyperparameters
    best_hyperparameters = fmin(
  File "/usr/local/lib/python3.10/site-packages/hyperopt/fmin.py", line 540, in fmin
    return trials.fmin(
  File "/usr/local/lib/python3.10/site-packages/hyperopt/base.py", line 671, in fmin
    return fmin(
  File "/usr/local/lib/python3.10/site-packages/hyperopt/fmin.py", line 586, in fmin
    rval.exhaust()
  File "/usr/local/lib/python3.10/site-packages/hyperopt/fmin.py", line 364, in exhaust
    self.run(self.max_evals - n_done, block_until_done=self.asynchronous)
  File "/usr/local/lib/python3.10/site-packages/hyperopt/fmin.py", line 300, in run
    self.serial_evaluate()
  File "/usr/local/lib/python3.10/site-packages/hyperopt/fmin.py", line 178, in serial_evaluate
    result = self.domain.evaluate(spec, ctrl)
  File "/usr/local/lib/python3.10/site-packages/hyperopt/base.py", line 892, in evaluate
    rval = self.fn(pyll_rval)
  File "/home/src/Basketball_results_prediction/utils/sklearn.py", line 122, in __objective
    mlflow.sklearn.log_model(artifact_path="",sk_model=model)
  File "/usr/local/lib/python3.10/site-packages/mlflow/sklearn/__init__.py", line 418, in log_model
    return Model.log(
  File "/usr/local/lib/python3.10/site-packages/mlflow/models/model.py", line 656, in log
    mlflow.tracking.fluent.log_artifacts(local_path, mlflow_model.artifact_path, run_id)
  File "/usr/local/lib/python3.10/site-packages/mlflow/tracking/fluent.py", line 1096, in log_artifacts
    MlflowClient().log_artifacts(run_id, local_dir, artifact_path)
  File "/usr/local/lib/python3.10/site-packages/mlflow/tracking/client.py", line 1242, in log_artifacts
    self._tracking_client.log_artifacts(run_id, local_dir, artifact_path)
  File "/usr/local/lib/python3.10/site-packages/mlflow/tracking/_tracking_service/client.py", line 570, in log_artifacts
    self._get_artifact_repo(run_id).log_artifacts(local_dir, artifact_path)
  File "/usr/local/lib/python3.10/site-packages/mlflow/store/artifact/gcs_artifact_repo.py", line 106, in log_artifacts
    gcs_bucket.blob(path, chunk_size=self._GCS_UPLOAD_CHUNK_SIZE).upload_from_filename(
  File "/usr/local/lib/python3.10/site-packages/google/cloud/storage/blob.py", line 2708, in upload_from_filename
    self.upload_from_file(
  File "/usr/local/lib/python3.10/site-packages/google/cloud/storage/blob.py", line 2584, in upload_from_file
    _raise_from_invalid_response(exc)
  File "/usr/local/lib/python3.10/site-packages/google/cloud/storage/blob.py", line 4457, in _raise_from_invalid_response
    raise exceptions.from_http_status(response.status_code, message, response=response)
google.api_core.exceptions.NotFound: 404 POST https://storage.googleapis.com/upload/storage/v1/b/test-mlops-philippov/o?uploadType=multipart: {
  "error": {
    "code": 404,
    "message": "The specified bucket does not exist.",
    "errors": [
      {
        "message": "The specified bucket does not exist.",
        "domain": "global",
        "reason": "notFound"
      }
    ]
  }
}
: ('Request failed with status code', 404, 'Expected one of', <HTTPStatus.OK: 200>)
2024-08-10T20:33:35 {"block_run_id": 138, "block_uuid": "training:GradientBoostingRegressor", "pipeline_run_id": 34, "pipeline_schedule_id": 3, "pipeline_uuid": "train_sklearn", "hostname": "2f717878a6d7", "level": "EXCEPTION", "message": "BlockRun 138 (block_uuid: training:GradientBoostingRegressor) failed.", "timestamp": 1723322015.566536, "uuid": "ab856bffa1d64dfea98fc48f3add0b8d", "error": ["Traceback (most recent call last):\n  File \"/usr/local/lib/python3.10/site-packages/google/cloud/storage/blob.py\", line 2567, in upload_from_file\n    created_json = self._do_upload(\n  File \"/usr/local/lib/python3.10/site-packages/google/cloud/storage/blob.py\", line 2368, in _do_upload\n    response = self._do_multipart_upload(\n  File \"/usr/local/lib/python3.10/site-packages/google/cloud/storage/blob.py\", line 1903, in _do_multipart_upload\n    response = upload.transmit(\n  File \"/usr/local/lib/python3.10/site-packages/google/resumable_media/requests/upload.py\", line 153, in transmit\n    return _request_helpers.wait_and_retry(\n  File \"/usr/local/lib/python3.10/site-packages/google/resumable_media/requests/_request_helpers.py\", line 155, in wait_and_retry\n    response = func()\n  File \"/usr/local/lib/python3.10/site-packages/google/resumable_media/requests/upload.py\", line 149, in retriable_request\n    self._process_response(result)\n  File \"/usr/local/lib/python3.10/site-packages/google/resumable_media/_upload.py\", line 125, in _process_response\n    _helpers.require_status_code(response, (http.client.OK,), self._get_status_code)\n  File \"/usr/local/lib/python3.10/site-packages/google/resumable_media/_helpers.py\", line 108, in require_status_code\n    raise common.InvalidResponse(\ngoogle.resumable_media.common.InvalidResponse: ('Request failed with status code', 404, 'Expected one of', <HTTPStatus.OK: 200>)\n\nDuring handling of the above exception, another exception occurred:\n\nTraceback (most recent call last):\n  File \"/usr/local/lib/python3.10/site-packages/mage_ai/data_preparation/executors/block_executor.py\", line 647, in execute\n    result = __execute_with_retry()\n  File \"/usr/local/lib/python3.10/site-packages/mage_ai/shared/retry.py\", line 54, in retry_func\n    raise e\n  File \"/usr/local/lib/python3.10/site-packages/mage_ai/shared/retry.py\", line 38, in retry_func\n    return func(*args, **kwargs)\n  File \"/usr/local/lib/python3.10/site-packages/mage_ai/data_preparation/executors/block_executor.py\", line 621, in __execute_with_retry\n    return self._execute(\n  File \"/usr/local/lib/python3.10/site-packages/mage_ai/data_preparation/executors/block_executor.py\", line 1154, in _execute\n    result = self.block.execute_sync(\n  File \"/usr/local/lib/python3.10/site-packages/mage_ai/data_preparation/models/block/__init__.py\", line 1685, in execute_sync\n    return __execute()\n  File \"/usr/local/lib/python3.10/site-packages/mage_ai/data_preparation/models/block/__init__.py\", line 1662, in __execute\n    raise err\n  File \"/usr/local/lib/python3.10/site-packages/mage_ai/data_preparation/models/block/__init__.py\", line 1564, in __execute\n    output = self.execute_block(\n  File \"/usr/local/lib/python3.10/site-packages/mage_ai/data_preparation/models/block/__init__.py\", line 1904, in execute_block\n    outputs = self._execute_block(\n  File \"/usr/local/lib/python3.10/site-packages/mage_ai/data_preparation/models/block/__init__.py\", line 2067, in _execute_block\n    outputs = self.execute_block_function(\n  File \"/usr/local/lib/python3.10/site-packages/mage_ai/data_preparation/models/block/__init__.py\", line 2163, in execute_block_function\n    output = block_function_updated(*input_vars, **global_vars)\n  File \"<string>\", line 33, in hyperparameter_tuning\n  File \"/home/src/Basketball_results_prediction/utils/sklearn.py\", line 138, in tune_hyperparameters\n    best_hyperparameters = fmin(\n  File \"/usr/local/lib/python3.10/site-packages/hyperopt/fmin.py\", line 540, in fmin\n    return trials.fmin(\n  File \"/usr/local/lib/python3.10/site-packages/hyperopt/base.py\", line 671, in fmin\n    return fmin(\n  File \"/usr/local/lib/python3.10/site-packages/hyperopt/fmin.py\", line 586, in fmin\n    rval.exhaust()\n  File \"/usr/local/lib/python3.10/site-packages/hyperopt/fmin.py\", line 364, in exhaust\n    self.run(self.max_evals - n_done, block_until_done=self.asynchronous)\n  File \"/usr/local/lib/python3.10/site-packages/hyperopt/fmin.py\", line 300, in run\n    self.serial_evaluate()\n  File \"/usr/local/lib/python3.10/site-packages/hyperopt/fmin.py\", line 178, in serial_evaluate\n    result = self.domain.evaluate(spec, ctrl)\n  File \"/usr/local/lib/python3.10/site-packages/hyperopt/base.py\", line 892, in evaluate\n    rval = self.fn(pyll_rval)\n  File \"/home/src/Basketball_results_prediction/utils/sklearn.py\", line 122, in __objective\n    mlflow.sklearn.log_model(artifact_path=\"\",sk_model=model)\n  File \"/usr/local/lib/python3.10/site-packages/mlflow/sklearn/__init__.py\", line 418, in log_model\n    return Model.log(\n  File \"/usr/local/lib/python3.10/site-packages/mlflow/models/model.py\", line 656, in log\n    mlflow.tracking.fluent.log_artifacts(local_path, mlflow_model.artifact_path, run_id)\n  File \"/usr/local/lib/python3.10/site-packages/mlflow/tracking/fluent.py\", line 1096, in log_artifacts\n    MlflowClient().log_artifacts(run_id, local_dir, artifact_path)\n  File \"/usr/local/lib/python3.10/site-packages/mlflow/tracking/client.py\", line 1242, in log_artifacts\n    self._tracking_client.log_artifacts(run_id, local_dir, artifact_path)\n  File \"/usr/local/lib/python3.10/site-packages/mlflow/tracking/_tracking_service/client.py\", line 570, in log_artifacts\n    self._get_artifact_repo(run_id).log_artifacts(local_dir, artifact_path)\n  File \"/usr/local/lib/python3.10/site-packages/mlflow/store/artifact/gcs_artifact_repo.py\", line 106, in log_artifacts\n    gcs_bucket.blob(path, chunk_size=self._GCS_UPLOAD_CHUNK_SIZE).upload_from_filename(\n  File \"/usr/local/lib/python3.10/site-packages/google/cloud/storage/blob.py\", line 2708, in upload_from_filename\n    self.upload_from_file(\n  File \"/usr/local/lib/python3.10/site-packages/google/cloud/storage/blob.py\", line 2584, in upload_from_file\n    _raise_from_invalid_response(exc)\n  File \"/usr/local/lib/python3.10/site-packages/google/cloud/storage/blob.py\", line 4457, in _raise_from_invalid_response\n    raise exceptions.from_http_status(response.status_code, message, response=response)\ngoogle.api_core.exceptions.NotFound: 404 POST https://storage.googleapis.com/upload/storage/v1/b/test-mlops-philippov/o?uploadType=multipart: {\n  \"error\": {\n    \"code\": 404,\n    \"message\": \"The specified bucket does not exist.\",\n    \"errors\": [\n      {\n        \"message\": \"The specified bucket does not exist.\",\n        \"domain\": \"global\",\n        \"reason\": \"notFound\"\n      }\n    ]\n  }\n}\n: ('Request failed with status code', 404, 'Expected one of', <HTTPStatus.OK: 200>)\n"], "error_stack": [["  File \"/usr/local/bin/mage\", line 8, in <module>\n    sys.exit(app())\n", "  File \"/usr/local/lib/python3.10/site-packages/typer/main.py\", line 311, in __call__\n    return get_command(self)(*args, **kwargs)\n", "  File \"/usr/local/lib/python3.10/site-packages/click/core.py\", line 1130, in __call__\n    return self.main(*args, **kwargs)\n", "  File \"/usr/local/lib/python3.10/site-packages/typer/core.py\", line 778, in main\n    return _main(\n", "  File \"/usr/local/lib/python3.10/site-packages/typer/core.py\", line 216, in _main\n    rv = self.invoke(ctx)\n", "  File \"/usr/local/lib/python3.10/site-packages/click/core.py\", line 1657, in invoke\n    return _process_result(sub_ctx.command.invoke(sub_ctx))\n", "  File \"/usr/local/lib/python3.10/site-packages/click/core.py\", line 1404, in invoke\n    return ctx.invoke(self.callback, **ctx.params)\n", "  File \"/usr/local/lib/python3.10/site-packages/click/core.py\", line 760, in invoke\n    return __callback(*args, **kwargs)\n", "  File \"/usr/local/lib/python3.10/site-packages/typer/main.py\", line 683, in wrapper\n    return callback(**use_params)  # type: ignore\n", "  File \"/usr/local/lib/python3.10/site-packages/mage_ai/cli/main.py\", line 147, in start\n    start_server(\n", "  File \"/usr/local/lib/python3.10/site-packages/mage_ai/server/server.py\", line 792, in start_server\n    scheduler_manager.start_scheduler()\n", "  File \"/usr/local/lib/python3.10/site-packages/mage_ai/server/scheduler_manager.py\", line 106, in start_scheduler\n    proc.start()\n", "  File \"/usr/local/lib/python3.10/multiprocessing/process.py\", line 121, in start\n    self._popen = self._Popen(self)\n", "  File \"/usr/local/lib/python3.10/multiprocessing/context.py\", line 224, in _Popen\n    return _default_context.get_context().Process._Popen(process_obj)\n", "  File \"/usr/local/lib/python3.10/multiprocessing/context.py\", line 281, in _Popen\n    return Popen(process_obj)\n", "  File \"/usr/local/lib/python3.10/multiprocessing/popen_fork.py\", line 19, in __init__\n    self._launch(process_obj)\n", "  File \"/usr/local/lib/python3.10/multiprocessing/popen_fork.py\", line 71, in _launch\n    code = process_obj._bootstrap(parent_sentinel=child_r)\n", "  File \"/usr/local/lib/python3.10/multiprocessing/process.py\", line 314, in _bootstrap\n    self.run()\n", "  File \"/usr/local/lib/python3.10/multiprocessing/process.py\", line 108, in run\n    self._target(*self._args, **self._kwargs)\n", "  File \"/usr/local/lib/python3.10/site-packages/mage_ai/orchestration/db/process.py\", line 15, in start_session_and_run\n    results = target(*args)\n", "  File \"/usr/local/lib/python3.10/site-packages/mage_ai/server/scheduler_manager.py\", line 58, in run_scheduler\n    LoopTimeTrigger().start()\n", "  File \"/usr/local/lib/python3.10/site-packages/mage_ai/orchestration/triggers/loop_time_trigger.py\", line 14, in start\n    self.run()\n", "  File \"/usr/local/lib/python3.10/site-packages/mage_ai/orchestration/triggers/time_trigger.py\", line 11, in run\n    schedule_all()\n", "  File \"/usr/local/lib/python3.10/site-packages/mage_ai/orchestration/pipeline_scheduler_original.py\", line 1703, in schedule_all\n    PipelineScheduler(r).start()\n", "  File \"/usr/local/lib/python3.10/site-packages/mage_ai/orchestration/db/__init__.py\", line 158, in func_with_rollback\n    return func(*args, **kwargs)\n", "  File \"/usr/local/lib/python3.10/site-packages/mage_ai/orchestration/pipeline_scheduler_original.py\", line 198, in start\n    self.schedule()\n", "  File \"/usr/local/lib/python3.10/site-packages/mage_ai/orchestration/db/__init__.py\", line 158, in func_with_rollback\n    return func(*args, **kwargs)\n", "  File \"/usr/local/lib/python3.10/site-packages/mage_ai/orchestration/pipeline_scheduler_original.py\", line 334, in schedule\n    self.__schedule_blocks(block_runs)\n", "  File \"/usr/local/lib/python3.10/site-packages/mage_ai/orchestration/pipeline_scheduler_original.py\", line 641, in __schedule_blocks\n    job_manager.add_job(\n", "  File \"/usr/local/lib/python3.10/site-packages/mage_ai/orchestration/job_manager.py\", line 20, in add_job\n    self.queue.enqueue(job_id, target, *args, **kwargs)\n", "  File \"/usr/local/lib/python3.10/site-packages/mage_ai/orchestration/queue/process_queue.py\", line 121, in enqueue\n    self.start_worker_pool()\n", "  File \"/usr/local/lib/python3.10/site-packages/mage_ai/orchestration/queue/process_queue.py\", line 198, in start_worker_pool\n    self.worker_pool_proc.start()\n", "  File \"/usr/local/lib/python3.10/multiprocessing/process.py\", line 121, in start\n    self._popen = self._Popen(self)\n", "  File \"/usr/local/lib/python3.10/multiprocessing/context.py\", line 224, in _Popen\n    return _default_context.get_context().Process._Popen(process_obj)\n", "  File \"/usr/local/lib/python3.10/multiprocessing/context.py\", line 281, in _Popen\n    return Popen(process_obj)\n", "  File \"/usr/local/lib/python3.10/multiprocessing/popen_fork.py\", line 19, in __init__\n    self._launch(process_obj)\n", "  File \"/usr/local/lib/python3.10/multiprocessing/popen_fork.py\", line 71, in _launch\n    code = process_obj._bootstrap(parent_sentinel=child_r)\n", "  File \"/usr/local/lib/python3.10/multiprocessing/process.py\", line 314, in _bootstrap\n    self.run()\n", "  File \"/usr/local/lib/python3.10/multiprocessing/process.py\", line 108, in run\n    self._target(*self._args, **self._kwargs)\n", "  File \"/usr/local/lib/python3.10/site-packages/mage_ai/orchestration/queue/process_queue.py\", line 351, in poll_job_and_execute\n    worker.start()\n", "  File \"/usr/local/lib/python3.10/multiprocessing/process.py\", line 121, in start\n    self._popen = self._Popen(self)\n", "  File \"/usr/local/lib/python3.10/multiprocessing/context.py\", line 224, in _Popen\n    return _default_context.get_context().Process._Popen(process_obj)\n", "  File \"/usr/local/lib/python3.10/multiprocessing/context.py\", line 281, in _Popen\n    return Popen(process_obj)\n", "  File \"/usr/local/lib/python3.10/multiprocessing/popen_fork.py\", line 19, in __init__\n    self._launch(process_obj)\n", "  File \"/usr/local/lib/python3.10/multiprocessing/popen_fork.py\", line 71, in _launch\n    code = process_obj._bootstrap(parent_sentinel=child_r)\n", "  File \"/usr/local/lib/python3.10/multiprocessing/process.py\", line 314, in _bootstrap\n    self.run()\n", "  File \"/usr/local/lib/python3.10/site-packages/newrelic/api/background_task.py\", line 117, in wrapper\n    return wrapped(*args, **kwargs)\n", "  File \"/usr/local/lib/python3.10/site-packages/mage_ai/orchestration/queue/process_queue.py\", line 315, in run\n    start_session_and_run(args[1], *args[2], **args[3])\n", "  File \"/usr/local/lib/python3.10/site-packages/mage_ai/orchestration/db/process.py\", line 15, in start_session_and_run\n    results = target(*args)\n", "  File \"/usr/local/lib/python3.10/site-packages/mage_ai/orchestration/pipeline_scheduler_original.py\", line 1236, in run_block\n    return ExecutorFactory.get_block_executor(\n", "  File \"/usr/local/lib/python3.10/site-packages/mage_ai/data_preparation/executors/block_executor.py\", line 682, in execute\n    on_failure(\n", "  File \"/usr/local/lib/python3.10/site-packages/mage_ai/orchestration/db/__init__.py\", line 158, in func_with_rollback\n    return func(*args, **kwargs)\n", "  File \"/usr/local/lib/python3.10/site-packages/mage_ai/orchestration/pipeline_scheduler_original.py\", line 465, in on_block_failure\n    self.logger.exception(\n", "  File \"/usr/local/lib/python3.10/site-packages/mage_ai/data_preparation/logging/logger.py\", line 30, in exception\n    self.__send_message('exception', message, **kwargs)\n", "  File \"/usr/local/lib/python3.10/site-packages/mage_ai/data_preparation/logging/logger.py\", line 65, in __send_message\n    data['error_stack'] = traceback.format_stack(),\n"]], "error_stacktrace": ["404 POST https://storage.googleapis.com/upload/storage/v1/b/test-mlops-philippov/o?uploadType=multipart: {\n  \"error\": {\n    \"code\": 404,\n    \"message\": \"The specified bucket does not exist.\",\n    \"errors\": [\n      {\n        \"message\": \"The specified bucket does not exist.\",\n        \"domain\": \"global\",\n        \"reason\": \"notFound\"\n      }\n    ]\n  }\n}\n: ('Request failed with status code', 404, 'Expected one of', <HTTPStatus.OK: 200>)"]}
Traceback (most recent call last):
  File "/usr/local/lib/python3.10/site-packages/google/cloud/storage/blob.py", line 2567, in upload_from_file
    created_json = self._do_upload(
  File "/usr/local/lib/python3.10/site-packages/google/cloud/storage/blob.py", line 2368, in _do_upload
    response = self._do_multipart_upload(
  File "/usr/local/lib/python3.10/site-packages/google/cloud/storage/blob.py", line 1903, in _do_multipart_upload
    response = upload.transmit(
  File "/usr/local/lib/python3.10/site-packages/google/resumable_media/requests/upload.py", line 153, in transmit
    return _request_helpers.wait_and_retry(
  File "/usr/local/lib/python3.10/site-packages/google/resumable_media/requests/_request_helpers.py", line 155, in wait_and_retry
    response = func()
  File "/usr/local/lib/python3.10/site-packages/google/resumable_media/requests/upload.py", line 149, in retriable_request
    self._process_response(result)
  File "/usr/local/lib/python3.10/site-packages/google/resumable_media/_upload.py", line 125, in _process_response
    _helpers.require_status_code(response, (http.client.OK,), self._get_status_code)
  File "/usr/local/lib/python3.10/site-packages/google/resumable_media/_helpers.py", line 108, in require_status_code
    raise common.InvalidResponse(
google.resumable_media.common.InvalidResponse: ('Request failed with status code', 404, 'Expected one of', <HTTPStatus.OK: 200>)

During handling of the above exception, another exception occurred:

Traceback (most recent call last):
  File "/usr/local/lib/python3.10/site-packages/mage_ai/data_preparation/executors/block_executor.py", line 647, in execute
    result = __execute_with_retry()
  File "/usr/local/lib/python3.10/site-packages/mage_ai/shared/retry.py", line 54, in retry_func
    raise e
  File "/usr/local/lib/python3.10/site-packages/mage_ai/shared/retry.py", line 38, in retry_func
    return func(*args, **kwargs)
  File "/usr/local/lib/python3.10/site-packages/mage_ai/data_preparation/executors/block_executor.py", line 621, in __execute_with_retry
    return self._execute(
  File "/usr/local/lib/python3.10/site-packages/mage_ai/data_preparation/executors/block_executor.py", line 1154, in _execute
    result = self.block.execute_sync(
  File "/usr/local/lib/python3.10/site-packages/mage_ai/data_preparation/models/block/__init__.py", line 1685, in execute_sync
    return __execute()
  File "/usr/local/lib/python3.10/site-packages/mage_ai/data_preparation/models/block/__init__.py", line 1662, in __execute
    raise err
  File "/usr/local/lib/python3.10/site-packages/mage_ai/data_preparation/models/block/__init__.py", line 1564, in __execute
    output = self.execute_block(
  File "/usr/local/lib/python3.10/site-packages/mage_ai/data_preparation/models/block/__init__.py", line 1904, in execute_block
    outputs = self._execute_block(
  File "/usr/local/lib/python3.10/site-packages/mage_ai/data_preparation/models/block/__init__.py", line 2067, in _execute_block
    outputs = self.execute_block_function(
  File "/usr/local/lib/python3.10/site-packages/mage_ai/data_preparation/models/block/__init__.py", line 2163, in execute_block_function
    output = block_function_updated(*input_vars, **global_vars)
  File "<string>", line 33, in hyperparameter_tuning
  File "/home/src/Basketball_results_prediction/utils/sklearn.py", line 138, in tune_hyperparameters
    best_hyperparameters = fmin(
  File "/usr/local/lib/python3.10/site-packages/hyperopt/fmin.py", line 540, in fmin
    return trials.fmin(
  File "/usr/local/lib/python3.10/site-packages/hyperopt/base.py", line 671, in fmin
    return fmin(
  File "/usr/local/lib/python3.10/site-packages/hyperopt/fmin.py", line 586, in fmin
    rval.exhaust()
  File "/usr/local/lib/python3.10/site-packages/hyperopt/fmin.py", line 364, in exhaust
    self.run(self.max_evals - n_done, block_until_done=self.asynchronous)
  File "/usr/local/lib/python3.10/site-packages/hyperopt/fmin.py", line 300, in run
    self.serial_evaluate()
  File "/usr/local/lib/python3.10/site-packages/hyperopt/fmin.py", line 178, in serial_evaluate
    result = self.domain.evaluate(spec, ctrl)
  File "/usr/local/lib/python3.10/site-packages/hyperopt/base.py", line 892, in evaluate
    rval = self.fn(pyll_rval)
  File "/home/src/Basketball_results_prediction/utils/sklearn.py", line 122, in __objective
    mlflow.sklearn.log_model(artifact_path="",sk_model=model)
  File "/usr/local/lib/python3.10/site-packages/mlflow/sklearn/__init__.py", line 418, in log_model
    return Model.log(
  File "/usr/local/lib/python3.10/site-packages/mlflow/models/model.py", line 656, in log
    mlflow.tracking.fluent.log_artifacts(local_path, mlflow_model.artifact_path, run_id)
  File "/usr/local/lib/python3.10/site-packages/mlflow/tracking/fluent.py", line 1096, in log_artifacts
    MlflowClient().log_artifacts(run_id, local_dir, artifact_path)
  File "/usr/local/lib/python3.10/site-packages/mlflow/tracking/client.py", line 1242, in log_artifacts
    self._tracking_client.log_artifacts(run_id, local_dir, artifact_path)
  File "/usr/local/lib/python3.10/site-packages/mlflow/tracking/_tracking_service/client.py", line 570, in log_artifacts
    self._get_artifact_repo(run_id).log_artifacts(local_dir, artifact_path)
  File "/usr/local/lib/python3.10/site-packages/mlflow/store/artifact/gcs_artifact_repo.py", line 106, in log_artifacts
    gcs_bucket.blob(path, chunk_size=self._GCS_UPLOAD_CHUNK_SIZE).upload_from_filename(
  File "/usr/local/lib/python3.10/site-packages/google/cloud/storage/blob.py", line 2708, in upload_from_filename
    self.upload_from_file(
  File "/usr/local/lib/python3.10/site-packages/google/cloud/storage/blob.py", line 2584, in upload_from_file
    _raise_from_invalid_response(exc)
  File "/usr/local/lib/python3.10/site-packages/google/cloud/storage/blob.py", line 4457, in _raise_from_invalid_response
    raise exceptions.from_http_status(response.status_code, message, response=response)
google.api_core.exceptions.NotFound: 404 POST https://storage.googleapis.com/upload/storage/v1/b/test-mlops-philippov/o?uploadType=multipart: {
  "error": {
    "code": 404,
    "message": "The specified bucket does not exist.",
    "errors": [
      {
        "message": "The specified bucket does not exist.",
        "domain": "global",
        "reason": "notFound"
      }
    ]
  }
}
: ('Request failed with status code', 404, 'Expected one of', <HTTPStatus.OK: 200>)
2024-08-10T20:33:35 {"block_run_id": 139, "block_uuid": "training:LinearRegression", "pipeline_run_id": 34, "pipeline_schedule_id": 3, "pipeline_uuid": "train_sklearn", "hostname": "2f717878a6d7", "level": "EXCEPTION", "message": "BlockRun 139 (block_uuid: training:LinearRegression) failed.", "timestamp": 1723322015.667111, "uuid": "9c1c303e3d354263ba7f0f23ad137cf3", "error": ["Traceback (most recent call last):\n  File \"/usr/local/lib/python3.10/site-packages/google/cloud/storage/blob.py\", line 2567, in upload_from_file\n    created_json = self._do_upload(\n  File \"/usr/local/lib/python3.10/site-packages/google/cloud/storage/blob.py\", line 2368, in _do_upload\n    response = self._do_multipart_upload(\n  File \"/usr/local/lib/python3.10/site-packages/google/cloud/storage/blob.py\", line 1903, in _do_multipart_upload\n    response = upload.transmit(\n  File \"/usr/local/lib/python3.10/site-packages/google/resumable_media/requests/upload.py\", line 153, in transmit\n    return _request_helpers.wait_and_retry(\n  File \"/usr/local/lib/python3.10/site-packages/google/resumable_media/requests/_request_helpers.py\", line 155, in wait_and_retry\n    response = func()\n  File \"/usr/local/lib/python3.10/site-packages/google/resumable_media/requests/upload.py\", line 149, in retriable_request\n    self._process_response(result)\n  File \"/usr/local/lib/python3.10/site-packages/google/resumable_media/_upload.py\", line 125, in _process_response\n    _helpers.require_status_code(response, (http.client.OK,), self._get_status_code)\n  File \"/usr/local/lib/python3.10/site-packages/google/resumable_media/_helpers.py\", line 108, in require_status_code\n    raise common.InvalidResponse(\ngoogle.resumable_media.common.InvalidResponse: ('Request failed with status code', 404, 'Expected one of', <HTTPStatus.OK: 200>)\n\nDuring handling of the above exception, another exception occurred:\n\nTraceback (most recent call last):\n  File \"/usr/local/lib/python3.10/site-packages/mage_ai/data_preparation/executors/block_executor.py\", line 647, in execute\n    result = __execute_with_retry()\n  File \"/usr/local/lib/python3.10/site-packages/mage_ai/shared/retry.py\", line 54, in retry_func\n    raise e\n  File \"/usr/local/lib/python3.10/site-packages/mage_ai/shared/retry.py\", line 38, in retry_func\n    return func(*args, **kwargs)\n  File \"/usr/local/lib/python3.10/site-packages/mage_ai/data_preparation/executors/block_executor.py\", line 621, in __execute_with_retry\n    return self._execute(\n  File \"/usr/local/lib/python3.10/site-packages/mage_ai/data_preparation/executors/block_executor.py\", line 1154, in _execute\n    result = self.block.execute_sync(\n  File \"/usr/local/lib/python3.10/site-packages/mage_ai/data_preparation/models/block/__init__.py\", line 1685, in execute_sync\n    return __execute()\n  File \"/usr/local/lib/python3.10/site-packages/mage_ai/data_preparation/models/block/__init__.py\", line 1662, in __execute\n    raise err\n  File \"/usr/local/lib/python3.10/site-packages/mage_ai/data_preparation/models/block/__init__.py\", line 1564, in __execute\n    output = self.execute_block(\n  File \"/usr/local/lib/python3.10/site-packages/mage_ai/data_preparation/models/block/__init__.py\", line 1904, in execute_block\n    outputs = self._execute_block(\n  File \"/usr/local/lib/python3.10/site-packages/mage_ai/data_preparation/models/block/__init__.py\", line 2067, in _execute_block\n    outputs = self.execute_block_function(\n  File \"/usr/local/lib/python3.10/site-packages/mage_ai/data_preparation/models/block/__init__.py\", line 2163, in execute_block_function\n    output = block_function_updated(*input_vars, **global_vars)\n  File \"<string>\", line 33, in hyperparameter_tuning\n  File \"/home/src/Basketball_results_prediction/utils/sklearn.py\", line 138, in tune_hyperparameters\n    best_hyperparameters = fmin(\n  File \"/usr/local/lib/python3.10/site-packages/hyperopt/fmin.py\", line 540, in fmin\n    return trials.fmin(\n  File \"/usr/local/lib/python3.10/site-packages/hyperopt/base.py\", line 671, in fmin\n    return fmin(\n  File \"/usr/local/lib/python3.10/site-packages/hyperopt/fmin.py\", line 586, in fmin\n    rval.exhaust()\n  File \"/usr/local/lib/python3.10/site-packages/hyperopt/fmin.py\", line 364, in exhaust\n    self.run(self.max_evals - n_done, block_until_done=self.asynchronous)\n  File \"/usr/local/lib/python3.10/site-packages/hyperopt/fmin.py\", line 300, in run\n    self.serial_evaluate()\n  File \"/usr/local/lib/python3.10/site-packages/hyperopt/fmin.py\", line 178, in serial_evaluate\n    result = self.domain.evaluate(spec, ctrl)\n  File \"/usr/local/lib/python3.10/site-packages/hyperopt/base.py\", line 892, in evaluate\n    rval = self.fn(pyll_rval)\n  File \"/home/src/Basketball_results_prediction/utils/sklearn.py\", line 122, in __objective\n    mlflow.sklearn.log_model(artifact_path=\"\",sk_model=model)\n  File \"/usr/local/lib/python3.10/site-packages/mlflow/sklearn/__init__.py\", line 418, in log_model\n    return Model.log(\n  File \"/usr/local/lib/python3.10/site-packages/mlflow/models/model.py\", line 656, in log\n    mlflow.tracking.fluent.log_artifacts(local_path, mlflow_model.artifact_path, run_id)\n  File \"/usr/local/lib/python3.10/site-packages/mlflow/tracking/fluent.py\", line 1096, in log_artifacts\n    MlflowClient().log_artifacts(run_id, local_dir, artifact_path)\n  File \"/usr/local/lib/python3.10/site-packages/mlflow/tracking/client.py\", line 1242, in log_artifacts\n    self._tracking_client.log_artifacts(run_id, local_dir, artifact_path)\n  File \"/usr/local/lib/python3.10/site-packages/mlflow/tracking/_tracking_service/client.py\", line 570, in log_artifacts\n    self._get_artifact_repo(run_id).log_artifacts(local_dir, artifact_path)\n  File \"/usr/local/lib/python3.10/site-packages/mlflow/store/artifact/gcs_artifact_repo.py\", line 106, in log_artifacts\n    gcs_bucket.blob(path, chunk_size=self._GCS_UPLOAD_CHUNK_SIZE).upload_from_filename(\n  File \"/usr/local/lib/python3.10/site-packages/google/cloud/storage/blob.py\", line 2708, in upload_from_filename\n    self.upload_from_file(\n  File \"/usr/local/lib/python3.10/site-packages/google/cloud/storage/blob.py\", line 2584, in upload_from_file\n    _raise_from_invalid_response(exc)\n  File \"/usr/local/lib/python3.10/site-packages/google/cloud/storage/blob.py\", line 4457, in _raise_from_invalid_response\n    raise exceptions.from_http_status(response.status_code, message, response=response)\ngoogle.api_core.exceptions.NotFound: 404 POST https://storage.googleapis.com/upload/storage/v1/b/test-mlops-philippov/o?uploadType=multipart: {\n  \"error\": {\n    \"code\": 404,\n    \"message\": \"The specified bucket does not exist.\",\n    \"errors\": [\n      {\n        \"message\": \"The specified bucket does not exist.\",\n        \"domain\": \"global\",\n        \"reason\": \"notFound\"\n      }\n    ]\n  }\n}\n: ('Request failed with status code', 404, 'Expected one of', <HTTPStatus.OK: 200>)\n"], "error_stack": [["  File \"/usr/local/bin/mage\", line 8, in <module>\n    sys.exit(app())\n", "  File \"/usr/local/lib/python3.10/site-packages/typer/main.py\", line 311, in __call__\n    return get_command(self)(*args, **kwargs)\n", "  File \"/usr/local/lib/python3.10/site-packages/click/core.py\", line 1130, in __call__\n    return self.main(*args, **kwargs)\n", "  File \"/usr/local/lib/python3.10/site-packages/typer/core.py\", line 778, in main\n    return _main(\n", "  File \"/usr/local/lib/python3.10/site-packages/typer/core.py\", line 216, in _main\n    rv = self.invoke(ctx)\n", "  File \"/usr/local/lib/python3.10/site-packages/click/core.py\", line 1657, in invoke\n    return _process_result(sub_ctx.command.invoke(sub_ctx))\n", "  File \"/usr/local/lib/python3.10/site-packages/click/core.py\", line 1404, in invoke\n    return ctx.invoke(self.callback, **ctx.params)\n", "  File \"/usr/local/lib/python3.10/site-packages/click/core.py\", line 760, in invoke\n    return __callback(*args, **kwargs)\n", "  File \"/usr/local/lib/python3.10/site-packages/typer/main.py\", line 683, in wrapper\n    return callback(**use_params)  # type: ignore\n", "  File \"/usr/local/lib/python3.10/site-packages/mage_ai/cli/main.py\", line 147, in start\n    start_server(\n", "  File \"/usr/local/lib/python3.10/site-packages/mage_ai/server/server.py\", line 792, in start_server\n    scheduler_manager.start_scheduler()\n", "  File \"/usr/local/lib/python3.10/site-packages/mage_ai/server/scheduler_manager.py\", line 106, in start_scheduler\n    proc.start()\n", "  File \"/usr/local/lib/python3.10/multiprocessing/process.py\", line 121, in start\n    self._popen = self._Popen(self)\n", "  File \"/usr/local/lib/python3.10/multiprocessing/context.py\", line 224, in _Popen\n    return _default_context.get_context().Process._Popen(process_obj)\n", "  File \"/usr/local/lib/python3.10/multiprocessing/context.py\", line 281, in _Popen\n    return Popen(process_obj)\n", "  File \"/usr/local/lib/python3.10/multiprocessing/popen_fork.py\", line 19, in __init__\n    self._launch(process_obj)\n", "  File \"/usr/local/lib/python3.10/multiprocessing/popen_fork.py\", line 71, in _launch\n    code = process_obj._bootstrap(parent_sentinel=child_r)\n", "  File \"/usr/local/lib/python3.10/multiprocessing/process.py\", line 314, in _bootstrap\n    self.run()\n", "  File \"/usr/local/lib/python3.10/multiprocessing/process.py\", line 108, in run\n    self._target(*self._args, **self._kwargs)\n", "  File \"/usr/local/lib/python3.10/site-packages/mage_ai/orchestration/db/process.py\", line 15, in start_session_and_run\n    results = target(*args)\n", "  File \"/usr/local/lib/python3.10/site-packages/mage_ai/server/scheduler_manager.py\", line 58, in run_scheduler\n    LoopTimeTrigger().start()\n", "  File \"/usr/local/lib/python3.10/site-packages/mage_ai/orchestration/triggers/loop_time_trigger.py\", line 14, in start\n    self.run()\n", "  File \"/usr/local/lib/python3.10/site-packages/mage_ai/orchestration/triggers/time_trigger.py\", line 11, in run\n    schedule_all()\n", "  File \"/usr/local/lib/python3.10/site-packages/mage_ai/orchestration/pipeline_scheduler_original.py\", line 1703, in schedule_all\n    PipelineScheduler(r).start()\n", "  File \"/usr/local/lib/python3.10/site-packages/mage_ai/orchestration/db/__init__.py\", line 158, in func_with_rollback\n    return func(*args, **kwargs)\n", "  File \"/usr/local/lib/python3.10/site-packages/mage_ai/orchestration/pipeline_scheduler_original.py\", line 198, in start\n    self.schedule()\n", "  File \"/usr/local/lib/python3.10/site-packages/mage_ai/orchestration/db/__init__.py\", line 158, in func_with_rollback\n    return func(*args, **kwargs)\n", "  File \"/usr/local/lib/python3.10/site-packages/mage_ai/orchestration/pipeline_scheduler_original.py\", line 334, in schedule\n    self.__schedule_blocks(block_runs)\n", "  File \"/usr/local/lib/python3.10/site-packages/mage_ai/orchestration/pipeline_scheduler_original.py\", line 641, in __schedule_blocks\n    job_manager.add_job(\n", "  File \"/usr/local/lib/python3.10/site-packages/mage_ai/orchestration/job_manager.py\", line 20, in add_job\n    self.queue.enqueue(job_id, target, *args, **kwargs)\n", "  File \"/usr/local/lib/python3.10/site-packages/mage_ai/orchestration/queue/process_queue.py\", line 121, in enqueue\n    self.start_worker_pool()\n", "  File \"/usr/local/lib/python3.10/site-packages/mage_ai/orchestration/queue/process_queue.py\", line 198, in start_worker_pool\n    self.worker_pool_proc.start()\n", "  File \"/usr/local/lib/python3.10/multiprocessing/process.py\", line 121, in start\n    self._popen = self._Popen(self)\n", "  File \"/usr/local/lib/python3.10/multiprocessing/context.py\", line 224, in _Popen\n    return _default_context.get_context().Process._Popen(process_obj)\n", "  File \"/usr/local/lib/python3.10/multiprocessing/context.py\", line 281, in _Popen\n    return Popen(process_obj)\n", "  File \"/usr/local/lib/python3.10/multiprocessing/popen_fork.py\", line 19, in __init__\n    self._launch(process_obj)\n", "  File \"/usr/local/lib/python3.10/multiprocessing/popen_fork.py\", line 71, in _launch\n    code = process_obj._bootstrap(parent_sentinel=child_r)\n", "  File \"/usr/local/lib/python3.10/multiprocessing/process.py\", line 314, in _bootstrap\n    self.run()\n", "  File \"/usr/local/lib/python3.10/multiprocessing/process.py\", line 108, in run\n    self._target(*self._args, **self._kwargs)\n", "  File \"/usr/local/lib/python3.10/site-packages/mage_ai/orchestration/queue/process_queue.py\", line 351, in poll_job_and_execute\n    worker.start()\n", "  File \"/usr/local/lib/python3.10/multiprocessing/process.py\", line 121, in start\n    self._popen = self._Popen(self)\n", "  File \"/usr/local/lib/python3.10/multiprocessing/context.py\", line 224, in _Popen\n    return _default_context.get_context().Process._Popen(process_obj)\n", "  File \"/usr/local/lib/python3.10/multiprocessing/context.py\", line 281, in _Popen\n    return Popen(process_obj)\n", "  File \"/usr/local/lib/python3.10/multiprocessing/popen_fork.py\", line 19, in __init__\n    self._launch(process_obj)\n", "  File \"/usr/local/lib/python3.10/multiprocessing/popen_fork.py\", line 71, in _launch\n    code = process_obj._bootstrap(parent_sentinel=child_r)\n", "  File \"/usr/local/lib/python3.10/multiprocessing/process.py\", line 314, in _bootstrap\n    self.run()\n", "  File \"/usr/local/lib/python3.10/site-packages/newrelic/api/background_task.py\", line 117, in wrapper\n    return wrapped(*args, **kwargs)\n", "  File \"/usr/local/lib/python3.10/site-packages/mage_ai/orchestration/queue/process_queue.py\", line 315, in run\n    start_session_and_run(args[1], *args[2], **args[3])\n", "  File \"/usr/local/lib/python3.10/site-packages/mage_ai/orchestration/db/process.py\", line 15, in start_session_and_run\n    results = target(*args)\n", "  File \"/usr/local/lib/python3.10/site-packages/mage_ai/orchestration/pipeline_scheduler_original.py\", line 1236, in run_block\n    return ExecutorFactory.get_block_executor(\n", "  File \"/usr/local/lib/python3.10/site-packages/mage_ai/data_preparation/executors/block_executor.py\", line 682, in execute\n    on_failure(\n", "  File \"/usr/local/lib/python3.10/site-packages/mage_ai/orchestration/db/__init__.py\", line 158, in func_with_rollback\n    return func(*args, **kwargs)\n", "  File \"/usr/local/lib/python3.10/site-packages/mage_ai/orchestration/pipeline_scheduler_original.py\", line 465, in on_block_failure\n    self.logger.exception(\n", "  File \"/usr/local/lib/python3.10/site-packages/mage_ai/data_preparation/logging/logger.py\", line 30, in exception\n    self.__send_message('exception', message, **kwargs)\n", "  File \"/usr/local/lib/python3.10/site-packages/mage_ai/data_preparation/logging/logger.py\", line 65, in __send_message\n    data['error_stack'] = traceback.format_stack(),\n"]], "error_stacktrace": ["404 POST https://storage.googleapis.com/upload/storage/v1/b/test-mlops-philippov/o?uploadType=multipart: {\n  \"error\": {\n    \"code\": 404,\n    \"message\": \"The specified bucket does not exist.\",\n    \"errors\": [\n      {\n        \"message\": \"The specified bucket does not exist.\",\n        \"domain\": \"global\",\n        \"reason\": \"notFound\"\n      }\n    ]\n  }\n}\n: ('Request failed with status code', 404, 'Expected one of', <HTTPStatus.OK: 200>)"]}
Traceback (most recent call last):
  File "/usr/local/lib/python3.10/site-packages/google/cloud/storage/blob.py", line 2567, in upload_from_file
    created_json = self._do_upload(
  File "/usr/local/lib/python3.10/site-packages/google/cloud/storage/blob.py", line 2368, in _do_upload
    response = self._do_multipart_upload(
  File "/usr/local/lib/python3.10/site-packages/google/cloud/storage/blob.py", line 1903, in _do_multipart_upload
    response = upload.transmit(
  File "/usr/local/lib/python3.10/site-packages/google/resumable_media/requests/upload.py", line 153, in transmit
    return _request_helpers.wait_and_retry(
  File "/usr/local/lib/python3.10/site-packages/google/resumable_media/requests/_request_helpers.py", line 155, in wait_and_retry
    response = func()
  File "/usr/local/lib/python3.10/site-packages/google/resumable_media/requests/upload.py", line 149, in retriable_request
    self._process_response(result)
  File "/usr/local/lib/python3.10/site-packages/google/resumable_media/_upload.py", line 125, in _process_response
    _helpers.require_status_code(response, (http.client.OK,), self._get_status_code)
  File "/usr/local/lib/python3.10/site-packages/google/resumable_media/_helpers.py", line 108, in require_status_code
    raise common.InvalidResponse(
google.resumable_media.common.InvalidResponse: ('Request failed with status code', 404, 'Expected one of', <HTTPStatus.OK: 200>)

During handling of the above exception, another exception occurred:

Traceback (most recent call last):
  File "/usr/local/lib/python3.10/site-packages/mage_ai/data_preparation/executors/block_executor.py", line 647, in execute
    result = __execute_with_retry()
  File "/usr/local/lib/python3.10/site-packages/mage_ai/shared/retry.py", line 54, in retry_func
    raise e
  File "/usr/local/lib/python3.10/site-packages/mage_ai/shared/retry.py", line 38, in retry_func
    return func(*args, **kwargs)
  File "/usr/local/lib/python3.10/site-packages/mage_ai/data_preparation/executors/block_executor.py", line 621, in __execute_with_retry
    return self._execute(
  File "/usr/local/lib/python3.10/site-packages/mage_ai/data_preparation/executors/block_executor.py", line 1154, in _execute
    result = self.block.execute_sync(
  File "/usr/local/lib/python3.10/site-packages/mage_ai/data_preparation/models/block/__init__.py", line 1685, in execute_sync
    return __execute()
  File "/usr/local/lib/python3.10/site-packages/mage_ai/data_preparation/models/block/__init__.py", line 1662, in __execute
    raise err
  File "/usr/local/lib/python3.10/site-packages/mage_ai/data_preparation/models/block/__init__.py", line 1564, in __execute
    output = self.execute_block(
  File "/usr/local/lib/python3.10/site-packages/mage_ai/data_preparation/models/block/__init__.py", line 1904, in execute_block
    outputs = self._execute_block(
  File "/usr/local/lib/python3.10/site-packages/mage_ai/data_preparation/models/block/__init__.py", line 2067, in _execute_block
    outputs = self.execute_block_function(
  File "/usr/local/lib/python3.10/site-packages/mage_ai/data_preparation/models/block/__init__.py", line 2163, in execute_block_function
    output = block_function_updated(*input_vars, **global_vars)
  File "<string>", line 33, in hyperparameter_tuning
  File "/home/src/Basketball_results_prediction/utils/sklearn.py", line 138, in tune_hyperparameters
    best_hyperparameters = fmin(
  File "/usr/local/lib/python3.10/site-packages/hyperopt/fmin.py", line 540, in fmin
    return trials.fmin(
  File "/usr/local/lib/python3.10/site-packages/hyperopt/base.py", line 671, in fmin
    return fmin(
  File "/usr/local/lib/python3.10/site-packages/hyperopt/fmin.py", line 586, in fmin
    rval.exhaust()
  File "/usr/local/lib/python3.10/site-packages/hyperopt/fmin.py", line 364, in exhaust
    self.run(self.max_evals - n_done, block_until_done=self.asynchronous)
  File "/usr/local/lib/python3.10/site-packages/hyperopt/fmin.py", line 300, in run
    self.serial_evaluate()
  File "/usr/local/lib/python3.10/site-packages/hyperopt/fmin.py", line 178, in serial_evaluate
    result = self.domain.evaluate(spec, ctrl)
  File "/usr/local/lib/python3.10/site-packages/hyperopt/base.py", line 892, in evaluate
    rval = self.fn(pyll_rval)
  File "/home/src/Basketball_results_prediction/utils/sklearn.py", line 122, in __objective
    mlflow.sklearn.log_model(artifact_path="",sk_model=model)
  File "/usr/local/lib/python3.10/site-packages/mlflow/sklearn/__init__.py", line 418, in log_model
    return Model.log(
  File "/usr/local/lib/python3.10/site-packages/mlflow/models/model.py", line 656, in log
    mlflow.tracking.fluent.log_artifacts(local_path, mlflow_model.artifact_path, run_id)
  File "/usr/local/lib/python3.10/site-packages/mlflow/tracking/fluent.py", line 1096, in log_artifacts
    MlflowClient().log_artifacts(run_id, local_dir, artifact_path)
  File "/usr/local/lib/python3.10/site-packages/mlflow/tracking/client.py", line 1242, in log_artifacts
    self._tracking_client.log_artifacts(run_id, local_dir, artifact_path)
  File "/usr/local/lib/python3.10/site-packages/mlflow/tracking/_tracking_service/client.py", line 570, in log_artifacts
    self._get_artifact_repo(run_id).log_artifacts(local_dir, artifact_path)
  File "/usr/local/lib/python3.10/site-packages/mlflow/store/artifact/gcs_artifact_repo.py", line 106, in log_artifacts
    gcs_bucket.blob(path, chunk_size=self._GCS_UPLOAD_CHUNK_SIZE).upload_from_filename(
  File "/usr/local/lib/python3.10/site-packages/google/cloud/storage/blob.py", line 2708, in upload_from_filename
    self.upload_from_file(
  File "/usr/local/lib/python3.10/site-packages/google/cloud/storage/blob.py", line 2584, in upload_from_file
    _raise_from_invalid_response(exc)
  File "/usr/local/lib/python3.10/site-packages/google/cloud/storage/blob.py", line 4457, in _raise_from_invalid_response
    raise exceptions.from_http_status(response.status_code, message, response=response)
google.api_core.exceptions.NotFound: 404 POST https://storage.googleapis.com/upload/storage/v1/b/test-mlops-philippov/o?uploadType=multipart: {
  "error": {
    "code": 404,
    "message": "The specified bucket does not exist.",
    "errors": [
      {
        "message": "The specified bucket does not exist.",
        "domain": "global",
        "reason": "notFound"
      }
    ]
  }
}
: ('Request failed with status code', 404, 'Expected one of', <HTTPStatus.OK: 200>)
2024-08-10T20:33:37 {"cpu": 0.24267578125, "cpu_total": 4, "cpu_usage": 0.0606689453125, "memory": 2818.0, "memory_total": 16002.0, "memory_usage": 0.17610298712660918, "pipeline_run_id": 34, "pipeline_schedule_id": 3, "pipeline_uuid": "train_sklearn", "hostname": "2f717878a6d7", "level": "INFO", "message": "Pipeline train_sklearn for run 34 in schedule 3 is alive.", "timestamp": 1723322017.74466, "uuid": "2a96c1267d514a4faf3e841a22185405"}
