2024-08-10T21:58:22 {"cpu": 0.580078125, "cpu_total": 4, "cpu_usage": 0.14501953125, "memory": 2472.0, "memory_total": 16002.0, "memory_usage": 0.1544806899137608, "pipeline_run_id": 42, "pipeline_schedule_id": 3, "pipeline_uuid": "train_sklearn", "hostname": "fbd19c79e2e6", "level": "INFO", "message": "Pipeline train_sklearn for run 42 in schedule 3 is alive.", "timestamp": 1723327102.628766, "uuid": "effba054e4f743b585d2642a8e72edfe"}
2024-08-10T21:58:22 {"block_run_id": 190, "block_uuid": "training_set", "pipeline_run_id": 42, "pipeline_schedule_id": 3, "pipeline_uuid": "train_sklearn", "hostname": "fbd19c79e2e6", "level": "INFO", "message": "Execute PipelineRun 42, BlockRun 190: pipeline train_sklearn block training_set", "timestamp": 1723327102.713393, "uuid": "8e768ab060eb4c8fb5cb67f1fe637088"}
2024-08-10T21:58:22 {"block_run_id": 191, "block_uuid": "set_models", "pipeline_run_id": 42, "pipeline_schedule_id": 3, "pipeline_uuid": "train_sklearn", "hostname": "fbd19c79e2e6", "level": "INFO", "message": "Execute PipelineRun 42, BlockRun 191: pipeline train_sklearn block set_models", "timestamp": 1723327102.723667, "uuid": "ab674a6b1a604661a602039070c86c56"}
2024-08-10T21:58:22 {"block_run_id": 192, "block_uuid": "training", "pipeline_run_id": 42, "pipeline_schedule_id": 3, "pipeline_uuid": "train_sklearn", "hostname": "fbd19c79e2e6", "level": "INFO", "message": "Execute PipelineRun 42, BlockRun 192: pipeline train_sklearn block training", "timestamp": 1723327102.749338, "uuid": "b699cd05ae7a480b89b27a5a78e2ef33"}
2024-08-10T21:58:22 {"block_run_id": 191, "block_uuid": "set_models", "pipeline_run_id": 42, "pipeline_schedule_id": 3, "pipeline_uuid": "train_sklearn", "hostname": "fbd19c79e2e6", "level": "INFO", "message": "BlockRun 191 (block_uuid: set_models) completes.", "timestamp": 1723327102.759832, "uuid": "4f57ff85c5264ea69ad806d7614b84ea"}
2024-08-10T21:58:22 {"block_run_id": 190, "block_uuid": "training_set", "pipeline_run_id": 42, "pipeline_schedule_id": 3, "pipeline_uuid": "train_sklearn", "hostname": "fbd19c79e2e6", "level": "INFO", "message": "BlockRun 190 (block_uuid: training_set) completes.", "timestamp": 1723327102.771008, "uuid": "356534056cac4674975986ebbedc5862"}
2024-08-10T21:58:22 {"block_run_id": 192, "block_uuid": "training", "pipeline_run_id": 42, "pipeline_schedule_id": 3, "pipeline_uuid": "train_sklearn", "hostname": "fbd19c79e2e6", "level": "INFO", "message": "BlockRun 192 (block_uuid: training) completes.", "timestamp": 1723327102.800562, "uuid": "67f8a08f5e2949cf80d714ff098c0dd0"}
2024-08-10T21:58:23 {"cpu": 0.580078125, "cpu_total": 4, "cpu_usage": 0.14501953125, "memory": 2490.0, "memory_total": 16002.0, "memory_usage": 0.15560554930633672, "pipeline_run_id": 42, "pipeline_schedule_id": 3, "pipeline_uuid": "train_sklearn", "hostname": "fbd19c79e2e6", "level": "INFO", "message": "Pipeline train_sklearn for run 42 in schedule 3 is alive.", "timestamp": 1723327103.121201, "uuid": "1c89266edaaf423cbba7e3eb8b4a49b1"}
2024-08-10T21:58:23 {"block_run_id": 194, "block_uuid": "training:LinearSVR", "pipeline_run_id": 42, "pipeline_schedule_id": 3, "pipeline_uuid": "train_sklearn", "hostname": "fbd19c79e2e6", "level": "INFO", "message": "Execute PipelineRun 42, BlockRun 194: pipeline train_sklearn block training:LinearSVR", "timestamp": 1723327103.745947, "uuid": "e9f4df71fea140ea970c7ffe9d7efbb7"}
2024-08-10T21:58:23 {"block_run_id": 195, "block_uuid": "training:GradientBoostingRegressor", "pipeline_run_id": 42, "pipeline_schedule_id": 3, "pipeline_uuid": "train_sklearn", "hostname": "fbd19c79e2e6", "level": "INFO", "message": "Execute PipelineRun 42, BlockRun 195: pipeline train_sklearn block training:GradientBoostingRegressor", "timestamp": 1723327103.772289, "uuid": "51e906f4e638454ba834bce4f8cb0d57"}
2024-08-10T21:58:23 {"block_run_id": 196, "block_uuid": "training:LinearRegression", "pipeline_run_id": 42, "pipeline_schedule_id": 3, "pipeline_uuid": "train_sklearn", "hostname": "fbd19c79e2e6", "level": "INFO", "message": "Execute PipelineRun 42, BlockRun 196: pipeline train_sklearn block training:LinearRegression", "timestamp": 1723327103.786614, "uuid": "991b33df308d47c08ea0337dbd86576c"}
2024-08-10T21:58:23 {"block_run_id": 197, "block_uuid": "training:Lasso", "pipeline_run_id": 42, "pipeline_schedule_id": 3, "pipeline_uuid": "train_sklearn", "hostname": "fbd19c79e2e6", "level": "INFO", "message": "Execute PipelineRun 42, BlockRun 197: pipeline train_sklearn block training:Lasso", "timestamp": 1723327103.809193, "uuid": "fd6c3f171dee4138a5fd91f4ba3f5b3a"}
2024-08-10T21:58:23 {"block_run_id": 198, "block_uuid": "training:RandomForestRegressor", "pipeline_run_id": 42, "pipeline_schedule_id": 3, "pipeline_uuid": "train_sklearn", "hostname": "fbd19c79e2e6", "level": "INFO", "message": "Execute PipelineRun 42, BlockRun 198: pipeline train_sklearn block training:RandomForestRegressor", "timestamp": 1723327103.830718, "uuid": "fb35965fcd284ebb8cec3789433b9923"}
2024-08-10T21:58:32 {"cpu": 0.6279296875, "cpu_total": 4, "cpu_usage": 0.156982421875, "memory": 3691.0, "memory_total": 16002.0, "memory_usage": 0.2306586676665417, "pipeline_run_id": 42, "pipeline_schedule_id": 3, "pipeline_uuid": "train_sklearn", "hostname": "fbd19c79e2e6", "level": "INFO", "message": "Pipeline train_sklearn for run 42 in schedule 3 is alive.", "timestamp": 1723327112.288731, "uuid": "e002126cc22943b4b6dc39efbcc10f80"}
2024-08-10T21:58:33 {"block_run_id": 197, "block_uuid": "training:Lasso", "pipeline_run_id": 42, "pipeline_schedule_id": 3, "pipeline_uuid": "train_sklearn", "hostname": "fbd19c79e2e6", "level": "EXCEPTION", "message": "BlockRun 197 (block_uuid: training:Lasso) failed.", "timestamp": 1723327113.331622, "uuid": "988b34f2cce648438a3c26ec5364d239", "error": ["Traceback (most recent call last):\n  File \"/usr/local/lib/python3.10/site-packages/google/cloud/storage/blob.py\", line 2567, in upload_from_file\n    created_json = self._do_upload(\n  File \"/usr/local/lib/python3.10/site-packages/google/cloud/storage/blob.py\", line 2368, in _do_upload\n    response = self._do_multipart_upload(\n  File \"/usr/local/lib/python3.10/site-packages/google/cloud/storage/blob.py\", line 1903, in _do_multipart_upload\n    response = upload.transmit(\n  File \"/usr/local/lib/python3.10/site-packages/google/resumable_media/requests/upload.py\", line 153, in transmit\n    return _request_helpers.wait_and_retry(\n  File \"/usr/local/lib/python3.10/site-packages/google/resumable_media/requests/_request_helpers.py\", line 155, in wait_and_retry\n    response = func()\n  File \"/usr/local/lib/python3.10/site-packages/google/resumable_media/requests/upload.py\", line 149, in retriable_request\n    self._process_response(result)\n  File \"/usr/local/lib/python3.10/site-packages/google/resumable_media/_upload.py\", line 125, in _process_response\n    _helpers.require_status_code(response, (http.client.OK,), self._get_status_code)\n  File \"/usr/local/lib/python3.10/site-packages/google/resumable_media/_helpers.py\", line 108, in require_status_code\n    raise common.InvalidResponse(\ngoogle.resumable_media.common.InvalidResponse: ('Request failed with status code', 404, 'Expected one of', <HTTPStatus.OK: 200>)\n\nDuring handling of the above exception, another exception occurred:\n\nTraceback (most recent call last):\n  File \"/usr/local/lib/python3.10/site-packages/mage_ai/data_preparation/executors/block_executor.py\", line 647, in execute\n    result = __execute_with_retry()\n  File \"/usr/local/lib/python3.10/site-packages/mage_ai/shared/retry.py\", line 54, in retry_func\n    raise e\n  File \"/usr/local/lib/python3.10/site-packages/mage_ai/shared/retry.py\", line 38, in retry_func\n    return func(*args, **kwargs)\n  File \"/usr/local/lib/python3.10/site-packages/mage_ai/data_preparation/executors/block_executor.py\", line 621, in __execute_with_retry\n    return self._execute(\n  File \"/usr/local/lib/python3.10/site-packages/mage_ai/data_preparation/executors/block_executor.py\", line 1154, in _execute\n    result = self.block.execute_sync(\n  File \"/usr/local/lib/python3.10/site-packages/mage_ai/data_preparation/models/block/__init__.py\", line 1685, in execute_sync\n    return __execute()\n  File \"/usr/local/lib/python3.10/site-packages/mage_ai/data_preparation/models/block/__init__.py\", line 1662, in __execute\n    raise err\n  File \"/usr/local/lib/python3.10/site-packages/mage_ai/data_preparation/models/block/__init__.py\", line 1564, in __execute\n    output = self.execute_block(\n  File \"/usr/local/lib/python3.10/site-packages/mage_ai/data_preparation/models/block/__init__.py\", line 1904, in execute_block\n    outputs = self._execute_block(\n  File \"/usr/local/lib/python3.10/site-packages/mage_ai/data_preparation/models/block/__init__.py\", line 2067, in _execute_block\n    outputs = self.execute_block_function(\n  File \"/usr/local/lib/python3.10/site-packages/mage_ai/data_preparation/models/block/__init__.py\", line 2163, in execute_block_function\n    output = block_function_updated(*input_vars, **global_vars)\n  File \"<string>\", line 33, in hyperparameter_tuning\n  File \"/home/src/Basketball_results_prediction/utils/sklearn.py\", line 138, in tune_hyperparameters\n    best_hyperparameters = fmin(\n  File \"/usr/local/lib/python3.10/site-packages/hyperopt/fmin.py\", line 540, in fmin\n    return trials.fmin(\n  File \"/usr/local/lib/python3.10/site-packages/hyperopt/base.py\", line 671, in fmin\n    return fmin(\n  File \"/usr/local/lib/python3.10/site-packages/hyperopt/fmin.py\", line 586, in fmin\n    rval.exhaust()\n  File \"/usr/local/lib/python3.10/site-packages/hyperopt/fmin.py\", line 364, in exhaust\n    self.run(self.max_evals - n_done, block_until_done=self.asynchronous)\n  File \"/usr/local/lib/python3.10/site-packages/hyperopt/fmin.py\", line 300, in run\n    self.serial_evaluate()\n  File \"/usr/local/lib/python3.10/site-packages/hyperopt/fmin.py\", line 178, in serial_evaluate\n    result = self.domain.evaluate(spec, ctrl)\n  File \"/usr/local/lib/python3.10/site-packages/hyperopt/base.py\", line 892, in evaluate\n    rval = self.fn(pyll_rval)\n  File \"/home/src/Basketball_results_prediction/utils/sklearn.py\", line 122, in __objective\n    mlflow.sklearn.log_model(artifact_path=\"\",sk_model=model)\n  File \"/usr/local/lib/python3.10/site-packages/mlflow/sklearn/__init__.py\", line 418, in log_model\n    return Model.log(\n  File \"/usr/local/lib/python3.10/site-packages/mlflow/models/model.py\", line 656, in log\n    mlflow.tracking.fluent.log_artifacts(local_path, mlflow_model.artifact_path, run_id)\n  File \"/usr/local/lib/python3.10/site-packages/mlflow/tracking/fluent.py\", line 1096, in log_artifacts\n    MlflowClient().log_artifacts(run_id, local_dir, artifact_path)\n  File \"/usr/local/lib/python3.10/site-packages/mlflow/tracking/client.py\", line 1242, in log_artifacts\n    self._tracking_client.log_artifacts(run_id, local_dir, artifact_path)\n  File \"/usr/local/lib/python3.10/site-packages/mlflow/tracking/_tracking_service/client.py\", line 570, in log_artifacts\n    self._get_artifact_repo(run_id).log_artifacts(local_dir, artifact_path)\n  File \"/usr/local/lib/python3.10/site-packages/mlflow/store/artifact/gcs_artifact_repo.py\", line 106, in log_artifacts\n    gcs_bucket.blob(path, chunk_size=self._GCS_UPLOAD_CHUNK_SIZE).upload_from_filename(\n  File \"/usr/local/lib/python3.10/site-packages/google/cloud/storage/blob.py\", line 2708, in upload_from_filename\n    self.upload_from_file(\n  File \"/usr/local/lib/python3.10/site-packages/google/cloud/storage/blob.py\", line 2584, in upload_from_file\n    _raise_from_invalid_response(exc)\n  File \"/usr/local/lib/python3.10/site-packages/google/cloud/storage/blob.py\", line 4457, in _raise_from_invalid_response\n    raise exceptions.from_http_status(response.status_code, message, response=response)\ngoogle.api_core.exceptions.NotFound: 404 POST https://storage.googleapis.com/upload/storage/v1/b/test-mlops-philippov/o?uploadType=multipart: {\n  \"error\": {\n    \"code\": 404,\n    \"message\": \"The specified bucket does not exist.\",\n    \"errors\": [\n      {\n        \"message\": \"The specified bucket does not exist.\",\n        \"domain\": \"global\",\n        \"reason\": \"notFound\"\n      }\n    ]\n  }\n}\n: ('Request failed with status code', 404, 'Expected one of', <HTTPStatus.OK: 200>)\n"], "error_stack": [["  File \"/usr/local/bin/mage\", line 8, in <module>\n    sys.exit(app())\n", "  File \"/usr/local/lib/python3.10/site-packages/typer/main.py\", line 311, in __call__\n    return get_command(self)(*args, **kwargs)\n", "  File \"/usr/local/lib/python3.10/site-packages/click/core.py\", line 1130, in __call__\n    return self.main(*args, **kwargs)\n", "  File \"/usr/local/lib/python3.10/site-packages/typer/core.py\", line 778, in main\n    return _main(\n", "  File \"/usr/local/lib/python3.10/site-packages/typer/core.py\", line 216, in _main\n    rv = self.invoke(ctx)\n", "  File \"/usr/local/lib/python3.10/site-packages/click/core.py\", line 1657, in invoke\n    return _process_result(sub_ctx.command.invoke(sub_ctx))\n", "  File \"/usr/local/lib/python3.10/site-packages/click/core.py\", line 1404, in invoke\n    return ctx.invoke(self.callback, **ctx.params)\n", "  File \"/usr/local/lib/python3.10/site-packages/click/core.py\", line 760, in invoke\n    return __callback(*args, **kwargs)\n", "  File \"/usr/local/lib/python3.10/site-packages/typer/main.py\", line 683, in wrapper\n    return callback(**use_params)  # type: ignore\n", "  File \"/usr/local/lib/python3.10/site-packages/mage_ai/cli/main.py\", line 147, in start\n    start_server(\n", "  File \"/usr/local/lib/python3.10/site-packages/mage_ai/server/server.py\", line 792, in start_server\n    scheduler_manager.start_scheduler()\n", "  File \"/usr/local/lib/python3.10/site-packages/mage_ai/server/scheduler_manager.py\", line 106, in start_scheduler\n    proc.start()\n", "  File \"/usr/local/lib/python3.10/multiprocessing/process.py\", line 121, in start\n    self._popen = self._Popen(self)\n", "  File \"/usr/local/lib/python3.10/multiprocessing/context.py\", line 224, in _Popen\n    return _default_context.get_context().Process._Popen(process_obj)\n", "  File \"/usr/local/lib/python3.10/multiprocessing/context.py\", line 281, in _Popen\n    return Popen(process_obj)\n", "  File \"/usr/local/lib/python3.10/multiprocessing/popen_fork.py\", line 19, in __init__\n    self._launch(process_obj)\n", "  File \"/usr/local/lib/python3.10/multiprocessing/popen_fork.py\", line 71, in _launch\n    code = process_obj._bootstrap(parent_sentinel=child_r)\n", "  File \"/usr/local/lib/python3.10/multiprocessing/process.py\", line 314, in _bootstrap\n    self.run()\n", "  File \"/usr/local/lib/python3.10/multiprocessing/process.py\", line 108, in run\n    self._target(*self._args, **self._kwargs)\n", "  File \"/usr/local/lib/python3.10/site-packages/mage_ai/orchestration/db/process.py\", line 15, in start_session_and_run\n    results = target(*args)\n", "  File \"/usr/local/lib/python3.10/site-packages/mage_ai/server/scheduler_manager.py\", line 58, in run_scheduler\n    LoopTimeTrigger().start()\n", "  File \"/usr/local/lib/python3.10/site-packages/mage_ai/orchestration/triggers/loop_time_trigger.py\", line 14, in start\n    self.run()\n", "  File \"/usr/local/lib/python3.10/site-packages/mage_ai/orchestration/triggers/time_trigger.py\", line 11, in run\n    schedule_all()\n", "  File \"/usr/local/lib/python3.10/site-packages/mage_ai/orchestration/pipeline_scheduler_original.py\", line 1703, in schedule_all\n    PipelineScheduler(r).start()\n", "  File \"/usr/local/lib/python3.10/site-packages/mage_ai/orchestration/db/__init__.py\", line 158, in func_with_rollback\n    return func(*args, **kwargs)\n", "  File \"/usr/local/lib/python3.10/site-packages/mage_ai/orchestration/pipeline_scheduler_original.py\", line 198, in start\n    self.schedule()\n", "  File \"/usr/local/lib/python3.10/site-packages/mage_ai/orchestration/db/__init__.py\", line 158, in func_with_rollback\n    return func(*args, **kwargs)\n", "  File \"/usr/local/lib/python3.10/site-packages/mage_ai/orchestration/pipeline_scheduler_original.py\", line 334, in schedule\n    self.__schedule_blocks(block_runs)\n", "  File \"/usr/local/lib/python3.10/site-packages/mage_ai/orchestration/pipeline_scheduler_original.py\", line 641, in __schedule_blocks\n    job_manager.add_job(\n", "  File \"/usr/local/lib/python3.10/site-packages/mage_ai/orchestration/job_manager.py\", line 20, in add_job\n    self.queue.enqueue(job_id, target, *args, **kwargs)\n", "  File \"/usr/local/lib/python3.10/site-packages/mage_ai/orchestration/queue/process_queue.py\", line 121, in enqueue\n    self.start_worker_pool()\n", "  File \"/usr/local/lib/python3.10/site-packages/mage_ai/orchestration/queue/process_queue.py\", line 198, in start_worker_pool\n    self.worker_pool_proc.start()\n", "  File \"/usr/local/lib/python3.10/multiprocessing/process.py\", line 121, in start\n    self._popen = self._Popen(self)\n", "  File \"/usr/local/lib/python3.10/multiprocessing/context.py\", line 224, in _Popen\n    return _default_context.get_context().Process._Popen(process_obj)\n", "  File \"/usr/local/lib/python3.10/multiprocessing/context.py\", line 281, in _Popen\n    return Popen(process_obj)\n", "  File \"/usr/local/lib/python3.10/multiprocessing/popen_fork.py\", line 19, in __init__\n    self._launch(process_obj)\n", "  File \"/usr/local/lib/python3.10/multiprocessing/popen_fork.py\", line 71, in _launch\n    code = process_obj._bootstrap(parent_sentinel=child_r)\n", "  File \"/usr/local/lib/python3.10/multiprocessing/process.py\", line 314, in _bootstrap\n    self.run()\n", "  File \"/usr/local/lib/python3.10/multiprocessing/process.py\", line 108, in run\n    self._target(*self._args, **self._kwargs)\n", "  File \"/usr/local/lib/python3.10/site-packages/mage_ai/orchestration/queue/process_queue.py\", line 351, in poll_job_and_execute\n    worker.start()\n", "  File \"/usr/local/lib/python3.10/multiprocessing/process.py\", line 121, in start\n    self._popen = self._Popen(self)\n", "  File \"/usr/local/lib/python3.10/multiprocessing/context.py\", line 224, in _Popen\n    return _default_context.get_context().Process._Popen(process_obj)\n", "  File \"/usr/local/lib/python3.10/multiprocessing/context.py\", line 281, in _Popen\n    return Popen(process_obj)\n", "  File \"/usr/local/lib/python3.10/multiprocessing/popen_fork.py\", line 19, in __init__\n    self._launch(process_obj)\n", "  File \"/usr/local/lib/python3.10/multiprocessing/popen_fork.py\", line 71, in _launch\n    code = process_obj._bootstrap(parent_sentinel=child_r)\n", "  File \"/usr/local/lib/python3.10/multiprocessing/process.py\", line 314, in _bootstrap\n    self.run()\n", "  File \"/usr/local/lib/python3.10/site-packages/newrelic/api/background_task.py\", line 117, in wrapper\n    return wrapped(*args, **kwargs)\n", "  File \"/usr/local/lib/python3.10/site-packages/mage_ai/orchestration/queue/process_queue.py\", line 315, in run\n    start_session_and_run(args[1], *args[2], **args[3])\n", "  File \"/usr/local/lib/python3.10/site-packages/mage_ai/orchestration/db/process.py\", line 15, in start_session_and_run\n    results = target(*args)\n", "  File \"/usr/local/lib/python3.10/site-packages/mage_ai/orchestration/pipeline_scheduler_original.py\", line 1236, in run_block\n    return ExecutorFactory.get_block_executor(\n", "  File \"/usr/local/lib/python3.10/site-packages/mage_ai/data_preparation/executors/block_executor.py\", line 682, in execute\n    on_failure(\n", "  File \"/usr/local/lib/python3.10/site-packages/mage_ai/orchestration/db/__init__.py\", line 158, in func_with_rollback\n    return func(*args, **kwargs)\n", "  File \"/usr/local/lib/python3.10/site-packages/mage_ai/orchestration/pipeline_scheduler_original.py\", line 465, in on_block_failure\n    self.logger.exception(\n", "  File \"/usr/local/lib/python3.10/site-packages/mage_ai/data_preparation/logging/logger.py\", line 30, in exception\n    self.__send_message('exception', message, **kwargs)\n", "  File \"/usr/local/lib/python3.10/site-packages/mage_ai/data_preparation/logging/logger.py\", line 65, in __send_message\n    data['error_stack'] = traceback.format_stack(),\n"]], "error_stacktrace": ["404 POST https://storage.googleapis.com/upload/storage/v1/b/test-mlops-philippov/o?uploadType=multipart: {\n  \"error\": {\n    \"code\": 404,\n    \"message\": \"The specified bucket does not exist.\",\n    \"errors\": [\n      {\n        \"message\": \"The specified bucket does not exist.\",\n        \"domain\": \"global\",\n        \"reason\": \"notFound\"\n      }\n    ]\n  }\n}\n: ('Request failed with status code', 404, 'Expected one of', <HTTPStatus.OK: 200>)"]}
Traceback (most recent call last):
  File "/usr/local/lib/python3.10/site-packages/google/cloud/storage/blob.py", line 2567, in upload_from_file
    created_json = self._do_upload(
  File "/usr/local/lib/python3.10/site-packages/google/cloud/storage/blob.py", line 2368, in _do_upload
    response = self._do_multipart_upload(
  File "/usr/local/lib/python3.10/site-packages/google/cloud/storage/blob.py", line 1903, in _do_multipart_upload
    response = upload.transmit(
  File "/usr/local/lib/python3.10/site-packages/google/resumable_media/requests/upload.py", line 153, in transmit
    return _request_helpers.wait_and_retry(
  File "/usr/local/lib/python3.10/site-packages/google/resumable_media/requests/_request_helpers.py", line 155, in wait_and_retry
    response = func()
  File "/usr/local/lib/python3.10/site-packages/google/resumable_media/requests/upload.py", line 149, in retriable_request
    self._process_response(result)
  File "/usr/local/lib/python3.10/site-packages/google/resumable_media/_upload.py", line 125, in _process_response
    _helpers.require_status_code(response, (http.client.OK,), self._get_status_code)
  File "/usr/local/lib/python3.10/site-packages/google/resumable_media/_helpers.py", line 108, in require_status_code
    raise common.InvalidResponse(
google.resumable_media.common.InvalidResponse: ('Request failed with status code', 404, 'Expected one of', <HTTPStatus.OK: 200>)

During handling of the above exception, another exception occurred:

Traceback (most recent call last):
  File "/usr/local/lib/python3.10/site-packages/mage_ai/data_preparation/executors/block_executor.py", line 647, in execute
    result = __execute_with_retry()
  File "/usr/local/lib/python3.10/site-packages/mage_ai/shared/retry.py", line 54, in retry_func
    raise e
  File "/usr/local/lib/python3.10/site-packages/mage_ai/shared/retry.py", line 38, in retry_func
    return func(*args, **kwargs)
  File "/usr/local/lib/python3.10/site-packages/mage_ai/data_preparation/executors/block_executor.py", line 621, in __execute_with_retry
    return self._execute(
  File "/usr/local/lib/python3.10/site-packages/mage_ai/data_preparation/executors/block_executor.py", line 1154, in _execute
    result = self.block.execute_sync(
  File "/usr/local/lib/python3.10/site-packages/mage_ai/data_preparation/models/block/__init__.py", line 1685, in execute_sync
    return __execute()
  File "/usr/local/lib/python3.10/site-packages/mage_ai/data_preparation/models/block/__init__.py", line 1662, in __execute
    raise err
  File "/usr/local/lib/python3.10/site-packages/mage_ai/data_preparation/models/block/__init__.py", line 1564, in __execute
    output = self.execute_block(
  File "/usr/local/lib/python3.10/site-packages/mage_ai/data_preparation/models/block/__init__.py", line 1904, in execute_block
    outputs = self._execute_block(
  File "/usr/local/lib/python3.10/site-packages/mage_ai/data_preparation/models/block/__init__.py", line 2067, in _execute_block
    outputs = self.execute_block_function(
  File "/usr/local/lib/python3.10/site-packages/mage_ai/data_preparation/models/block/__init__.py", line 2163, in execute_block_function
    output = block_function_updated(*input_vars, **global_vars)
  File "<string>", line 33, in hyperparameter_tuning
  File "/home/src/Basketball_results_prediction/utils/sklearn.py", line 138, in tune_hyperparameters
    best_hyperparameters = fmin(
  File "/usr/local/lib/python3.10/site-packages/hyperopt/fmin.py", line 540, in fmin
    return trials.fmin(
  File "/usr/local/lib/python3.10/site-packages/hyperopt/base.py", line 671, in fmin
    return fmin(
  File "/usr/local/lib/python3.10/site-packages/hyperopt/fmin.py", line 586, in fmin
    rval.exhaust()
  File "/usr/local/lib/python3.10/site-packages/hyperopt/fmin.py", line 364, in exhaust
    self.run(self.max_evals - n_done, block_until_done=self.asynchronous)
  File "/usr/local/lib/python3.10/site-packages/hyperopt/fmin.py", line 300, in run
    self.serial_evaluate()
  File "/usr/local/lib/python3.10/site-packages/hyperopt/fmin.py", line 178, in serial_evaluate
    result = self.domain.evaluate(spec, ctrl)
  File "/usr/local/lib/python3.10/site-packages/hyperopt/base.py", line 892, in evaluate
    rval = self.fn(pyll_rval)
  File "/home/src/Basketball_results_prediction/utils/sklearn.py", line 122, in __objective
    mlflow.sklearn.log_model(artifact_path="",sk_model=model)
  File "/usr/local/lib/python3.10/site-packages/mlflow/sklearn/__init__.py", line 418, in log_model
    return Model.log(
  File "/usr/local/lib/python3.10/site-packages/mlflow/models/model.py", line 656, in log
    mlflow.tracking.fluent.log_artifacts(local_path, mlflow_model.artifact_path, run_id)
  File "/usr/local/lib/python3.10/site-packages/mlflow/tracking/fluent.py", line 1096, in log_artifacts
    MlflowClient().log_artifacts(run_id, local_dir, artifact_path)
  File "/usr/local/lib/python3.10/site-packages/mlflow/tracking/client.py", line 1242, in log_artifacts
    self._tracking_client.log_artifacts(run_id, local_dir, artifact_path)
  File "/usr/local/lib/python3.10/site-packages/mlflow/tracking/_tracking_service/client.py", line 570, in log_artifacts
    self._get_artifact_repo(run_id).log_artifacts(local_dir, artifact_path)
  File "/usr/local/lib/python3.10/site-packages/mlflow/store/artifact/gcs_artifact_repo.py", line 106, in log_artifacts
    gcs_bucket.blob(path, chunk_size=self._GCS_UPLOAD_CHUNK_SIZE).upload_from_filename(
  File "/usr/local/lib/python3.10/site-packages/google/cloud/storage/blob.py", line 2708, in upload_from_filename
    self.upload_from_file(
  File "/usr/local/lib/python3.10/site-packages/google/cloud/storage/blob.py", line 2584, in upload_from_file
    _raise_from_invalid_response(exc)
  File "/usr/local/lib/python3.10/site-packages/google/cloud/storage/blob.py", line 4457, in _raise_from_invalid_response
    raise exceptions.from_http_status(response.status_code, message, response=response)
google.api_core.exceptions.NotFound: 404 POST https://storage.googleapis.com/upload/storage/v1/b/test-mlops-philippov/o?uploadType=multipart: {
  "error": {
    "code": 404,
    "message": "The specified bucket does not exist.",
    "errors": [
      {
        "message": "The specified bucket does not exist.",
        "domain": "global",
        "reason": "notFound"
      }
    ]
  }
}
: ('Request failed with status code', 404, 'Expected one of', <HTTPStatus.OK: 200>)
2024-08-10T21:58:33 {"block_run_id": 194, "block_uuid": "training:LinearSVR", "pipeline_run_id": 42, "pipeline_schedule_id": 3, "pipeline_uuid": "train_sklearn", "hostname": "fbd19c79e2e6", "level": "EXCEPTION", "message": "BlockRun 194 (block_uuid: training:LinearSVR) failed.", "timestamp": 1723327113.484491, "uuid": "19be594cf4a1429dad3a39d3430f6036", "error": ["Traceback (most recent call last):\n  File \"/usr/local/lib/python3.10/site-packages/google/cloud/storage/blob.py\", line 2567, in upload_from_file\n    created_json = self._do_upload(\n  File \"/usr/local/lib/python3.10/site-packages/google/cloud/storage/blob.py\", line 2368, in _do_upload\n    response = self._do_multipart_upload(\n  File \"/usr/local/lib/python3.10/site-packages/google/cloud/storage/blob.py\", line 1903, in _do_multipart_upload\n    response = upload.transmit(\n  File \"/usr/local/lib/python3.10/site-packages/google/resumable_media/requests/upload.py\", line 153, in transmit\n    return _request_helpers.wait_and_retry(\n  File \"/usr/local/lib/python3.10/site-packages/google/resumable_media/requests/_request_helpers.py\", line 155, in wait_and_retry\n    response = func()\n  File \"/usr/local/lib/python3.10/site-packages/google/resumable_media/requests/upload.py\", line 149, in retriable_request\n    self._process_response(result)\n  File \"/usr/local/lib/python3.10/site-packages/google/resumable_media/_upload.py\", line 125, in _process_response\n    _helpers.require_status_code(response, (http.client.OK,), self._get_status_code)\n  File \"/usr/local/lib/python3.10/site-packages/google/resumable_media/_helpers.py\", line 108, in require_status_code\n    raise common.InvalidResponse(\ngoogle.resumable_media.common.InvalidResponse: ('Request failed with status code', 404, 'Expected one of', <HTTPStatus.OK: 200>)\n\nDuring handling of the above exception, another exception occurred:\n\nTraceback (most recent call last):\n  File \"/usr/local/lib/python3.10/site-packages/mage_ai/data_preparation/executors/block_executor.py\", line 647, in execute\n    result = __execute_with_retry()\n  File \"/usr/local/lib/python3.10/site-packages/mage_ai/shared/retry.py\", line 54, in retry_func\n    raise e\n  File \"/usr/local/lib/python3.10/site-packages/mage_ai/shared/retry.py\", line 38, in retry_func\n    return func(*args, **kwargs)\n  File \"/usr/local/lib/python3.10/site-packages/mage_ai/data_preparation/executors/block_executor.py\", line 621, in __execute_with_retry\n    return self._execute(\n  File \"/usr/local/lib/python3.10/site-packages/mage_ai/data_preparation/executors/block_executor.py\", line 1154, in _execute\n    result = self.block.execute_sync(\n  File \"/usr/local/lib/python3.10/site-packages/mage_ai/data_preparation/models/block/__init__.py\", line 1685, in execute_sync\n    return __execute()\n  File \"/usr/local/lib/python3.10/site-packages/mage_ai/data_preparation/models/block/__init__.py\", line 1662, in __execute\n    raise err\n  File \"/usr/local/lib/python3.10/site-packages/mage_ai/data_preparation/models/block/__init__.py\", line 1564, in __execute\n    output = self.execute_block(\n  File \"/usr/local/lib/python3.10/site-packages/mage_ai/data_preparation/models/block/__init__.py\", line 1904, in execute_block\n    outputs = self._execute_block(\n  File \"/usr/local/lib/python3.10/site-packages/mage_ai/data_preparation/models/block/__init__.py\", line 2067, in _execute_block\n    outputs = self.execute_block_function(\n  File \"/usr/local/lib/python3.10/site-packages/mage_ai/data_preparation/models/block/__init__.py\", line 2163, in execute_block_function\n    output = block_function_updated(*input_vars, **global_vars)\n  File \"<string>\", line 33, in hyperparameter_tuning\n  File \"/home/src/Basketball_results_prediction/utils/sklearn.py\", line 138, in tune_hyperparameters\n    best_hyperparameters = fmin(\n  File \"/usr/local/lib/python3.10/site-packages/hyperopt/fmin.py\", line 540, in fmin\n    return trials.fmin(\n  File \"/usr/local/lib/python3.10/site-packages/hyperopt/base.py\", line 671, in fmin\n    return fmin(\n  File \"/usr/local/lib/python3.10/site-packages/hyperopt/fmin.py\", line 586, in fmin\n    rval.exhaust()\n  File \"/usr/local/lib/python3.10/site-packages/hyperopt/fmin.py\", line 364, in exhaust\n    self.run(self.max_evals - n_done, block_until_done=self.asynchronous)\n  File \"/usr/local/lib/python3.10/site-packages/hyperopt/fmin.py\", line 300, in run\n    self.serial_evaluate()\n  File \"/usr/local/lib/python3.10/site-packages/hyperopt/fmin.py\", line 178, in serial_evaluate\n    result = self.domain.evaluate(spec, ctrl)\n  File \"/usr/local/lib/python3.10/site-packages/hyperopt/base.py\", line 892, in evaluate\n    rval = self.fn(pyll_rval)\n  File \"/home/src/Basketball_results_prediction/utils/sklearn.py\", line 122, in __objective\n    mlflow.sklearn.log_model(artifact_path=\"\",sk_model=model)\n  File \"/usr/local/lib/python3.10/site-packages/mlflow/sklearn/__init__.py\", line 418, in log_model\n    return Model.log(\n  File \"/usr/local/lib/python3.10/site-packages/mlflow/models/model.py\", line 656, in log\n    mlflow.tracking.fluent.log_artifacts(local_path, mlflow_model.artifact_path, run_id)\n  File \"/usr/local/lib/python3.10/site-packages/mlflow/tracking/fluent.py\", line 1096, in log_artifacts\n    MlflowClient().log_artifacts(run_id, local_dir, artifact_path)\n  File \"/usr/local/lib/python3.10/site-packages/mlflow/tracking/client.py\", line 1242, in log_artifacts\n    self._tracking_client.log_artifacts(run_id, local_dir, artifact_path)\n  File \"/usr/local/lib/python3.10/site-packages/mlflow/tracking/_tracking_service/client.py\", line 570, in log_artifacts\n    self._get_artifact_repo(run_id).log_artifacts(local_dir, artifact_path)\n  File \"/usr/local/lib/python3.10/site-packages/mlflow/store/artifact/gcs_artifact_repo.py\", line 106, in log_artifacts\n    gcs_bucket.blob(path, chunk_size=self._GCS_UPLOAD_CHUNK_SIZE).upload_from_filename(\n  File \"/usr/local/lib/python3.10/site-packages/google/cloud/storage/blob.py\", line 2708, in upload_from_filename\n    self.upload_from_file(\n  File \"/usr/local/lib/python3.10/site-packages/google/cloud/storage/blob.py\", line 2584, in upload_from_file\n    _raise_from_invalid_response(exc)\n  File \"/usr/local/lib/python3.10/site-packages/google/cloud/storage/blob.py\", line 4457, in _raise_from_invalid_response\n    raise exceptions.from_http_status(response.status_code, message, response=response)\ngoogle.api_core.exceptions.NotFound: 404 POST https://storage.googleapis.com/upload/storage/v1/b/test-mlops-philippov/o?uploadType=multipart: {\n  \"error\": {\n    \"code\": 404,\n    \"message\": \"The specified bucket does not exist.\",\n    \"errors\": [\n      {\n        \"message\": \"The specified bucket does not exist.\",\n        \"domain\": \"global\",\n        \"reason\": \"notFound\"\n      }\n    ]\n  }\n}\n: ('Request failed with status code', 404, 'Expected one of', <HTTPStatus.OK: 200>)\n"], "error_stack": [["  File \"/usr/local/bin/mage\", line 8, in <module>\n    sys.exit(app())\n", "  File \"/usr/local/lib/python3.10/site-packages/typer/main.py\", line 311, in __call__\n    return get_command(self)(*args, **kwargs)\n", "  File \"/usr/local/lib/python3.10/site-packages/click/core.py\", line 1130, in __call__\n    return self.main(*args, **kwargs)\n", "  File \"/usr/local/lib/python3.10/site-packages/typer/core.py\", line 778, in main\n    return _main(\n", "  File \"/usr/local/lib/python3.10/site-packages/typer/core.py\", line 216, in _main\n    rv = self.invoke(ctx)\n", "  File \"/usr/local/lib/python3.10/site-packages/click/core.py\", line 1657, in invoke\n    return _process_result(sub_ctx.command.invoke(sub_ctx))\n", "  File \"/usr/local/lib/python3.10/site-packages/click/core.py\", line 1404, in invoke\n    return ctx.invoke(self.callback, **ctx.params)\n", "  File \"/usr/local/lib/python3.10/site-packages/click/core.py\", line 760, in invoke\n    return __callback(*args, **kwargs)\n", "  File \"/usr/local/lib/python3.10/site-packages/typer/main.py\", line 683, in wrapper\n    return callback(**use_params)  # type: ignore\n", "  File \"/usr/local/lib/python3.10/site-packages/mage_ai/cli/main.py\", line 147, in start\n    start_server(\n", "  File \"/usr/local/lib/python3.10/site-packages/mage_ai/server/server.py\", line 792, in start_server\n    scheduler_manager.start_scheduler()\n", "  File \"/usr/local/lib/python3.10/site-packages/mage_ai/server/scheduler_manager.py\", line 106, in start_scheduler\n    proc.start()\n", "  File \"/usr/local/lib/python3.10/multiprocessing/process.py\", line 121, in start\n    self._popen = self._Popen(self)\n", "  File \"/usr/local/lib/python3.10/multiprocessing/context.py\", line 224, in _Popen\n    return _default_context.get_context().Process._Popen(process_obj)\n", "  File \"/usr/local/lib/python3.10/multiprocessing/context.py\", line 281, in _Popen\n    return Popen(process_obj)\n", "  File \"/usr/local/lib/python3.10/multiprocessing/popen_fork.py\", line 19, in __init__\n    self._launch(process_obj)\n", "  File \"/usr/local/lib/python3.10/multiprocessing/popen_fork.py\", line 71, in _launch\n    code = process_obj._bootstrap(parent_sentinel=child_r)\n", "  File \"/usr/local/lib/python3.10/multiprocessing/process.py\", line 314, in _bootstrap\n    self.run()\n", "  File \"/usr/local/lib/python3.10/multiprocessing/process.py\", line 108, in run\n    self._target(*self._args, **self._kwargs)\n", "  File \"/usr/local/lib/python3.10/site-packages/mage_ai/orchestration/db/process.py\", line 15, in start_session_and_run\n    results = target(*args)\n", "  File \"/usr/local/lib/python3.10/site-packages/mage_ai/server/scheduler_manager.py\", line 58, in run_scheduler\n    LoopTimeTrigger().start()\n", "  File \"/usr/local/lib/python3.10/site-packages/mage_ai/orchestration/triggers/loop_time_trigger.py\", line 14, in start\n    self.run()\n", "  File \"/usr/local/lib/python3.10/site-packages/mage_ai/orchestration/triggers/time_trigger.py\", line 11, in run\n    schedule_all()\n", "  File \"/usr/local/lib/python3.10/site-packages/mage_ai/orchestration/pipeline_scheduler_original.py\", line 1703, in schedule_all\n    PipelineScheduler(r).start()\n", "  File \"/usr/local/lib/python3.10/site-packages/mage_ai/orchestration/db/__init__.py\", line 158, in func_with_rollback\n    return func(*args, **kwargs)\n", "  File \"/usr/local/lib/python3.10/site-packages/mage_ai/orchestration/pipeline_scheduler_original.py\", line 198, in start\n    self.schedule()\n", "  File \"/usr/local/lib/python3.10/site-packages/mage_ai/orchestration/db/__init__.py\", line 158, in func_with_rollback\n    return func(*args, **kwargs)\n", "  File \"/usr/local/lib/python3.10/site-packages/mage_ai/orchestration/pipeline_scheduler_original.py\", line 334, in schedule\n    self.__schedule_blocks(block_runs)\n", "  File \"/usr/local/lib/python3.10/site-packages/mage_ai/orchestration/pipeline_scheduler_original.py\", line 641, in __schedule_blocks\n    job_manager.add_job(\n", "  File \"/usr/local/lib/python3.10/site-packages/mage_ai/orchestration/job_manager.py\", line 20, in add_job\n    self.queue.enqueue(job_id, target, *args, **kwargs)\n", "  File \"/usr/local/lib/python3.10/site-packages/mage_ai/orchestration/queue/process_queue.py\", line 121, in enqueue\n    self.start_worker_pool()\n", "  File \"/usr/local/lib/python3.10/site-packages/mage_ai/orchestration/queue/process_queue.py\", line 198, in start_worker_pool\n    self.worker_pool_proc.start()\n", "  File \"/usr/local/lib/python3.10/multiprocessing/process.py\", line 121, in start\n    self._popen = self._Popen(self)\n", "  File \"/usr/local/lib/python3.10/multiprocessing/context.py\", line 224, in _Popen\n    return _default_context.get_context().Process._Popen(process_obj)\n", "  File \"/usr/local/lib/python3.10/multiprocessing/context.py\", line 281, in _Popen\n    return Popen(process_obj)\n", "  File \"/usr/local/lib/python3.10/multiprocessing/popen_fork.py\", line 19, in __init__\n    self._launch(process_obj)\n", "  File \"/usr/local/lib/python3.10/multiprocessing/popen_fork.py\", line 71, in _launch\n    code = process_obj._bootstrap(parent_sentinel=child_r)\n", "  File \"/usr/local/lib/python3.10/multiprocessing/process.py\", line 314, in _bootstrap\n    self.run()\n", "  File \"/usr/local/lib/python3.10/multiprocessing/process.py\", line 108, in run\n    self._target(*self._args, **self._kwargs)\n", "  File \"/usr/local/lib/python3.10/site-packages/mage_ai/orchestration/queue/process_queue.py\", line 351, in poll_job_and_execute\n    worker.start()\n", "  File \"/usr/local/lib/python3.10/multiprocessing/process.py\", line 121, in start\n    self._popen = self._Popen(self)\n", "  File \"/usr/local/lib/python3.10/multiprocessing/context.py\", line 224, in _Popen\n    return _default_context.get_context().Process._Popen(process_obj)\n", "  File \"/usr/local/lib/python3.10/multiprocessing/context.py\", line 281, in _Popen\n    return Popen(process_obj)\n", "  File \"/usr/local/lib/python3.10/multiprocessing/popen_fork.py\", line 19, in __init__\n    self._launch(process_obj)\n", "  File \"/usr/local/lib/python3.10/multiprocessing/popen_fork.py\", line 71, in _launch\n    code = process_obj._bootstrap(parent_sentinel=child_r)\n", "  File \"/usr/local/lib/python3.10/multiprocessing/process.py\", line 314, in _bootstrap\n    self.run()\n", "  File \"/usr/local/lib/python3.10/site-packages/newrelic/api/background_task.py\", line 117, in wrapper\n    return wrapped(*args, **kwargs)\n", "  File \"/usr/local/lib/python3.10/site-packages/mage_ai/orchestration/queue/process_queue.py\", line 315, in run\n    start_session_and_run(args[1], *args[2], **args[3])\n", "  File \"/usr/local/lib/python3.10/site-packages/mage_ai/orchestration/db/process.py\", line 15, in start_session_and_run\n    results = target(*args)\n", "  File \"/usr/local/lib/python3.10/site-packages/mage_ai/orchestration/pipeline_scheduler_original.py\", line 1236, in run_block\n    return ExecutorFactory.get_block_executor(\n", "  File \"/usr/local/lib/python3.10/site-packages/mage_ai/data_preparation/executors/block_executor.py\", line 682, in execute\n    on_failure(\n", "  File \"/usr/local/lib/python3.10/site-packages/mage_ai/orchestration/db/__init__.py\", line 158, in func_with_rollback\n    return func(*args, **kwargs)\n", "  File \"/usr/local/lib/python3.10/site-packages/mage_ai/orchestration/pipeline_scheduler_original.py\", line 465, in on_block_failure\n    self.logger.exception(\n", "  File \"/usr/local/lib/python3.10/site-packages/mage_ai/data_preparation/logging/logger.py\", line 30, in exception\n    self.__send_message('exception', message, **kwargs)\n", "  File \"/usr/local/lib/python3.10/site-packages/mage_ai/data_preparation/logging/logger.py\", line 65, in __send_message\n    data['error_stack'] = traceback.format_stack(),\n"]], "error_stacktrace": ["404 POST https://storage.googleapis.com/upload/storage/v1/b/test-mlops-philippov/o?uploadType=multipart: {\n  \"error\": {\n    \"code\": 404,\n    \"message\": \"The specified bucket does not exist.\",\n    \"errors\": [\n      {\n        \"message\": \"The specified bucket does not exist.\",\n        \"domain\": \"global\",\n        \"reason\": \"notFound\"\n      }\n    ]\n  }\n}\n: ('Request failed with status code', 404, 'Expected one of', <HTTPStatus.OK: 200>)"]}
Traceback (most recent call last):
  File "/usr/local/lib/python3.10/site-packages/google/cloud/storage/blob.py", line 2567, in upload_from_file
    created_json = self._do_upload(
  File "/usr/local/lib/python3.10/site-packages/google/cloud/storage/blob.py", line 2368, in _do_upload
    response = self._do_multipart_upload(
  File "/usr/local/lib/python3.10/site-packages/google/cloud/storage/blob.py", line 1903, in _do_multipart_upload
    response = upload.transmit(
  File "/usr/local/lib/python3.10/site-packages/google/resumable_media/requests/upload.py", line 153, in transmit
    return _request_helpers.wait_and_retry(
  File "/usr/local/lib/python3.10/site-packages/google/resumable_media/requests/_request_helpers.py", line 155, in wait_and_retry
    response = func()
  File "/usr/local/lib/python3.10/site-packages/google/resumable_media/requests/upload.py", line 149, in retriable_request
    self._process_response(result)
  File "/usr/local/lib/python3.10/site-packages/google/resumable_media/_upload.py", line 125, in _process_response
    _helpers.require_status_code(response, (http.client.OK,), self._get_status_code)
  File "/usr/local/lib/python3.10/site-packages/google/resumable_media/_helpers.py", line 108, in require_status_code
    raise common.InvalidResponse(
google.resumable_media.common.InvalidResponse: ('Request failed with status code', 404, 'Expected one of', <HTTPStatus.OK: 200>)

During handling of the above exception, another exception occurred:

Traceback (most recent call last):
  File "/usr/local/lib/python3.10/site-packages/mage_ai/data_preparation/executors/block_executor.py", line 647, in execute
    result = __execute_with_retry()
  File "/usr/local/lib/python3.10/site-packages/mage_ai/shared/retry.py", line 54, in retry_func
    raise e
  File "/usr/local/lib/python3.10/site-packages/mage_ai/shared/retry.py", line 38, in retry_func
    return func(*args, **kwargs)
  File "/usr/local/lib/python3.10/site-packages/mage_ai/data_preparation/executors/block_executor.py", line 621, in __execute_with_retry
    return self._execute(
  File "/usr/local/lib/python3.10/site-packages/mage_ai/data_preparation/executors/block_executor.py", line 1154, in _execute
    result = self.block.execute_sync(
  File "/usr/local/lib/python3.10/site-packages/mage_ai/data_preparation/models/block/__init__.py", line 1685, in execute_sync
    return __execute()
  File "/usr/local/lib/python3.10/site-packages/mage_ai/data_preparation/models/block/__init__.py", line 1662, in __execute
    raise err
  File "/usr/local/lib/python3.10/site-packages/mage_ai/data_preparation/models/block/__init__.py", line 1564, in __execute
    output = self.execute_block(
  File "/usr/local/lib/python3.10/site-packages/mage_ai/data_preparation/models/block/__init__.py", line 1904, in execute_block
    outputs = self._execute_block(
  File "/usr/local/lib/python3.10/site-packages/mage_ai/data_preparation/models/block/__init__.py", line 2067, in _execute_block
    outputs = self.execute_block_function(
  File "/usr/local/lib/python3.10/site-packages/mage_ai/data_preparation/models/block/__init__.py", line 2163, in execute_block_function
    output = block_function_updated(*input_vars, **global_vars)
  File "<string>", line 33, in hyperparameter_tuning
  File "/home/src/Basketball_results_prediction/utils/sklearn.py", line 138, in tune_hyperparameters
    best_hyperparameters = fmin(
  File "/usr/local/lib/python3.10/site-packages/hyperopt/fmin.py", line 540, in fmin
    return trials.fmin(
  File "/usr/local/lib/python3.10/site-packages/hyperopt/base.py", line 671, in fmin
    return fmin(
  File "/usr/local/lib/python3.10/site-packages/hyperopt/fmin.py", line 586, in fmin
    rval.exhaust()
  File "/usr/local/lib/python3.10/site-packages/hyperopt/fmin.py", line 364, in exhaust
    self.run(self.max_evals - n_done, block_until_done=self.asynchronous)
  File "/usr/local/lib/python3.10/site-packages/hyperopt/fmin.py", line 300, in run
    self.serial_evaluate()
  File "/usr/local/lib/python3.10/site-packages/hyperopt/fmin.py", line 178, in serial_evaluate
    result = self.domain.evaluate(spec, ctrl)
  File "/usr/local/lib/python3.10/site-packages/hyperopt/base.py", line 892, in evaluate
    rval = self.fn(pyll_rval)
  File "/home/src/Basketball_results_prediction/utils/sklearn.py", line 122, in __objective
    mlflow.sklearn.log_model(artifact_path="",sk_model=model)
  File "/usr/local/lib/python3.10/site-packages/mlflow/sklearn/__init__.py", line 418, in log_model
    return Model.log(
  File "/usr/local/lib/python3.10/site-packages/mlflow/models/model.py", line 656, in log
    mlflow.tracking.fluent.log_artifacts(local_path, mlflow_model.artifact_path, run_id)
  File "/usr/local/lib/python3.10/site-packages/mlflow/tracking/fluent.py", line 1096, in log_artifacts
    MlflowClient().log_artifacts(run_id, local_dir, artifact_path)
  File "/usr/local/lib/python3.10/site-packages/mlflow/tracking/client.py", line 1242, in log_artifacts
    self._tracking_client.log_artifacts(run_id, local_dir, artifact_path)
  File "/usr/local/lib/python3.10/site-packages/mlflow/tracking/_tracking_service/client.py", line 570, in log_artifacts
    self._get_artifact_repo(run_id).log_artifacts(local_dir, artifact_path)
  File "/usr/local/lib/python3.10/site-packages/mlflow/store/artifact/gcs_artifact_repo.py", line 106, in log_artifacts
    gcs_bucket.blob(path, chunk_size=self._GCS_UPLOAD_CHUNK_SIZE).upload_from_filename(
  File "/usr/local/lib/python3.10/site-packages/google/cloud/storage/blob.py", line 2708, in upload_from_filename
    self.upload_from_file(
  File "/usr/local/lib/python3.10/site-packages/google/cloud/storage/blob.py", line 2584, in upload_from_file
    _raise_from_invalid_response(exc)
  File "/usr/local/lib/python3.10/site-packages/google/cloud/storage/blob.py", line 4457, in _raise_from_invalid_response
    raise exceptions.from_http_status(response.status_code, message, response=response)
google.api_core.exceptions.NotFound: 404 POST https://storage.googleapis.com/upload/storage/v1/b/test-mlops-philippov/o?uploadType=multipart: {
  "error": {
    "code": 404,
    "message": "The specified bucket does not exist.",
    "errors": [
      {
        "message": "The specified bucket does not exist.",
        "domain": "global",
        "reason": "notFound"
      }
    ]
  }
}
: ('Request failed with status code', 404, 'Expected one of', <HTTPStatus.OK: 200>)
2024-08-10T21:58:33 {"block_run_id": 195, "block_uuid": "training:GradientBoostingRegressor", "pipeline_run_id": 42, "pipeline_schedule_id": 3, "pipeline_uuid": "train_sklearn", "hostname": "fbd19c79e2e6", "level": "EXCEPTION", "message": "BlockRun 195 (block_uuid: training:GradientBoostingRegressor) failed.", "timestamp": 1723327113.564466, "uuid": "643d2a99a3d644a3b8d30ca3a11008b6", "error": ["Traceback (most recent call last):\n  File \"/usr/local/lib/python3.10/site-packages/google/cloud/storage/blob.py\", line 2567, in upload_from_file\n    created_json = self._do_upload(\n  File \"/usr/local/lib/python3.10/site-packages/google/cloud/storage/blob.py\", line 2368, in _do_upload\n    response = self._do_multipart_upload(\n  File \"/usr/local/lib/python3.10/site-packages/google/cloud/storage/blob.py\", line 1903, in _do_multipart_upload\n    response = upload.transmit(\n  File \"/usr/local/lib/python3.10/site-packages/google/resumable_media/requests/upload.py\", line 153, in transmit\n    return _request_helpers.wait_and_retry(\n  File \"/usr/local/lib/python3.10/site-packages/google/resumable_media/requests/_request_helpers.py\", line 155, in wait_and_retry\n    response = func()\n  File \"/usr/local/lib/python3.10/site-packages/google/resumable_media/requests/upload.py\", line 149, in retriable_request\n    self._process_response(result)\n  File \"/usr/local/lib/python3.10/site-packages/google/resumable_media/_upload.py\", line 125, in _process_response\n    _helpers.require_status_code(response, (http.client.OK,), self._get_status_code)\n  File \"/usr/local/lib/python3.10/site-packages/google/resumable_media/_helpers.py\", line 108, in require_status_code\n    raise common.InvalidResponse(\ngoogle.resumable_media.common.InvalidResponse: ('Request failed with status code', 404, 'Expected one of', <HTTPStatus.OK: 200>)\n\nDuring handling of the above exception, another exception occurred:\n\nTraceback (most recent call last):\n  File \"/usr/local/lib/python3.10/site-packages/mage_ai/data_preparation/executors/block_executor.py\", line 647, in execute\n    result = __execute_with_retry()\n  File \"/usr/local/lib/python3.10/site-packages/mage_ai/shared/retry.py\", line 54, in retry_func\n    raise e\n  File \"/usr/local/lib/python3.10/site-packages/mage_ai/shared/retry.py\", line 38, in retry_func\n    return func(*args, **kwargs)\n  File \"/usr/local/lib/python3.10/site-packages/mage_ai/data_preparation/executors/block_executor.py\", line 621, in __execute_with_retry\n    return self._execute(\n  File \"/usr/local/lib/python3.10/site-packages/mage_ai/data_preparation/executors/block_executor.py\", line 1154, in _execute\n    result = self.block.execute_sync(\n  File \"/usr/local/lib/python3.10/site-packages/mage_ai/data_preparation/models/block/__init__.py\", line 1685, in execute_sync\n    return __execute()\n  File \"/usr/local/lib/python3.10/site-packages/mage_ai/data_preparation/models/block/__init__.py\", line 1662, in __execute\n    raise err\n  File \"/usr/local/lib/python3.10/site-packages/mage_ai/data_preparation/models/block/__init__.py\", line 1564, in __execute\n    output = self.execute_block(\n  File \"/usr/local/lib/python3.10/site-packages/mage_ai/data_preparation/models/block/__init__.py\", line 1904, in execute_block\n    outputs = self._execute_block(\n  File \"/usr/local/lib/python3.10/site-packages/mage_ai/data_preparation/models/block/__init__.py\", line 2067, in _execute_block\n    outputs = self.execute_block_function(\n  File \"/usr/local/lib/python3.10/site-packages/mage_ai/data_preparation/models/block/__init__.py\", line 2163, in execute_block_function\n    output = block_function_updated(*input_vars, **global_vars)\n  File \"<string>\", line 33, in hyperparameter_tuning\n  File \"/home/src/Basketball_results_prediction/utils/sklearn.py\", line 138, in tune_hyperparameters\n    best_hyperparameters = fmin(\n  File \"/usr/local/lib/python3.10/site-packages/hyperopt/fmin.py\", line 540, in fmin\n    return trials.fmin(\n  File \"/usr/local/lib/python3.10/site-packages/hyperopt/base.py\", line 671, in fmin\n    return fmin(\n  File \"/usr/local/lib/python3.10/site-packages/hyperopt/fmin.py\", line 586, in fmin\n    rval.exhaust()\n  File \"/usr/local/lib/python3.10/site-packages/hyperopt/fmin.py\", line 364, in exhaust\n    self.run(self.max_evals - n_done, block_until_done=self.asynchronous)\n  File \"/usr/local/lib/python3.10/site-packages/hyperopt/fmin.py\", line 300, in run\n    self.serial_evaluate()\n  File \"/usr/local/lib/python3.10/site-packages/hyperopt/fmin.py\", line 178, in serial_evaluate\n    result = self.domain.evaluate(spec, ctrl)\n  File \"/usr/local/lib/python3.10/site-packages/hyperopt/base.py\", line 892, in evaluate\n    rval = self.fn(pyll_rval)\n  File \"/home/src/Basketball_results_prediction/utils/sklearn.py\", line 122, in __objective\n    mlflow.sklearn.log_model(artifact_path=\"\",sk_model=model)\n  File \"/usr/local/lib/python3.10/site-packages/mlflow/sklearn/__init__.py\", line 418, in log_model\n    return Model.log(\n  File \"/usr/local/lib/python3.10/site-packages/mlflow/models/model.py\", line 656, in log\n    mlflow.tracking.fluent.log_artifacts(local_path, mlflow_model.artifact_path, run_id)\n  File \"/usr/local/lib/python3.10/site-packages/mlflow/tracking/fluent.py\", line 1096, in log_artifacts\n    MlflowClient().log_artifacts(run_id, local_dir, artifact_path)\n  File \"/usr/local/lib/python3.10/site-packages/mlflow/tracking/client.py\", line 1242, in log_artifacts\n    self._tracking_client.log_artifacts(run_id, local_dir, artifact_path)\n  File \"/usr/local/lib/python3.10/site-packages/mlflow/tracking/_tracking_service/client.py\", line 570, in log_artifacts\n    self._get_artifact_repo(run_id).log_artifacts(local_dir, artifact_path)\n  File \"/usr/local/lib/python3.10/site-packages/mlflow/store/artifact/gcs_artifact_repo.py\", line 106, in log_artifacts\n    gcs_bucket.blob(path, chunk_size=self._GCS_UPLOAD_CHUNK_SIZE).upload_from_filename(\n  File \"/usr/local/lib/python3.10/site-packages/google/cloud/storage/blob.py\", line 2708, in upload_from_filename\n    self.upload_from_file(\n  File \"/usr/local/lib/python3.10/site-packages/google/cloud/storage/blob.py\", line 2584, in upload_from_file\n    _raise_from_invalid_response(exc)\n  File \"/usr/local/lib/python3.10/site-packages/google/cloud/storage/blob.py\", line 4457, in _raise_from_invalid_response\n    raise exceptions.from_http_status(response.status_code, message, response=response)\ngoogle.api_core.exceptions.NotFound: 404 POST https://storage.googleapis.com/upload/storage/v1/b/test-mlops-philippov/o?uploadType=multipart: {\n  \"error\": {\n    \"code\": 404,\n    \"message\": \"The specified bucket does not exist.\",\n    \"errors\": [\n      {\n        \"message\": \"The specified bucket does not exist.\",\n        \"domain\": \"global\",\n        \"reason\": \"notFound\"\n      }\n    ]\n  }\n}\n: ('Request failed with status code', 404, 'Expected one of', <HTTPStatus.OK: 200>)\n"], "error_stack": [["  File \"/usr/local/bin/mage\", line 8, in <module>\n    sys.exit(app())\n", "  File \"/usr/local/lib/python3.10/site-packages/typer/main.py\", line 311, in __call__\n    return get_command(self)(*args, **kwargs)\n", "  File \"/usr/local/lib/python3.10/site-packages/click/core.py\", line 1130, in __call__\n    return self.main(*args, **kwargs)\n", "  File \"/usr/local/lib/python3.10/site-packages/typer/core.py\", line 778, in main\n    return _main(\n", "  File \"/usr/local/lib/python3.10/site-packages/typer/core.py\", line 216, in _main\n    rv = self.invoke(ctx)\n", "  File \"/usr/local/lib/python3.10/site-packages/click/core.py\", line 1657, in invoke\n    return _process_result(sub_ctx.command.invoke(sub_ctx))\n", "  File \"/usr/local/lib/python3.10/site-packages/click/core.py\", line 1404, in invoke\n    return ctx.invoke(self.callback, **ctx.params)\n", "  File \"/usr/local/lib/python3.10/site-packages/click/core.py\", line 760, in invoke\n    return __callback(*args, **kwargs)\n", "  File \"/usr/local/lib/python3.10/site-packages/typer/main.py\", line 683, in wrapper\n    return callback(**use_params)  # type: ignore\n", "  File \"/usr/local/lib/python3.10/site-packages/mage_ai/cli/main.py\", line 147, in start\n    start_server(\n", "  File \"/usr/local/lib/python3.10/site-packages/mage_ai/server/server.py\", line 792, in start_server\n    scheduler_manager.start_scheduler()\n", "  File \"/usr/local/lib/python3.10/site-packages/mage_ai/server/scheduler_manager.py\", line 106, in start_scheduler\n    proc.start()\n", "  File \"/usr/local/lib/python3.10/multiprocessing/process.py\", line 121, in start\n    self._popen = self._Popen(self)\n", "  File \"/usr/local/lib/python3.10/multiprocessing/context.py\", line 224, in _Popen\n    return _default_context.get_context().Process._Popen(process_obj)\n", "  File \"/usr/local/lib/python3.10/multiprocessing/context.py\", line 281, in _Popen\n    return Popen(process_obj)\n", "  File \"/usr/local/lib/python3.10/multiprocessing/popen_fork.py\", line 19, in __init__\n    self._launch(process_obj)\n", "  File \"/usr/local/lib/python3.10/multiprocessing/popen_fork.py\", line 71, in _launch\n    code = process_obj._bootstrap(parent_sentinel=child_r)\n", "  File \"/usr/local/lib/python3.10/multiprocessing/process.py\", line 314, in _bootstrap\n    self.run()\n", "  File \"/usr/local/lib/python3.10/multiprocessing/process.py\", line 108, in run\n    self._target(*self._args, **self._kwargs)\n", "  File \"/usr/local/lib/python3.10/site-packages/mage_ai/orchestration/db/process.py\", line 15, in start_session_and_run\n    results = target(*args)\n", "  File \"/usr/local/lib/python3.10/site-packages/mage_ai/server/scheduler_manager.py\", line 58, in run_scheduler\n    LoopTimeTrigger().start()\n", "  File \"/usr/local/lib/python3.10/site-packages/mage_ai/orchestration/triggers/loop_time_trigger.py\", line 14, in start\n    self.run()\n", "  File \"/usr/local/lib/python3.10/site-packages/mage_ai/orchestration/triggers/time_trigger.py\", line 11, in run\n    schedule_all()\n", "  File \"/usr/local/lib/python3.10/site-packages/mage_ai/orchestration/pipeline_scheduler_original.py\", line 1703, in schedule_all\n    PipelineScheduler(r).start()\n", "  File \"/usr/local/lib/python3.10/site-packages/mage_ai/orchestration/db/__init__.py\", line 158, in func_with_rollback\n    return func(*args, **kwargs)\n", "  File \"/usr/local/lib/python3.10/site-packages/mage_ai/orchestration/pipeline_scheduler_original.py\", line 198, in start\n    self.schedule()\n", "  File \"/usr/local/lib/python3.10/site-packages/mage_ai/orchestration/db/__init__.py\", line 158, in func_with_rollback\n    return func(*args, **kwargs)\n", "  File \"/usr/local/lib/python3.10/site-packages/mage_ai/orchestration/pipeline_scheduler_original.py\", line 334, in schedule\n    self.__schedule_blocks(block_runs)\n", "  File \"/usr/local/lib/python3.10/site-packages/mage_ai/orchestration/pipeline_scheduler_original.py\", line 641, in __schedule_blocks\n    job_manager.add_job(\n", "  File \"/usr/local/lib/python3.10/site-packages/mage_ai/orchestration/job_manager.py\", line 20, in add_job\n    self.queue.enqueue(job_id, target, *args, **kwargs)\n", "  File \"/usr/local/lib/python3.10/site-packages/mage_ai/orchestration/queue/process_queue.py\", line 121, in enqueue\n    self.start_worker_pool()\n", "  File \"/usr/local/lib/python3.10/site-packages/mage_ai/orchestration/queue/process_queue.py\", line 198, in start_worker_pool\n    self.worker_pool_proc.start()\n", "  File \"/usr/local/lib/python3.10/multiprocessing/process.py\", line 121, in start\n    self._popen = self._Popen(self)\n", "  File \"/usr/local/lib/python3.10/multiprocessing/context.py\", line 224, in _Popen\n    return _default_context.get_context().Process._Popen(process_obj)\n", "  File \"/usr/local/lib/python3.10/multiprocessing/context.py\", line 281, in _Popen\n    return Popen(process_obj)\n", "  File \"/usr/local/lib/python3.10/multiprocessing/popen_fork.py\", line 19, in __init__\n    self._launch(process_obj)\n", "  File \"/usr/local/lib/python3.10/multiprocessing/popen_fork.py\", line 71, in _launch\n    code = process_obj._bootstrap(parent_sentinel=child_r)\n", "  File \"/usr/local/lib/python3.10/multiprocessing/process.py\", line 314, in _bootstrap\n    self.run()\n", "  File \"/usr/local/lib/python3.10/multiprocessing/process.py\", line 108, in run\n    self._target(*self._args, **self._kwargs)\n", "  File \"/usr/local/lib/python3.10/site-packages/mage_ai/orchestration/queue/process_queue.py\", line 351, in poll_job_and_execute\n    worker.start()\n", "  File \"/usr/local/lib/python3.10/multiprocessing/process.py\", line 121, in start\n    self._popen = self._Popen(self)\n", "  File \"/usr/local/lib/python3.10/multiprocessing/context.py\", line 224, in _Popen\n    return _default_context.get_context().Process._Popen(process_obj)\n", "  File \"/usr/local/lib/python3.10/multiprocessing/context.py\", line 281, in _Popen\n    return Popen(process_obj)\n", "  File \"/usr/local/lib/python3.10/multiprocessing/popen_fork.py\", line 19, in __init__\n    self._launch(process_obj)\n", "  File \"/usr/local/lib/python3.10/multiprocessing/popen_fork.py\", line 71, in _launch\n    code = process_obj._bootstrap(parent_sentinel=child_r)\n", "  File \"/usr/local/lib/python3.10/multiprocessing/process.py\", line 314, in _bootstrap\n    self.run()\n", "  File \"/usr/local/lib/python3.10/site-packages/newrelic/api/background_task.py\", line 117, in wrapper\n    return wrapped(*args, **kwargs)\n", "  File \"/usr/local/lib/python3.10/site-packages/mage_ai/orchestration/queue/process_queue.py\", line 315, in run\n    start_session_and_run(args[1], *args[2], **args[3])\n", "  File \"/usr/local/lib/python3.10/site-packages/mage_ai/orchestration/db/process.py\", line 15, in start_session_and_run\n    results = target(*args)\n", "  File \"/usr/local/lib/python3.10/site-packages/mage_ai/orchestration/pipeline_scheduler_original.py\", line 1236, in run_block\n    return ExecutorFactory.get_block_executor(\n", "  File \"/usr/local/lib/python3.10/site-packages/mage_ai/data_preparation/executors/block_executor.py\", line 682, in execute\n    on_failure(\n", "  File \"/usr/local/lib/python3.10/site-packages/mage_ai/orchestration/db/__init__.py\", line 158, in func_with_rollback\n    return func(*args, **kwargs)\n", "  File \"/usr/local/lib/python3.10/site-packages/mage_ai/orchestration/pipeline_scheduler_original.py\", line 465, in on_block_failure\n    self.logger.exception(\n", "  File \"/usr/local/lib/python3.10/site-packages/mage_ai/data_preparation/logging/logger.py\", line 30, in exception\n    self.__send_message('exception', message, **kwargs)\n", "  File \"/usr/local/lib/python3.10/site-packages/mage_ai/data_preparation/logging/logger.py\", line 65, in __send_message\n    data['error_stack'] = traceback.format_stack(),\n"]], "error_stacktrace": ["404 POST https://storage.googleapis.com/upload/storage/v1/b/test-mlops-philippov/o?uploadType=multipart: {\n  \"error\": {\n    \"code\": 404,\n    \"message\": \"The specified bucket does not exist.\",\n    \"errors\": [\n      {\n        \"message\": \"The specified bucket does not exist.\",\n        \"domain\": \"global\",\n        \"reason\": \"notFound\"\n      }\n    ]\n  }\n}\n: ('Request failed with status code', 404, 'Expected one of', <HTTPStatus.OK: 200>)"]}
Traceback (most recent call last):
  File "/usr/local/lib/python3.10/site-packages/google/cloud/storage/blob.py", line 2567, in upload_from_file
    created_json = self._do_upload(
  File "/usr/local/lib/python3.10/site-packages/google/cloud/storage/blob.py", line 2368, in _do_upload
    response = self._do_multipart_upload(
  File "/usr/local/lib/python3.10/site-packages/google/cloud/storage/blob.py", line 1903, in _do_multipart_upload
    response = upload.transmit(
  File "/usr/local/lib/python3.10/site-packages/google/resumable_media/requests/upload.py", line 153, in transmit
    return _request_helpers.wait_and_retry(
  File "/usr/local/lib/python3.10/site-packages/google/resumable_media/requests/_request_helpers.py", line 155, in wait_and_retry
    response = func()
  File "/usr/local/lib/python3.10/site-packages/google/resumable_media/requests/upload.py", line 149, in retriable_request
    self._process_response(result)
  File "/usr/local/lib/python3.10/site-packages/google/resumable_media/_upload.py", line 125, in _process_response
    _helpers.require_status_code(response, (http.client.OK,), self._get_status_code)
  File "/usr/local/lib/python3.10/site-packages/google/resumable_media/_helpers.py", line 108, in require_status_code
    raise common.InvalidResponse(
google.resumable_media.common.InvalidResponse: ('Request failed with status code', 404, 'Expected one of', <HTTPStatus.OK: 200>)

During handling of the above exception, another exception occurred:

Traceback (most recent call last):
  File "/usr/local/lib/python3.10/site-packages/mage_ai/data_preparation/executors/block_executor.py", line 647, in execute
    result = __execute_with_retry()
  File "/usr/local/lib/python3.10/site-packages/mage_ai/shared/retry.py", line 54, in retry_func
    raise e
  File "/usr/local/lib/python3.10/site-packages/mage_ai/shared/retry.py", line 38, in retry_func
    return func(*args, **kwargs)
  File "/usr/local/lib/python3.10/site-packages/mage_ai/data_preparation/executors/block_executor.py", line 621, in __execute_with_retry
    return self._execute(
  File "/usr/local/lib/python3.10/site-packages/mage_ai/data_preparation/executors/block_executor.py", line 1154, in _execute
    result = self.block.execute_sync(
  File "/usr/local/lib/python3.10/site-packages/mage_ai/data_preparation/models/block/__init__.py", line 1685, in execute_sync
    return __execute()
  File "/usr/local/lib/python3.10/site-packages/mage_ai/data_preparation/models/block/__init__.py", line 1662, in __execute
    raise err
  File "/usr/local/lib/python3.10/site-packages/mage_ai/data_preparation/models/block/__init__.py", line 1564, in __execute
    output = self.execute_block(
  File "/usr/local/lib/python3.10/site-packages/mage_ai/data_preparation/models/block/__init__.py", line 1904, in execute_block
    outputs = self._execute_block(
  File "/usr/local/lib/python3.10/site-packages/mage_ai/data_preparation/models/block/__init__.py", line 2067, in _execute_block
    outputs = self.execute_block_function(
  File "/usr/local/lib/python3.10/site-packages/mage_ai/data_preparation/models/block/__init__.py", line 2163, in execute_block_function
    output = block_function_updated(*input_vars, **global_vars)
  File "<string>", line 33, in hyperparameter_tuning
  File "/home/src/Basketball_results_prediction/utils/sklearn.py", line 138, in tune_hyperparameters
    best_hyperparameters = fmin(
  File "/usr/local/lib/python3.10/site-packages/hyperopt/fmin.py", line 540, in fmin
    return trials.fmin(
  File "/usr/local/lib/python3.10/site-packages/hyperopt/base.py", line 671, in fmin
    return fmin(
  File "/usr/local/lib/python3.10/site-packages/hyperopt/fmin.py", line 586, in fmin
    rval.exhaust()
  File "/usr/local/lib/python3.10/site-packages/hyperopt/fmin.py", line 364, in exhaust
    self.run(self.max_evals - n_done, block_until_done=self.asynchronous)
  File "/usr/local/lib/python3.10/site-packages/hyperopt/fmin.py", line 300, in run
    self.serial_evaluate()
  File "/usr/local/lib/python3.10/site-packages/hyperopt/fmin.py", line 178, in serial_evaluate
    result = self.domain.evaluate(spec, ctrl)
  File "/usr/local/lib/python3.10/site-packages/hyperopt/base.py", line 892, in evaluate
    rval = self.fn(pyll_rval)
  File "/home/src/Basketball_results_prediction/utils/sklearn.py", line 122, in __objective
    mlflow.sklearn.log_model(artifact_path="",sk_model=model)
  File "/usr/local/lib/python3.10/site-packages/mlflow/sklearn/__init__.py", line 418, in log_model
    return Model.log(
  File "/usr/local/lib/python3.10/site-packages/mlflow/models/model.py", line 656, in log
    mlflow.tracking.fluent.log_artifacts(local_path, mlflow_model.artifact_path, run_id)
  File "/usr/local/lib/python3.10/site-packages/mlflow/tracking/fluent.py", line 1096, in log_artifacts
    MlflowClient().log_artifacts(run_id, local_dir, artifact_path)
  File "/usr/local/lib/python3.10/site-packages/mlflow/tracking/client.py", line 1242, in log_artifacts
    self._tracking_client.log_artifacts(run_id, local_dir, artifact_path)
  File "/usr/local/lib/python3.10/site-packages/mlflow/tracking/_tracking_service/client.py", line 570, in log_artifacts
    self._get_artifact_repo(run_id).log_artifacts(local_dir, artifact_path)
  File "/usr/local/lib/python3.10/site-packages/mlflow/store/artifact/gcs_artifact_repo.py", line 106, in log_artifacts
    gcs_bucket.blob(path, chunk_size=self._GCS_UPLOAD_CHUNK_SIZE).upload_from_filename(
  File "/usr/local/lib/python3.10/site-packages/google/cloud/storage/blob.py", line 2708, in upload_from_filename
    self.upload_from_file(
  File "/usr/local/lib/python3.10/site-packages/google/cloud/storage/blob.py", line 2584, in upload_from_file
    _raise_from_invalid_response(exc)
  File "/usr/local/lib/python3.10/site-packages/google/cloud/storage/blob.py", line 4457, in _raise_from_invalid_response
    raise exceptions.from_http_status(response.status_code, message, response=response)
google.api_core.exceptions.NotFound: 404 POST https://storage.googleapis.com/upload/storage/v1/b/test-mlops-philippov/o?uploadType=multipart: {
  "error": {
    "code": 404,
    "message": "The specified bucket does not exist.",
    "errors": [
      {
        "message": "The specified bucket does not exist.",
        "domain": "global",
        "reason": "notFound"
      }
    ]
  }
}
: ('Request failed with status code', 404, 'Expected one of', <HTTPStatus.OK: 200>)
2024-08-10T21:58:33 {"block_run_id": 196, "block_uuid": "training:LinearRegression", "pipeline_run_id": 42, "pipeline_schedule_id": 3, "pipeline_uuid": "train_sklearn", "hostname": "fbd19c79e2e6", "level": "EXCEPTION", "message": "BlockRun 196 (block_uuid: training:LinearRegression) failed.", "timestamp": 1723327113.658296, "uuid": "0f30b1f9130c44fba58717fb5212b6e1", "error": ["Traceback (most recent call last):\n  File \"/usr/local/lib/python3.10/site-packages/google/cloud/storage/blob.py\", line 2567, in upload_from_file\n    created_json = self._do_upload(\n  File \"/usr/local/lib/python3.10/site-packages/google/cloud/storage/blob.py\", line 2368, in _do_upload\n    response = self._do_multipart_upload(\n  File \"/usr/local/lib/python3.10/site-packages/google/cloud/storage/blob.py\", line 1903, in _do_multipart_upload\n    response = upload.transmit(\n  File \"/usr/local/lib/python3.10/site-packages/google/resumable_media/requests/upload.py\", line 153, in transmit\n    return _request_helpers.wait_and_retry(\n  File \"/usr/local/lib/python3.10/site-packages/google/resumable_media/requests/_request_helpers.py\", line 155, in wait_and_retry\n    response = func()\n  File \"/usr/local/lib/python3.10/site-packages/google/resumable_media/requests/upload.py\", line 149, in retriable_request\n    self._process_response(result)\n  File \"/usr/local/lib/python3.10/site-packages/google/resumable_media/_upload.py\", line 125, in _process_response\n    _helpers.require_status_code(response, (http.client.OK,), self._get_status_code)\n  File \"/usr/local/lib/python3.10/site-packages/google/resumable_media/_helpers.py\", line 108, in require_status_code\n    raise common.InvalidResponse(\ngoogle.resumable_media.common.InvalidResponse: ('Request failed with status code', 404, 'Expected one of', <HTTPStatus.OK: 200>)\n\nDuring handling of the above exception, another exception occurred:\n\nTraceback (most recent call last):\n  File \"/usr/local/lib/python3.10/site-packages/mage_ai/data_preparation/executors/block_executor.py\", line 647, in execute\n    result = __execute_with_retry()\n  File \"/usr/local/lib/python3.10/site-packages/mage_ai/shared/retry.py\", line 54, in retry_func\n    raise e\n  File \"/usr/local/lib/python3.10/site-packages/mage_ai/shared/retry.py\", line 38, in retry_func\n    return func(*args, **kwargs)\n  File \"/usr/local/lib/python3.10/site-packages/mage_ai/data_preparation/executors/block_executor.py\", line 621, in __execute_with_retry\n    return self._execute(\n  File \"/usr/local/lib/python3.10/site-packages/mage_ai/data_preparation/executors/block_executor.py\", line 1154, in _execute\n    result = self.block.execute_sync(\n  File \"/usr/local/lib/python3.10/site-packages/mage_ai/data_preparation/models/block/__init__.py\", line 1685, in execute_sync\n    return __execute()\n  File \"/usr/local/lib/python3.10/site-packages/mage_ai/data_preparation/models/block/__init__.py\", line 1662, in __execute\n    raise err\n  File \"/usr/local/lib/python3.10/site-packages/mage_ai/data_preparation/models/block/__init__.py\", line 1564, in __execute\n    output = self.execute_block(\n  File \"/usr/local/lib/python3.10/site-packages/mage_ai/data_preparation/models/block/__init__.py\", line 1904, in execute_block\n    outputs = self._execute_block(\n  File \"/usr/local/lib/python3.10/site-packages/mage_ai/data_preparation/models/block/__init__.py\", line 2067, in _execute_block\n    outputs = self.execute_block_function(\n  File \"/usr/local/lib/python3.10/site-packages/mage_ai/data_preparation/models/block/__init__.py\", line 2163, in execute_block_function\n    output = block_function_updated(*input_vars, **global_vars)\n  File \"<string>\", line 33, in hyperparameter_tuning\n  File \"/home/src/Basketball_results_prediction/utils/sklearn.py\", line 138, in tune_hyperparameters\n    best_hyperparameters = fmin(\n  File \"/usr/local/lib/python3.10/site-packages/hyperopt/fmin.py\", line 540, in fmin\n    return trials.fmin(\n  File \"/usr/local/lib/python3.10/site-packages/hyperopt/base.py\", line 671, in fmin\n    return fmin(\n  File \"/usr/local/lib/python3.10/site-packages/hyperopt/fmin.py\", line 586, in fmin\n    rval.exhaust()\n  File \"/usr/local/lib/python3.10/site-packages/hyperopt/fmin.py\", line 364, in exhaust\n    self.run(self.max_evals - n_done, block_until_done=self.asynchronous)\n  File \"/usr/local/lib/python3.10/site-packages/hyperopt/fmin.py\", line 300, in run\n    self.serial_evaluate()\n  File \"/usr/local/lib/python3.10/site-packages/hyperopt/fmin.py\", line 178, in serial_evaluate\n    result = self.domain.evaluate(spec, ctrl)\n  File \"/usr/local/lib/python3.10/site-packages/hyperopt/base.py\", line 892, in evaluate\n    rval = self.fn(pyll_rval)\n  File \"/home/src/Basketball_results_prediction/utils/sklearn.py\", line 122, in __objective\n    mlflow.sklearn.log_model(artifact_path=\"\",sk_model=model)\n  File \"/usr/local/lib/python3.10/site-packages/mlflow/sklearn/__init__.py\", line 418, in log_model\n    return Model.log(\n  File \"/usr/local/lib/python3.10/site-packages/mlflow/models/model.py\", line 656, in log\n    mlflow.tracking.fluent.log_artifacts(local_path, mlflow_model.artifact_path, run_id)\n  File \"/usr/local/lib/python3.10/site-packages/mlflow/tracking/fluent.py\", line 1096, in log_artifacts\n    MlflowClient().log_artifacts(run_id, local_dir, artifact_path)\n  File \"/usr/local/lib/python3.10/site-packages/mlflow/tracking/client.py\", line 1242, in log_artifacts\n    self._tracking_client.log_artifacts(run_id, local_dir, artifact_path)\n  File \"/usr/local/lib/python3.10/site-packages/mlflow/tracking/_tracking_service/client.py\", line 570, in log_artifacts\n    self._get_artifact_repo(run_id).log_artifacts(local_dir, artifact_path)\n  File \"/usr/local/lib/python3.10/site-packages/mlflow/store/artifact/gcs_artifact_repo.py\", line 106, in log_artifacts\n    gcs_bucket.blob(path, chunk_size=self._GCS_UPLOAD_CHUNK_SIZE).upload_from_filename(\n  File \"/usr/local/lib/python3.10/site-packages/google/cloud/storage/blob.py\", line 2708, in upload_from_filename\n    self.upload_from_file(\n  File \"/usr/local/lib/python3.10/site-packages/google/cloud/storage/blob.py\", line 2584, in upload_from_file\n    _raise_from_invalid_response(exc)\n  File \"/usr/local/lib/python3.10/site-packages/google/cloud/storage/blob.py\", line 4457, in _raise_from_invalid_response\n    raise exceptions.from_http_status(response.status_code, message, response=response)\ngoogle.api_core.exceptions.NotFound: 404 POST https://storage.googleapis.com/upload/storage/v1/b/test-mlops-philippov/o?uploadType=multipart: {\n  \"error\": {\n    \"code\": 404,\n    \"message\": \"The specified bucket does not exist.\",\n    \"errors\": [\n      {\n        \"message\": \"The specified bucket does not exist.\",\n        \"domain\": \"global\",\n        \"reason\": \"notFound\"\n      }\n    ]\n  }\n}\n: ('Request failed with status code', 404, 'Expected one of', <HTTPStatus.OK: 200>)\n"], "error_stack": [["  File \"/usr/local/bin/mage\", line 8, in <module>\n    sys.exit(app())\n", "  File \"/usr/local/lib/python3.10/site-packages/typer/main.py\", line 311, in __call__\n    return get_command(self)(*args, **kwargs)\n", "  File \"/usr/local/lib/python3.10/site-packages/click/core.py\", line 1130, in __call__\n    return self.main(*args, **kwargs)\n", "  File \"/usr/local/lib/python3.10/site-packages/typer/core.py\", line 778, in main\n    return _main(\n", "  File \"/usr/local/lib/python3.10/site-packages/typer/core.py\", line 216, in _main\n    rv = self.invoke(ctx)\n", "  File \"/usr/local/lib/python3.10/site-packages/click/core.py\", line 1657, in invoke\n    return _process_result(sub_ctx.command.invoke(sub_ctx))\n", "  File \"/usr/local/lib/python3.10/site-packages/click/core.py\", line 1404, in invoke\n    return ctx.invoke(self.callback, **ctx.params)\n", "  File \"/usr/local/lib/python3.10/site-packages/click/core.py\", line 760, in invoke\n    return __callback(*args, **kwargs)\n", "  File \"/usr/local/lib/python3.10/site-packages/typer/main.py\", line 683, in wrapper\n    return callback(**use_params)  # type: ignore\n", "  File \"/usr/local/lib/python3.10/site-packages/mage_ai/cli/main.py\", line 147, in start\n    start_server(\n", "  File \"/usr/local/lib/python3.10/site-packages/mage_ai/server/server.py\", line 792, in start_server\n    scheduler_manager.start_scheduler()\n", "  File \"/usr/local/lib/python3.10/site-packages/mage_ai/server/scheduler_manager.py\", line 106, in start_scheduler\n    proc.start()\n", "  File \"/usr/local/lib/python3.10/multiprocessing/process.py\", line 121, in start\n    self._popen = self._Popen(self)\n", "  File \"/usr/local/lib/python3.10/multiprocessing/context.py\", line 224, in _Popen\n    return _default_context.get_context().Process._Popen(process_obj)\n", "  File \"/usr/local/lib/python3.10/multiprocessing/context.py\", line 281, in _Popen\n    return Popen(process_obj)\n", "  File \"/usr/local/lib/python3.10/multiprocessing/popen_fork.py\", line 19, in __init__\n    self._launch(process_obj)\n", "  File \"/usr/local/lib/python3.10/multiprocessing/popen_fork.py\", line 71, in _launch\n    code = process_obj._bootstrap(parent_sentinel=child_r)\n", "  File \"/usr/local/lib/python3.10/multiprocessing/process.py\", line 314, in _bootstrap\n    self.run()\n", "  File \"/usr/local/lib/python3.10/multiprocessing/process.py\", line 108, in run\n    self._target(*self._args, **self._kwargs)\n", "  File \"/usr/local/lib/python3.10/site-packages/mage_ai/orchestration/db/process.py\", line 15, in start_session_and_run\n    results = target(*args)\n", "  File \"/usr/local/lib/python3.10/site-packages/mage_ai/server/scheduler_manager.py\", line 58, in run_scheduler\n    LoopTimeTrigger().start()\n", "  File \"/usr/local/lib/python3.10/site-packages/mage_ai/orchestration/triggers/loop_time_trigger.py\", line 14, in start\n    self.run()\n", "  File \"/usr/local/lib/python3.10/site-packages/mage_ai/orchestration/triggers/time_trigger.py\", line 11, in run\n    schedule_all()\n", "  File \"/usr/local/lib/python3.10/site-packages/mage_ai/orchestration/pipeline_scheduler_original.py\", line 1703, in schedule_all\n    PipelineScheduler(r).start()\n", "  File \"/usr/local/lib/python3.10/site-packages/mage_ai/orchestration/db/__init__.py\", line 158, in func_with_rollback\n    return func(*args, **kwargs)\n", "  File \"/usr/local/lib/python3.10/site-packages/mage_ai/orchestration/pipeline_scheduler_original.py\", line 198, in start\n    self.schedule()\n", "  File \"/usr/local/lib/python3.10/site-packages/mage_ai/orchestration/db/__init__.py\", line 158, in func_with_rollback\n    return func(*args, **kwargs)\n", "  File \"/usr/local/lib/python3.10/site-packages/mage_ai/orchestration/pipeline_scheduler_original.py\", line 334, in schedule\n    self.__schedule_blocks(block_runs)\n", "  File \"/usr/local/lib/python3.10/site-packages/mage_ai/orchestration/pipeline_scheduler_original.py\", line 641, in __schedule_blocks\n    job_manager.add_job(\n", "  File \"/usr/local/lib/python3.10/site-packages/mage_ai/orchestration/job_manager.py\", line 20, in add_job\n    self.queue.enqueue(job_id, target, *args, **kwargs)\n", "  File \"/usr/local/lib/python3.10/site-packages/mage_ai/orchestration/queue/process_queue.py\", line 121, in enqueue\n    self.start_worker_pool()\n", "  File \"/usr/local/lib/python3.10/site-packages/mage_ai/orchestration/queue/process_queue.py\", line 198, in start_worker_pool\n    self.worker_pool_proc.start()\n", "  File \"/usr/local/lib/python3.10/multiprocessing/process.py\", line 121, in start\n    self._popen = self._Popen(self)\n", "  File \"/usr/local/lib/python3.10/multiprocessing/context.py\", line 224, in _Popen\n    return _default_context.get_context().Process._Popen(process_obj)\n", "  File \"/usr/local/lib/python3.10/multiprocessing/context.py\", line 281, in _Popen\n    return Popen(process_obj)\n", "  File \"/usr/local/lib/python3.10/multiprocessing/popen_fork.py\", line 19, in __init__\n    self._launch(process_obj)\n", "  File \"/usr/local/lib/python3.10/multiprocessing/popen_fork.py\", line 71, in _launch\n    code = process_obj._bootstrap(parent_sentinel=child_r)\n", "  File \"/usr/local/lib/python3.10/multiprocessing/process.py\", line 314, in _bootstrap\n    self.run()\n", "  File \"/usr/local/lib/python3.10/multiprocessing/process.py\", line 108, in run\n    self._target(*self._args, **self._kwargs)\n", "  File \"/usr/local/lib/python3.10/site-packages/mage_ai/orchestration/queue/process_queue.py\", line 351, in poll_job_and_execute\n    worker.start()\n", "  File \"/usr/local/lib/python3.10/multiprocessing/process.py\", line 121, in start\n    self._popen = self._Popen(self)\n", "  File \"/usr/local/lib/python3.10/multiprocessing/context.py\", line 224, in _Popen\n    return _default_context.get_context().Process._Popen(process_obj)\n", "  File \"/usr/local/lib/python3.10/multiprocessing/context.py\", line 281, in _Popen\n    return Popen(process_obj)\n", "  File \"/usr/local/lib/python3.10/multiprocessing/popen_fork.py\", line 19, in __init__\n    self._launch(process_obj)\n", "  File \"/usr/local/lib/python3.10/multiprocessing/popen_fork.py\", line 71, in _launch\n    code = process_obj._bootstrap(parent_sentinel=child_r)\n", "  File \"/usr/local/lib/python3.10/multiprocessing/process.py\", line 314, in _bootstrap\n    self.run()\n", "  File \"/usr/local/lib/python3.10/site-packages/newrelic/api/background_task.py\", line 117, in wrapper\n    return wrapped(*args, **kwargs)\n", "  File \"/usr/local/lib/python3.10/site-packages/mage_ai/orchestration/queue/process_queue.py\", line 315, in run\n    start_session_and_run(args[1], *args[2], **args[3])\n", "  File \"/usr/local/lib/python3.10/site-packages/mage_ai/orchestration/db/process.py\", line 15, in start_session_and_run\n    results = target(*args)\n", "  File \"/usr/local/lib/python3.10/site-packages/mage_ai/orchestration/pipeline_scheduler_original.py\", line 1236, in run_block\n    return ExecutorFactory.get_block_executor(\n", "  File \"/usr/local/lib/python3.10/site-packages/mage_ai/data_preparation/executors/block_executor.py\", line 682, in execute\n    on_failure(\n", "  File \"/usr/local/lib/python3.10/site-packages/mage_ai/orchestration/db/__init__.py\", line 158, in func_with_rollback\n    return func(*args, **kwargs)\n", "  File \"/usr/local/lib/python3.10/site-packages/mage_ai/orchestration/pipeline_scheduler_original.py\", line 465, in on_block_failure\n    self.logger.exception(\n", "  File \"/usr/local/lib/python3.10/site-packages/mage_ai/data_preparation/logging/logger.py\", line 30, in exception\n    self.__send_message('exception', message, **kwargs)\n", "  File \"/usr/local/lib/python3.10/site-packages/mage_ai/data_preparation/logging/logger.py\", line 65, in __send_message\n    data['error_stack'] = traceback.format_stack(),\n"]], "error_stacktrace": ["404 POST https://storage.googleapis.com/upload/storage/v1/b/test-mlops-philippov/o?uploadType=multipart: {\n  \"error\": {\n    \"code\": 404,\n    \"message\": \"The specified bucket does not exist.\",\n    \"errors\": [\n      {\n        \"message\": \"The specified bucket does not exist.\",\n        \"domain\": \"global\",\n        \"reason\": \"notFound\"\n      }\n    ]\n  }\n}\n: ('Request failed with status code', 404, 'Expected one of', <HTTPStatus.OK: 200>)"]}
Traceback (most recent call last):
  File "/usr/local/lib/python3.10/site-packages/google/cloud/storage/blob.py", line 2567, in upload_from_file
    created_json = self._do_upload(
  File "/usr/local/lib/python3.10/site-packages/google/cloud/storage/blob.py", line 2368, in _do_upload
    response = self._do_multipart_upload(
  File "/usr/local/lib/python3.10/site-packages/google/cloud/storage/blob.py", line 1903, in _do_multipart_upload
    response = upload.transmit(
  File "/usr/local/lib/python3.10/site-packages/google/resumable_media/requests/upload.py", line 153, in transmit
    return _request_helpers.wait_and_retry(
  File "/usr/local/lib/python3.10/site-packages/google/resumable_media/requests/_request_helpers.py", line 155, in wait_and_retry
    response = func()
  File "/usr/local/lib/python3.10/site-packages/google/resumable_media/requests/upload.py", line 149, in retriable_request
    self._process_response(result)
  File "/usr/local/lib/python3.10/site-packages/google/resumable_media/_upload.py", line 125, in _process_response
    _helpers.require_status_code(response, (http.client.OK,), self._get_status_code)
  File "/usr/local/lib/python3.10/site-packages/google/resumable_media/_helpers.py", line 108, in require_status_code
    raise common.InvalidResponse(
google.resumable_media.common.InvalidResponse: ('Request failed with status code', 404, 'Expected one of', <HTTPStatus.OK: 200>)

During handling of the above exception, another exception occurred:

Traceback (most recent call last):
  File "/usr/local/lib/python3.10/site-packages/mage_ai/data_preparation/executors/block_executor.py", line 647, in execute
    result = __execute_with_retry()
  File "/usr/local/lib/python3.10/site-packages/mage_ai/shared/retry.py", line 54, in retry_func
    raise e
  File "/usr/local/lib/python3.10/site-packages/mage_ai/shared/retry.py", line 38, in retry_func
    return func(*args, **kwargs)
  File "/usr/local/lib/python3.10/site-packages/mage_ai/data_preparation/executors/block_executor.py", line 621, in __execute_with_retry
    return self._execute(
  File "/usr/local/lib/python3.10/site-packages/mage_ai/data_preparation/executors/block_executor.py", line 1154, in _execute
    result = self.block.execute_sync(
  File "/usr/local/lib/python3.10/site-packages/mage_ai/data_preparation/models/block/__init__.py", line 1685, in execute_sync
    return __execute()
  File "/usr/local/lib/python3.10/site-packages/mage_ai/data_preparation/models/block/__init__.py", line 1662, in __execute
    raise err
  File "/usr/local/lib/python3.10/site-packages/mage_ai/data_preparation/models/block/__init__.py", line 1564, in __execute
    output = self.execute_block(
  File "/usr/local/lib/python3.10/site-packages/mage_ai/data_preparation/models/block/__init__.py", line 1904, in execute_block
    outputs = self._execute_block(
  File "/usr/local/lib/python3.10/site-packages/mage_ai/data_preparation/models/block/__init__.py", line 2067, in _execute_block
    outputs = self.execute_block_function(
  File "/usr/local/lib/python3.10/site-packages/mage_ai/data_preparation/models/block/__init__.py", line 2163, in execute_block_function
    output = block_function_updated(*input_vars, **global_vars)
  File "<string>", line 33, in hyperparameter_tuning
  File "/home/src/Basketball_results_prediction/utils/sklearn.py", line 138, in tune_hyperparameters
    best_hyperparameters = fmin(
  File "/usr/local/lib/python3.10/site-packages/hyperopt/fmin.py", line 540, in fmin
    return trials.fmin(
  File "/usr/local/lib/python3.10/site-packages/hyperopt/base.py", line 671, in fmin
    return fmin(
  File "/usr/local/lib/python3.10/site-packages/hyperopt/fmin.py", line 586, in fmin
    rval.exhaust()
  File "/usr/local/lib/python3.10/site-packages/hyperopt/fmin.py", line 364, in exhaust
    self.run(self.max_evals - n_done, block_until_done=self.asynchronous)
  File "/usr/local/lib/python3.10/site-packages/hyperopt/fmin.py", line 300, in run
    self.serial_evaluate()
  File "/usr/local/lib/python3.10/site-packages/hyperopt/fmin.py", line 178, in serial_evaluate
    result = self.domain.evaluate(spec, ctrl)
  File "/usr/local/lib/python3.10/site-packages/hyperopt/base.py", line 892, in evaluate
    rval = self.fn(pyll_rval)
  File "/home/src/Basketball_results_prediction/utils/sklearn.py", line 122, in __objective
    mlflow.sklearn.log_model(artifact_path="",sk_model=model)
  File "/usr/local/lib/python3.10/site-packages/mlflow/sklearn/__init__.py", line 418, in log_model
    return Model.log(
  File "/usr/local/lib/python3.10/site-packages/mlflow/models/model.py", line 656, in log
    mlflow.tracking.fluent.log_artifacts(local_path, mlflow_model.artifact_path, run_id)
  File "/usr/local/lib/python3.10/site-packages/mlflow/tracking/fluent.py", line 1096, in log_artifacts
    MlflowClient().log_artifacts(run_id, local_dir, artifact_path)
  File "/usr/local/lib/python3.10/site-packages/mlflow/tracking/client.py", line 1242, in log_artifacts
    self._tracking_client.log_artifacts(run_id, local_dir, artifact_path)
  File "/usr/local/lib/python3.10/site-packages/mlflow/tracking/_tracking_service/client.py", line 570, in log_artifacts
    self._get_artifact_repo(run_id).log_artifacts(local_dir, artifact_path)
  File "/usr/local/lib/python3.10/site-packages/mlflow/store/artifact/gcs_artifact_repo.py", line 106, in log_artifacts
    gcs_bucket.blob(path, chunk_size=self._GCS_UPLOAD_CHUNK_SIZE).upload_from_filename(
  File "/usr/local/lib/python3.10/site-packages/google/cloud/storage/blob.py", line 2708, in upload_from_filename
    self.upload_from_file(
  File "/usr/local/lib/python3.10/site-packages/google/cloud/storage/blob.py", line 2584, in upload_from_file
    _raise_from_invalid_response(exc)
  File "/usr/local/lib/python3.10/site-packages/google/cloud/storage/blob.py", line 4457, in _raise_from_invalid_response
    raise exceptions.from_http_status(response.status_code, message, response=response)
google.api_core.exceptions.NotFound: 404 POST https://storage.googleapis.com/upload/storage/v1/b/test-mlops-philippov/o?uploadType=multipart: {
  "error": {
    "code": 404,
    "message": "The specified bucket does not exist.",
    "errors": [
      {
        "message": "The specified bucket does not exist.",
        "domain": "global",
        "reason": "notFound"
      }
    ]
  }
}
: ('Request failed with status code', 404, 'Expected one of', <HTTPStatus.OK: 200>)
2024-08-10T21:58:33 {"block_run_id": 198, "block_uuid": "training:RandomForestRegressor", "pipeline_run_id": 42, "pipeline_schedule_id": 3, "pipeline_uuid": "train_sklearn", "hostname": "fbd19c79e2e6", "level": "EXCEPTION", "message": "BlockRun 198 (block_uuid: training:RandomForestRegressor) failed.", "timestamp": 1723327113.668627, "uuid": "4795795949e54cd3b4acf350146e3d64", "error": ["Traceback (most recent call last):\n  File \"/usr/local/lib/python3.10/site-packages/google/cloud/storage/blob.py\", line 2567, in upload_from_file\n    created_json = self._do_upload(\n  File \"/usr/local/lib/python3.10/site-packages/google/cloud/storage/blob.py\", line 2368, in _do_upload\n    response = self._do_multipart_upload(\n  File \"/usr/local/lib/python3.10/site-packages/google/cloud/storage/blob.py\", line 1903, in _do_multipart_upload\n    response = upload.transmit(\n  File \"/usr/local/lib/python3.10/site-packages/google/resumable_media/requests/upload.py\", line 153, in transmit\n    return _request_helpers.wait_and_retry(\n  File \"/usr/local/lib/python3.10/site-packages/google/resumable_media/requests/_request_helpers.py\", line 155, in wait_and_retry\n    response = func()\n  File \"/usr/local/lib/python3.10/site-packages/google/resumable_media/requests/upload.py\", line 149, in retriable_request\n    self._process_response(result)\n  File \"/usr/local/lib/python3.10/site-packages/google/resumable_media/_upload.py\", line 125, in _process_response\n    _helpers.require_status_code(response, (http.client.OK,), self._get_status_code)\n  File \"/usr/local/lib/python3.10/site-packages/google/resumable_media/_helpers.py\", line 108, in require_status_code\n    raise common.InvalidResponse(\ngoogle.resumable_media.common.InvalidResponse: ('Request failed with status code', 404, 'Expected one of', <HTTPStatus.OK: 200>)\n\nDuring handling of the above exception, another exception occurred:\n\nTraceback (most recent call last):\n  File \"/usr/local/lib/python3.10/site-packages/mage_ai/data_preparation/executors/block_executor.py\", line 647, in execute\n    result = __execute_with_retry()\n  File \"/usr/local/lib/python3.10/site-packages/mage_ai/shared/retry.py\", line 54, in retry_func\n    raise e\n  File \"/usr/local/lib/python3.10/site-packages/mage_ai/shared/retry.py\", line 38, in retry_func\n    return func(*args, **kwargs)\n  File \"/usr/local/lib/python3.10/site-packages/mage_ai/data_preparation/executors/block_executor.py\", line 621, in __execute_with_retry\n    return self._execute(\n  File \"/usr/local/lib/python3.10/site-packages/mage_ai/data_preparation/executors/block_executor.py\", line 1154, in _execute\n    result = self.block.execute_sync(\n  File \"/usr/local/lib/python3.10/site-packages/mage_ai/data_preparation/models/block/__init__.py\", line 1685, in execute_sync\n    return __execute()\n  File \"/usr/local/lib/python3.10/site-packages/mage_ai/data_preparation/models/block/__init__.py\", line 1662, in __execute\n    raise err\n  File \"/usr/local/lib/python3.10/site-packages/mage_ai/data_preparation/models/block/__init__.py\", line 1564, in __execute\n    output = self.execute_block(\n  File \"/usr/local/lib/python3.10/site-packages/mage_ai/data_preparation/models/block/__init__.py\", line 1904, in execute_block\n    outputs = self._execute_block(\n  File \"/usr/local/lib/python3.10/site-packages/mage_ai/data_preparation/models/block/__init__.py\", line 2067, in _execute_block\n    outputs = self.execute_block_function(\n  File \"/usr/local/lib/python3.10/site-packages/mage_ai/data_preparation/models/block/__init__.py\", line 2163, in execute_block_function\n    output = block_function_updated(*input_vars, **global_vars)\n  File \"<string>\", line 33, in hyperparameter_tuning\n  File \"/home/src/Basketball_results_prediction/utils/sklearn.py\", line 138, in tune_hyperparameters\n    best_hyperparameters = fmin(\n  File \"/usr/local/lib/python3.10/site-packages/hyperopt/fmin.py\", line 540, in fmin\n    return trials.fmin(\n  File \"/usr/local/lib/python3.10/site-packages/hyperopt/base.py\", line 671, in fmin\n    return fmin(\n  File \"/usr/local/lib/python3.10/site-packages/hyperopt/fmin.py\", line 586, in fmin\n    rval.exhaust()\n  File \"/usr/local/lib/python3.10/site-packages/hyperopt/fmin.py\", line 364, in exhaust\n    self.run(self.max_evals - n_done, block_until_done=self.asynchronous)\n  File \"/usr/local/lib/python3.10/site-packages/hyperopt/fmin.py\", line 300, in run\n    self.serial_evaluate()\n  File \"/usr/local/lib/python3.10/site-packages/hyperopt/fmin.py\", line 178, in serial_evaluate\n    result = self.domain.evaluate(spec, ctrl)\n  File \"/usr/local/lib/python3.10/site-packages/hyperopt/base.py\", line 892, in evaluate\n    rval = self.fn(pyll_rval)\n  File \"/home/src/Basketball_results_prediction/utils/sklearn.py\", line 122, in __objective\n    mlflow.sklearn.log_model(artifact_path=\"\",sk_model=model)\n  File \"/usr/local/lib/python3.10/site-packages/mlflow/sklearn/__init__.py\", line 418, in log_model\n    return Model.log(\n  File \"/usr/local/lib/python3.10/site-packages/mlflow/models/model.py\", line 656, in log\n    mlflow.tracking.fluent.log_artifacts(local_path, mlflow_model.artifact_path, run_id)\n  File \"/usr/local/lib/python3.10/site-packages/mlflow/tracking/fluent.py\", line 1096, in log_artifacts\n    MlflowClient().log_artifacts(run_id, local_dir, artifact_path)\n  File \"/usr/local/lib/python3.10/site-packages/mlflow/tracking/client.py\", line 1242, in log_artifacts\n    self._tracking_client.log_artifacts(run_id, local_dir, artifact_path)\n  File \"/usr/local/lib/python3.10/site-packages/mlflow/tracking/_tracking_service/client.py\", line 570, in log_artifacts\n    self._get_artifact_repo(run_id).log_artifacts(local_dir, artifact_path)\n  File \"/usr/local/lib/python3.10/site-packages/mlflow/store/artifact/gcs_artifact_repo.py\", line 106, in log_artifacts\n    gcs_bucket.blob(path, chunk_size=self._GCS_UPLOAD_CHUNK_SIZE).upload_from_filename(\n  File \"/usr/local/lib/python3.10/site-packages/google/cloud/storage/blob.py\", line 2708, in upload_from_filename\n    self.upload_from_file(\n  File \"/usr/local/lib/python3.10/site-packages/google/cloud/storage/blob.py\", line 2584, in upload_from_file\n    _raise_from_invalid_response(exc)\n  File \"/usr/local/lib/python3.10/site-packages/google/cloud/storage/blob.py\", line 4457, in _raise_from_invalid_response\n    raise exceptions.from_http_status(response.status_code, message, response=response)\ngoogle.api_core.exceptions.NotFound: 404 POST https://storage.googleapis.com/upload/storage/v1/b/test-mlops-philippov/o?uploadType=multipart: {\n  \"error\": {\n    \"code\": 404,\n    \"message\": \"The specified bucket does not exist.\",\n    \"errors\": [\n      {\n        \"message\": \"The specified bucket does not exist.\",\n        \"domain\": \"global\",\n        \"reason\": \"notFound\"\n      }\n    ]\n  }\n}\n: ('Request failed with status code', 404, 'Expected one of', <HTTPStatus.OK: 200>)\n"], "error_stack": [["  File \"/usr/local/bin/mage\", line 8, in <module>\n    sys.exit(app())\n", "  File \"/usr/local/lib/python3.10/site-packages/typer/main.py\", line 311, in __call__\n    return get_command(self)(*args, **kwargs)\n", "  File \"/usr/local/lib/python3.10/site-packages/click/core.py\", line 1130, in __call__\n    return self.main(*args, **kwargs)\n", "  File \"/usr/local/lib/python3.10/site-packages/typer/core.py\", line 778, in main\n    return _main(\n", "  File \"/usr/local/lib/python3.10/site-packages/typer/core.py\", line 216, in _main\n    rv = self.invoke(ctx)\n", "  File \"/usr/local/lib/python3.10/site-packages/click/core.py\", line 1657, in invoke\n    return _process_result(sub_ctx.command.invoke(sub_ctx))\n", "  File \"/usr/local/lib/python3.10/site-packages/click/core.py\", line 1404, in invoke\n    return ctx.invoke(self.callback, **ctx.params)\n", "  File \"/usr/local/lib/python3.10/site-packages/click/core.py\", line 760, in invoke\n    return __callback(*args, **kwargs)\n", "  File \"/usr/local/lib/python3.10/site-packages/typer/main.py\", line 683, in wrapper\n    return callback(**use_params)  # type: ignore\n", "  File \"/usr/local/lib/python3.10/site-packages/mage_ai/cli/main.py\", line 147, in start\n    start_server(\n", "  File \"/usr/local/lib/python3.10/site-packages/mage_ai/server/server.py\", line 792, in start_server\n    scheduler_manager.start_scheduler()\n", "  File \"/usr/local/lib/python3.10/site-packages/mage_ai/server/scheduler_manager.py\", line 106, in start_scheduler\n    proc.start()\n", "  File \"/usr/local/lib/python3.10/multiprocessing/process.py\", line 121, in start\n    self._popen = self._Popen(self)\n", "  File \"/usr/local/lib/python3.10/multiprocessing/context.py\", line 224, in _Popen\n    return _default_context.get_context().Process._Popen(process_obj)\n", "  File \"/usr/local/lib/python3.10/multiprocessing/context.py\", line 281, in _Popen\n    return Popen(process_obj)\n", "  File \"/usr/local/lib/python3.10/multiprocessing/popen_fork.py\", line 19, in __init__\n    self._launch(process_obj)\n", "  File \"/usr/local/lib/python3.10/multiprocessing/popen_fork.py\", line 71, in _launch\n    code = process_obj._bootstrap(parent_sentinel=child_r)\n", "  File \"/usr/local/lib/python3.10/multiprocessing/process.py\", line 314, in _bootstrap\n    self.run()\n", "  File \"/usr/local/lib/python3.10/multiprocessing/process.py\", line 108, in run\n    self._target(*self._args, **self._kwargs)\n", "  File \"/usr/local/lib/python3.10/site-packages/mage_ai/orchestration/db/process.py\", line 15, in start_session_and_run\n    results = target(*args)\n", "  File \"/usr/local/lib/python3.10/site-packages/mage_ai/server/scheduler_manager.py\", line 58, in run_scheduler\n    LoopTimeTrigger().start()\n", "  File \"/usr/local/lib/python3.10/site-packages/mage_ai/orchestration/triggers/loop_time_trigger.py\", line 14, in start\n    self.run()\n", "  File \"/usr/local/lib/python3.10/site-packages/mage_ai/orchestration/triggers/time_trigger.py\", line 11, in run\n    schedule_all()\n", "  File \"/usr/local/lib/python3.10/site-packages/mage_ai/orchestration/pipeline_scheduler_original.py\", line 1703, in schedule_all\n    PipelineScheduler(r).start()\n", "  File \"/usr/local/lib/python3.10/site-packages/mage_ai/orchestration/db/__init__.py\", line 158, in func_with_rollback\n    return func(*args, **kwargs)\n", "  File \"/usr/local/lib/python3.10/site-packages/mage_ai/orchestration/pipeline_scheduler_original.py\", line 198, in start\n    self.schedule()\n", "  File \"/usr/local/lib/python3.10/site-packages/mage_ai/orchestration/db/__init__.py\", line 158, in func_with_rollback\n    return func(*args, **kwargs)\n", "  File \"/usr/local/lib/python3.10/site-packages/mage_ai/orchestration/pipeline_scheduler_original.py\", line 334, in schedule\n    self.__schedule_blocks(block_runs)\n", "  File \"/usr/local/lib/python3.10/site-packages/mage_ai/orchestration/pipeline_scheduler_original.py\", line 641, in __schedule_blocks\n    job_manager.add_job(\n", "  File \"/usr/local/lib/python3.10/site-packages/mage_ai/orchestration/job_manager.py\", line 20, in add_job\n    self.queue.enqueue(job_id, target, *args, **kwargs)\n", "  File \"/usr/local/lib/python3.10/site-packages/mage_ai/orchestration/queue/process_queue.py\", line 121, in enqueue\n    self.start_worker_pool()\n", "  File \"/usr/local/lib/python3.10/site-packages/mage_ai/orchestration/queue/process_queue.py\", line 198, in start_worker_pool\n    self.worker_pool_proc.start()\n", "  File \"/usr/local/lib/python3.10/multiprocessing/process.py\", line 121, in start\n    self._popen = self._Popen(self)\n", "  File \"/usr/local/lib/python3.10/multiprocessing/context.py\", line 224, in _Popen\n    return _default_context.get_context().Process._Popen(process_obj)\n", "  File \"/usr/local/lib/python3.10/multiprocessing/context.py\", line 281, in _Popen\n    return Popen(process_obj)\n", "  File \"/usr/local/lib/python3.10/multiprocessing/popen_fork.py\", line 19, in __init__\n    self._launch(process_obj)\n", "  File \"/usr/local/lib/python3.10/multiprocessing/popen_fork.py\", line 71, in _launch\n    code = process_obj._bootstrap(parent_sentinel=child_r)\n", "  File \"/usr/local/lib/python3.10/multiprocessing/process.py\", line 314, in _bootstrap\n    self.run()\n", "  File \"/usr/local/lib/python3.10/multiprocessing/process.py\", line 108, in run\n    self._target(*self._args, **self._kwargs)\n", "  File \"/usr/local/lib/python3.10/site-packages/mage_ai/orchestration/queue/process_queue.py\", line 351, in poll_job_and_execute\n    worker.start()\n", "  File \"/usr/local/lib/python3.10/multiprocessing/process.py\", line 121, in start\n    self._popen = self._Popen(self)\n", "  File \"/usr/local/lib/python3.10/multiprocessing/context.py\", line 224, in _Popen\n    return _default_context.get_context().Process._Popen(process_obj)\n", "  File \"/usr/local/lib/python3.10/multiprocessing/context.py\", line 281, in _Popen\n    return Popen(process_obj)\n", "  File \"/usr/local/lib/python3.10/multiprocessing/popen_fork.py\", line 19, in __init__\n    self._launch(process_obj)\n", "  File \"/usr/local/lib/python3.10/multiprocessing/popen_fork.py\", line 71, in _launch\n    code = process_obj._bootstrap(parent_sentinel=child_r)\n", "  File \"/usr/local/lib/python3.10/multiprocessing/process.py\", line 314, in _bootstrap\n    self.run()\n", "  File \"/usr/local/lib/python3.10/site-packages/newrelic/api/background_task.py\", line 117, in wrapper\n    return wrapped(*args, **kwargs)\n", "  File \"/usr/local/lib/python3.10/site-packages/mage_ai/orchestration/queue/process_queue.py\", line 315, in run\n    start_session_and_run(args[1], *args[2], **args[3])\n", "  File \"/usr/local/lib/python3.10/site-packages/mage_ai/orchestration/db/process.py\", line 15, in start_session_and_run\n    results = target(*args)\n", "  File \"/usr/local/lib/python3.10/site-packages/mage_ai/orchestration/pipeline_scheduler_original.py\", line 1236, in run_block\n    return ExecutorFactory.get_block_executor(\n", "  File \"/usr/local/lib/python3.10/site-packages/mage_ai/data_preparation/executors/block_executor.py\", line 682, in execute\n    on_failure(\n", "  File \"/usr/local/lib/python3.10/site-packages/mage_ai/orchestration/db/__init__.py\", line 158, in func_with_rollback\n    return func(*args, **kwargs)\n", "  File \"/usr/local/lib/python3.10/site-packages/mage_ai/orchestration/pipeline_scheduler_original.py\", line 465, in on_block_failure\n    self.logger.exception(\n", "  File \"/usr/local/lib/python3.10/site-packages/mage_ai/data_preparation/logging/logger.py\", line 30, in exception\n    self.__send_message('exception', message, **kwargs)\n", "  File \"/usr/local/lib/python3.10/site-packages/mage_ai/data_preparation/logging/logger.py\", line 65, in __send_message\n    data['error_stack'] = traceback.format_stack(),\n"]], "error_stacktrace": ["404 POST https://storage.googleapis.com/upload/storage/v1/b/test-mlops-philippov/o?uploadType=multipart: {\n  \"error\": {\n    \"code\": 404,\n    \"message\": \"The specified bucket does not exist.\",\n    \"errors\": [\n      {\n        \"message\": \"The specified bucket does not exist.\",\n        \"domain\": \"global\",\n        \"reason\": \"notFound\"\n      }\n    ]\n  }\n}\n: ('Request failed with status code', 404, 'Expected one of', <HTTPStatus.OK: 200>)"]}
Traceback (most recent call last):
  File "/usr/local/lib/python3.10/site-packages/google/cloud/storage/blob.py", line 2567, in upload_from_file
    created_json = self._do_upload(
  File "/usr/local/lib/python3.10/site-packages/google/cloud/storage/blob.py", line 2368, in _do_upload
    response = self._do_multipart_upload(
  File "/usr/local/lib/python3.10/site-packages/google/cloud/storage/blob.py", line 1903, in _do_multipart_upload
    response = upload.transmit(
  File "/usr/local/lib/python3.10/site-packages/google/resumable_media/requests/upload.py", line 153, in transmit
    return _request_helpers.wait_and_retry(
  File "/usr/local/lib/python3.10/site-packages/google/resumable_media/requests/_request_helpers.py", line 155, in wait_and_retry
    response = func()
  File "/usr/local/lib/python3.10/site-packages/google/resumable_media/requests/upload.py", line 149, in retriable_request
    self._process_response(result)
  File "/usr/local/lib/python3.10/site-packages/google/resumable_media/_upload.py", line 125, in _process_response
    _helpers.require_status_code(response, (http.client.OK,), self._get_status_code)
  File "/usr/local/lib/python3.10/site-packages/google/resumable_media/_helpers.py", line 108, in require_status_code
    raise common.InvalidResponse(
google.resumable_media.common.InvalidResponse: ('Request failed with status code', 404, 'Expected one of', <HTTPStatus.OK: 200>)

During handling of the above exception, another exception occurred:

Traceback (most recent call last):
  File "/usr/local/lib/python3.10/site-packages/mage_ai/data_preparation/executors/block_executor.py", line 647, in execute
    result = __execute_with_retry()
  File "/usr/local/lib/python3.10/site-packages/mage_ai/shared/retry.py", line 54, in retry_func
    raise e
  File "/usr/local/lib/python3.10/site-packages/mage_ai/shared/retry.py", line 38, in retry_func
    return func(*args, **kwargs)
  File "/usr/local/lib/python3.10/site-packages/mage_ai/data_preparation/executors/block_executor.py", line 621, in __execute_with_retry
    return self._execute(
  File "/usr/local/lib/python3.10/site-packages/mage_ai/data_preparation/executors/block_executor.py", line 1154, in _execute
    result = self.block.execute_sync(
  File "/usr/local/lib/python3.10/site-packages/mage_ai/data_preparation/models/block/__init__.py", line 1685, in execute_sync
    return __execute()
  File "/usr/local/lib/python3.10/site-packages/mage_ai/data_preparation/models/block/__init__.py", line 1662, in __execute
    raise err
  File "/usr/local/lib/python3.10/site-packages/mage_ai/data_preparation/models/block/__init__.py", line 1564, in __execute
    output = self.execute_block(
  File "/usr/local/lib/python3.10/site-packages/mage_ai/data_preparation/models/block/__init__.py", line 1904, in execute_block
    outputs = self._execute_block(
  File "/usr/local/lib/python3.10/site-packages/mage_ai/data_preparation/models/block/__init__.py", line 2067, in _execute_block
    outputs = self.execute_block_function(
  File "/usr/local/lib/python3.10/site-packages/mage_ai/data_preparation/models/block/__init__.py", line 2163, in execute_block_function
    output = block_function_updated(*input_vars, **global_vars)
  File "<string>", line 33, in hyperparameter_tuning
  File "/home/src/Basketball_results_prediction/utils/sklearn.py", line 138, in tune_hyperparameters
    best_hyperparameters = fmin(
  File "/usr/local/lib/python3.10/site-packages/hyperopt/fmin.py", line 540, in fmin
    return trials.fmin(
  File "/usr/local/lib/python3.10/site-packages/hyperopt/base.py", line 671, in fmin
    return fmin(
  File "/usr/local/lib/python3.10/site-packages/hyperopt/fmin.py", line 586, in fmin
    rval.exhaust()
  File "/usr/local/lib/python3.10/site-packages/hyperopt/fmin.py", line 364, in exhaust
    self.run(self.max_evals - n_done, block_until_done=self.asynchronous)
  File "/usr/local/lib/python3.10/site-packages/hyperopt/fmin.py", line 300, in run
    self.serial_evaluate()
  File "/usr/local/lib/python3.10/site-packages/hyperopt/fmin.py", line 178, in serial_evaluate
    result = self.domain.evaluate(spec, ctrl)
  File "/usr/local/lib/python3.10/site-packages/hyperopt/base.py", line 892, in evaluate
    rval = self.fn(pyll_rval)
  File "/home/src/Basketball_results_prediction/utils/sklearn.py", line 122, in __objective
    mlflow.sklearn.log_model(artifact_path="",sk_model=model)
  File "/usr/local/lib/python3.10/site-packages/mlflow/sklearn/__init__.py", line 418, in log_model
    return Model.log(
  File "/usr/local/lib/python3.10/site-packages/mlflow/models/model.py", line 656, in log
    mlflow.tracking.fluent.log_artifacts(local_path, mlflow_model.artifact_path, run_id)
  File "/usr/local/lib/python3.10/site-packages/mlflow/tracking/fluent.py", line 1096, in log_artifacts
    MlflowClient().log_artifacts(run_id, local_dir, artifact_path)
  File "/usr/local/lib/python3.10/site-packages/mlflow/tracking/client.py", line 1242, in log_artifacts
    self._tracking_client.log_artifacts(run_id, local_dir, artifact_path)
  File "/usr/local/lib/python3.10/site-packages/mlflow/tracking/_tracking_service/client.py", line 570, in log_artifacts
    self._get_artifact_repo(run_id).log_artifacts(local_dir, artifact_path)
  File "/usr/local/lib/python3.10/site-packages/mlflow/store/artifact/gcs_artifact_repo.py", line 106, in log_artifacts
    gcs_bucket.blob(path, chunk_size=self._GCS_UPLOAD_CHUNK_SIZE).upload_from_filename(
  File "/usr/local/lib/python3.10/site-packages/google/cloud/storage/blob.py", line 2708, in upload_from_filename
    self.upload_from_file(
  File "/usr/local/lib/python3.10/site-packages/google/cloud/storage/blob.py", line 2584, in upload_from_file
    _raise_from_invalid_response(exc)
  File "/usr/local/lib/python3.10/site-packages/google/cloud/storage/blob.py", line 4457, in _raise_from_invalid_response
    raise exceptions.from_http_status(response.status_code, message, response=response)
google.api_core.exceptions.NotFound: 404 POST https://storage.googleapis.com/upload/storage/v1/b/test-mlops-philippov/o?uploadType=multipart: {
  "error": {
    "code": 404,
    "message": "The specified bucket does not exist.",
    "errors": [
      {
        "message": "The specified bucket does not exist.",
        "domain": "global",
        "reason": "notFound"
      }
    ]
  }
}
: ('Request failed with status code', 404, 'Expected one of', <HTTPStatus.OK: 200>)
2024-08-10T21:58:42 {"cpu": 0.62109375, "cpu_total": 4, "cpu_usage": 0.1552734375, "memory": 2483.0, "memory_total": 16002.0, "memory_usage": 0.15516810398700162, "pipeline_run_id": 42, "pipeline_schedule_id": 3, "pipeline_uuid": "train_sklearn", "hostname": "fbd19c79e2e6", "level": "INFO", "message": "Pipeline train_sklearn for run 42 in schedule 3 is alive.", "timestamp": 1723327122.36171, "uuid": "7676294baf834bcf85f7ff36394138f6"}
